[2023-12-08T22:17:35.504+0000] {taskinstance.py:1159} INFO - Dependencies all met for dep_context=non-requeueable deps ti=<TaskInstance: Zillow_Dag.load_file_to_s3 manual__2023-12-08T22:15:23.570088+00:00 [queued]>
[2023-12-08T22:17:35.516+0000] {taskinstance.py:1159} INFO - Dependencies all met for dep_context=requeueable deps ti=<TaskInstance: Zillow_Dag.load_file_to_s3 manual__2023-12-08T22:15:23.570088+00:00 [queued]>
[2023-12-08T22:17:35.516+0000] {taskinstance.py:1361} INFO - Starting attempt 2 of 3
[2023-12-08T22:17:35.533+0000] {taskinstance.py:1382} INFO - Executing <Task(BashOperator): load_file_to_s3> on 2023-12-08 22:15:23.570088+00:00
[2023-12-08T22:17:35.537+0000] {standard_task_runner.py:57} INFO - Started process 25105 to run task
[2023-12-08T22:17:35.542+0000] {standard_task_runner.py:84} INFO - Running: ['airflow', 'tasks', 'run', 'Zillow_Dag', 'load_file_to_s3', 'manual__2023-12-08T22:15:23.570088+00:00', '--job-id', '24', '--raw', '--subdir', 'DAGS_FOLDER/etl.py', '--cfg-path', '/tmp/tmpiesll4i7']
[2023-12-08T22:17:35.543+0000] {standard_task_runner.py:85} INFO - Job 24: Subtask load_file_to_s3
[2023-12-08T22:17:35.579+0000] {task_command.py:416} INFO - Running <TaskInstance: Zillow_Dag.load_file_to_s3 manual__2023-12-08T22:15:23.570088+00:00 [running]> on host ip-172-31-29-175.eu-north-1.compute.internal
[2023-12-08T22:17:35.786+0000] {taskinstance.py:1662} INFO - Exporting env vars: AIRFLOW_CTX_DAG_EMAIL='anamsken60@gmail.com' AIRFLOW_CTX_DAG_OWNER='airflow' AIRFLOW_CTX_DAG_ID='Zillow_Dag' AIRFLOW_CTX_TASK_ID='load_file_to_s3' AIRFLOW_CTX_EXECUTION_DATE='2023-12-08T22:15:23.570088+00:00' AIRFLOW_CTX_TRY_NUMBER='2' AIRFLOW_CTX_DAG_RUN_ID='manual__2023-12-08T22:15:23.570088+00:00'
[2023-12-08T22:17:35.787+0000] {subprocess.py:63} INFO - Tmp dir root location: /tmp
[2023-12-08T22:17:35.788+0000] {subprocess.py:75} INFO - Running command: ['/usr/bin/bash', '-c', 'aws s3 mv /home/ubuntu/response_data_08122023221529.json s3://zillow-analytics-ec2/lagos/']
[2023-12-08T22:17:35.815+0000] {subprocess.py:86} INFO - Output:
[2023-12-08T22:17:35.817+0000] {subprocess.py:93} INFO - /usr/bin/bash: line 1: aws: command not found
[2023-12-08T22:17:35.818+0000] {subprocess.py:97} INFO - Command exited with return code 127
[2023-12-08T22:17:35.828+0000] {taskinstance.py:1937} ERROR - Task failed with exception
Traceback (most recent call last):
  File "/usr/local/lib/python3.10/dist-packages/airflow/operators/bash.py", line 210, in execute
    raise AirflowException(
airflow.exceptions.AirflowException: Bash command failed. The command returned a non-zero exit code 127.
[2023-12-08T22:17:35.831+0000] {taskinstance.py:1400} INFO - Marking task as UP_FOR_RETRY. dag_id=Zillow_Dag, task_id=load_file_to_s3, execution_date=20231208T221523, start_date=20231208T221735, end_date=20231208T221735
[2023-12-08T22:17:35.844+0000] {standard_task_runner.py:104} ERROR - Failed to execute job 24 for task load_file_to_s3 (Bash command failed. The command returned a non-zero exit code 127.; 25105)
[2023-12-08T22:17:35.875+0000] {local_task_job_runner.py:228} INFO - Task exited with return code 1
[2023-12-08T22:17:35.889+0000] {taskinstance.py:2778} INFO - 0 downstream tasks scheduled from follow-on schedule check
