[2023-12-08T20:59:05.313+0000] {taskinstance.py:1159} INFO - Dependencies all met for dep_context=non-requeueable deps ti=<TaskInstance: weather_dag.extract_data_task manual__2023-12-08T20:58:59.408148+00:00 [queued]>
[2023-12-08T20:59:05.325+0000] {taskinstance.py:1159} INFO - Dependencies all met for dep_context=requeueable deps ti=<TaskInstance: weather_dag.extract_data_task manual__2023-12-08T20:58:59.408148+00:00 [queued]>
[2023-12-08T20:59:05.325+0000] {taskinstance.py:1361} INFO - Starting attempt 1 of 3
[2023-12-08T20:59:05.355+0000] {taskinstance.py:1382} INFO - Executing <Task(PythonOperator): extract_data_task> on 2023-12-08 20:58:59.408148+00:00
[2023-12-08T20:59:05.372+0000] {standard_task_runner.py:84} INFO - Running: ['airflow', 'tasks', 'run', 'weather_dag', 'extract_data_task', 'manual__2023-12-08T20:58:59.408148+00:00', '--job-id', '19', '--raw', '--subdir', 'DAGS_FOLDER/etl.py', '--cfg-path', '/tmp/tmpc1q9xoik']
[2023-12-08T20:59:05.374+0000] {standard_task_runner.py:85} INFO - Job 19: Subtask extract_data_task
[2023-12-08T20:59:05.360+0000] {standard_task_runner.py:57} INFO - Started process 5971 to run task
[2023-12-08T20:59:05.486+0000] {task_command.py:416} INFO - Running <TaskInstance: weather_dag.extract_data_task manual__2023-12-08T20:58:59.408148+00:00 [running]> on host ip-172-31-29-175.eu-north-1.compute.internal
[2023-12-08T20:59:05.696+0000] {taskinstance.py:1662} INFO - Exporting env vars: AIRFLOW_CTX_DAG_EMAIL='anamsken60@gmail.com' AIRFLOW_CTX_DAG_OWNER='airflow' AIRFLOW_CTX_DAG_ID='weather_dag' AIRFLOW_CTX_TASK_ID='extract_data_task' AIRFLOW_CTX_EXECUTION_DATE='2023-12-08T20:58:59.408148+00:00' AIRFLOW_CTX_TRY_NUMBER='1' AIRFLOW_CTX_DAG_RUN_ID='manual__2023-12-08T20:58:59.408148+00:00'
[2023-12-08T20:59:07.722+0000] {taskinstance.py:1937} ERROR - Task failed with exception
Traceback (most recent call last):
  File "/usr/local/lib/python3.10/dist-packages/airflow/operators/python.py", line 192, in execute
    return_value = self.execute_callable()
  File "/usr/local/lib/python3.10/dist-packages/airflow/operators/python.py", line 209, in execute_callable
    return self.python_callable(*self.op_args, **self.op_kwargs)
  File "/home/ubuntu/airflow/dags/etl.py", line 35, in extract_data
    with open(file_path,'w') as output_file:
NameError: name 'file_path' is not defined. Did you mean: 'file_str'?
[2023-12-08T20:59:07.728+0000] {taskinstance.py:1400} INFO - Marking task as UP_FOR_RETRY. dag_id=weather_dag, task_id=extract_data_task, execution_date=20231208T205859, start_date=20231208T205905, end_date=20231208T205907
[2023-12-08T20:59:07.741+0000] {standard_task_runner.py:104} ERROR - Failed to execute job 19 for task extract_data_task (name 'file_path' is not defined; 5971)
[2023-12-08T20:59:07.773+0000] {local_task_job_runner.py:228} INFO - Task exited with return code 1
[2023-12-08T20:59:07.787+0000] {taskinstance.py:2778} INFO - 0 downstream tasks scheduled from follow-on schedule check
