[2023-12-05T18:21:06.076+0000] {processor.py:157} INFO - Started process (PID=15657) to work on /home/ubuntu/airflow/dags/etl.py
[2023-12-05T18:21:06.077+0000] {processor.py:829} INFO - Processing file /home/ubuntu/airflow/dags/etl.py for tasks to queue
[2023-12-05T18:21:06.078+0000] {logging_mixin.py:154} INFO - [2023-12-05T18:21:06.077+0000] {dagbag.py:536} INFO - Filling up the DagBag from /home/ubuntu/airflow/dags/etl.py
[2023-12-05T18:21:06.084+0000] {logging_mixin.py:154} INFO - [2023-12-05T18:21:06.081+0000] {dagbag.py:346} ERROR - Failed to import: /home/ubuntu/airflow/dags/etl.py
Traceback (most recent call last):
  File "/usr/local/lib/python3.10/dist-packages/airflow/models/dagbag.py", line 342, in parse
    loader.exec_module(new_module)
  File "<frozen importlib._bootstrap_external>", line 879, in exec_module
  File "<frozen importlib._bootstrap_external>", line 1017, in get_code
  File "<frozen importlib._bootstrap_external>", line 947, in source_to_code
  File "<frozen importlib._bootstrap>", line 241, in _call_with_frames_removed
  File "/home/ubuntu/airflow/dags/etl.py", line 7
    'start_date': datetime(2023, 5. 12),
                                 ^^^^^
SyntaxError: invalid syntax. Perhaps you forgot a comma?
[2023-12-05T18:21:06.089+0000] {processor.py:841} WARNING - No viable dags retrieved from /home/ubuntu/airflow/dags/etl.py
[2023-12-05T18:21:06.132+0000] {processor.py:179} INFO - Processing /home/ubuntu/airflow/dags/etl.py took 0.067 seconds
[2023-12-05T18:21:36.835+0000] {processor.py:157} INFO - Started process (PID=15881) to work on /home/ubuntu/airflow/dags/etl.py
[2023-12-05T18:21:36.836+0000] {processor.py:829} INFO - Processing file /home/ubuntu/airflow/dags/etl.py for tasks to queue
[2023-12-05T18:21:36.837+0000] {logging_mixin.py:154} INFO - [2023-12-05T18:21:36.836+0000] {dagbag.py:536} INFO - Filling up the DagBag from /home/ubuntu/airflow/dags/etl.py
[2023-12-05T18:21:36.841+0000] {logging_mixin.py:154} INFO - [2023-12-05T18:21:36.840+0000] {dagbag.py:346} ERROR - Failed to import: /home/ubuntu/airflow/dags/etl.py
Traceback (most recent call last):
  File "/usr/local/lib/python3.10/dist-packages/airflow/models/dagbag.py", line 342, in parse
    loader.exec_module(new_module)
  File "<frozen importlib._bootstrap_external>", line 879, in exec_module
  File "<frozen importlib._bootstrap_external>", line 1017, in get_code
  File "<frozen importlib._bootstrap_external>", line 947, in source_to_code
  File "<frozen importlib._bootstrap>", line 241, in _call_with_frames_removed
  File "/home/ubuntu/airflow/dags/etl.py", line 7
    'start_date': datetime(2023, 5. 12),
                                 ^^^^^
SyntaxError: invalid syntax. Perhaps you forgot a comma?
[2023-12-05T18:21:36.841+0000] {processor.py:841} WARNING - No viable dags retrieved from /home/ubuntu/airflow/dags/etl.py
[2023-12-05T18:21:36.864+0000] {processor.py:179} INFO - Processing /home/ubuntu/airflow/dags/etl.py took 0.034 seconds
[2023-12-05T18:22:07.516+0000] {processor.py:157} INFO - Started process (PID=15957) to work on /home/ubuntu/airflow/dags/etl.py
[2023-12-05T18:22:07.517+0000] {processor.py:829} INFO - Processing file /home/ubuntu/airflow/dags/etl.py for tasks to queue
[2023-12-05T18:22:07.518+0000] {logging_mixin.py:154} INFO - [2023-12-05T18:22:07.518+0000] {dagbag.py:536} INFO - Filling up the DagBag from /home/ubuntu/airflow/dags/etl.py
[2023-12-05T18:22:07.522+0000] {logging_mixin.py:154} INFO - [2023-12-05T18:22:07.520+0000] {dagbag.py:346} ERROR - Failed to import: /home/ubuntu/airflow/dags/etl.py
Traceback (most recent call last):
  File "/usr/local/lib/python3.10/dist-packages/airflow/models/dagbag.py", line 342, in parse
    loader.exec_module(new_module)
  File "<frozen importlib._bootstrap_external>", line 879, in exec_module
  File "<frozen importlib._bootstrap_external>", line 1017, in get_code
  File "<frozen importlib._bootstrap_external>", line 947, in source_to_code
  File "<frozen importlib._bootstrap>", line 241, in _call_with_frames_removed
  File "/home/ubuntu/airflow/dags/etl.py", line 7
    'start_date': datetime(2023, 5. 12),
                                 ^^^^^
SyntaxError: invalid syntax. Perhaps you forgot a comma?
[2023-12-05T18:22:07.522+0000] {processor.py:841} WARNING - No viable dags retrieved from /home/ubuntu/airflow/dags/etl.py
[2023-12-05T18:22:07.559+0000] {processor.py:179} INFO - Processing /home/ubuntu/airflow/dags/etl.py took 0.046 seconds
[2023-12-05T18:22:37.969+0000] {processor.py:157} INFO - Started process (PID=16134) to work on /home/ubuntu/airflow/dags/etl.py
[2023-12-05T18:22:37.970+0000] {processor.py:829} INFO - Processing file /home/ubuntu/airflow/dags/etl.py for tasks to queue
[2023-12-05T18:22:37.971+0000] {logging_mixin.py:154} INFO - [2023-12-05T18:22:37.971+0000] {dagbag.py:536} INFO - Filling up the DagBag from /home/ubuntu/airflow/dags/etl.py
[2023-12-05T18:22:37.976+0000] {logging_mixin.py:154} INFO - [2023-12-05T18:22:37.974+0000] {dagbag.py:346} ERROR - Failed to import: /home/ubuntu/airflow/dags/etl.py
Traceback (most recent call last):
  File "/usr/local/lib/python3.10/dist-packages/airflow/models/dagbag.py", line 342, in parse
    loader.exec_module(new_module)
  File "<frozen importlib._bootstrap_external>", line 879, in exec_module
  File "<frozen importlib._bootstrap_external>", line 1017, in get_code
  File "<frozen importlib._bootstrap_external>", line 947, in source_to_code
  File "<frozen importlib._bootstrap>", line 241, in _call_with_frames_removed
  File "/home/ubuntu/airflow/dags/etl.py", line 7
    'start_date': datetime(2023, 5. 12),
                                 ^^^^^
SyntaxError: invalid syntax. Perhaps you forgot a comma?
[2023-12-05T18:22:37.976+0000] {processor.py:841} WARNING - No viable dags retrieved from /home/ubuntu/airflow/dags/etl.py
[2023-12-05T18:22:37.999+0000] {processor.py:179} INFO - Processing /home/ubuntu/airflow/dags/etl.py took 0.036 seconds
[2023-12-05T18:23:08.150+0000] {processor.py:157} INFO - Started process (PID=16274) to work on /home/ubuntu/airflow/dags/etl.py
[2023-12-05T18:23:08.151+0000] {processor.py:829} INFO - Processing file /home/ubuntu/airflow/dags/etl.py for tasks to queue
[2023-12-05T18:23:08.152+0000] {logging_mixin.py:154} INFO - [2023-12-05T18:23:08.152+0000] {dagbag.py:536} INFO - Filling up the DagBag from /home/ubuntu/airflow/dags/etl.py
[2023-12-05T18:23:08.155+0000] {logging_mixin.py:154} INFO - [2023-12-05T18:23:08.154+0000] {dagbag.py:346} ERROR - Failed to import: /home/ubuntu/airflow/dags/etl.py
Traceback (most recent call last):
  File "/usr/local/lib/python3.10/dist-packages/airflow/models/dagbag.py", line 342, in parse
    loader.exec_module(new_module)
  File "<frozen importlib._bootstrap_external>", line 879, in exec_module
  File "<frozen importlib._bootstrap_external>", line 1017, in get_code
  File "<frozen importlib._bootstrap_external>", line 947, in source_to_code
  File "<frozen importlib._bootstrap>", line 241, in _call_with_frames_removed
  File "/home/ubuntu/airflow/dags/etl.py", line 7
    'start_date': datetime(2023, 5. 12),
                                 ^^^^^
SyntaxError: invalid syntax. Perhaps you forgot a comma?
[2023-12-05T18:23:08.156+0000] {processor.py:841} WARNING - No viable dags retrieved from /home/ubuntu/airflow/dags/etl.py
[2023-12-05T18:23:08.179+0000] {processor.py:179} INFO - Processing /home/ubuntu/airflow/dags/etl.py took 0.033 seconds
[2023-12-05T18:23:38.376+0000] {processor.py:157} INFO - Started process (PID=16403) to work on /home/ubuntu/airflow/dags/etl.py
[2023-12-05T18:23:38.378+0000] {processor.py:829} INFO - Processing file /home/ubuntu/airflow/dags/etl.py for tasks to queue
[2023-12-05T18:23:38.382+0000] {logging_mixin.py:154} INFO - [2023-12-05T18:23:38.379+0000] {dagbag.py:536} INFO - Filling up the DagBag from /home/ubuntu/airflow/dags/etl.py
[2023-12-05T18:23:38.389+0000] {logging_mixin.py:154} INFO - [2023-12-05T18:23:38.388+0000] {dagbag.py:346} ERROR - Failed to import: /home/ubuntu/airflow/dags/etl.py
Traceback (most recent call last):
  File "/usr/local/lib/python3.10/dist-packages/airflow/models/dagbag.py", line 342, in parse
    loader.exec_module(new_module)
  File "<frozen importlib._bootstrap_external>", line 879, in exec_module
  File "<frozen importlib._bootstrap_external>", line 1017, in get_code
  File "<frozen importlib._bootstrap_external>", line 947, in source_to_code
  File "<frozen importlib._bootstrap>", line 241, in _call_with_frames_removed
  File "/home/ubuntu/airflow/dags/etl.py", line 7
    'start_date': datetime(2023, 5. 12),
                                 ^^^^^
SyntaxError: invalid syntax. Perhaps you forgot a comma?
[2023-12-05T18:23:38.391+0000] {processor.py:841} WARNING - No viable dags retrieved from /home/ubuntu/airflow/dags/etl.py
[2023-12-05T18:23:38.416+0000] {processor.py:179} INFO - Processing /home/ubuntu/airflow/dags/etl.py took 0.044 seconds
[2023-12-05T18:24:08.565+0000] {processor.py:157} INFO - Started process (PID=16591) to work on /home/ubuntu/airflow/dags/etl.py
[2023-12-05T18:24:08.566+0000] {processor.py:829} INFO - Processing file /home/ubuntu/airflow/dags/etl.py for tasks to queue
[2023-12-05T18:24:08.567+0000] {logging_mixin.py:154} INFO - [2023-12-05T18:24:08.566+0000] {dagbag.py:536} INFO - Filling up the DagBag from /home/ubuntu/airflow/dags/etl.py
[2023-12-05T18:24:08.571+0000] {logging_mixin.py:154} INFO - [2023-12-05T18:24:08.569+0000] {dagbag.py:346} ERROR - Failed to import: /home/ubuntu/airflow/dags/etl.py
Traceback (most recent call last):
  File "/usr/local/lib/python3.10/dist-packages/airflow/models/dagbag.py", line 342, in parse
    loader.exec_module(new_module)
  File "<frozen importlib._bootstrap_external>", line 879, in exec_module
  File "<frozen importlib._bootstrap_external>", line 1017, in get_code
  File "<frozen importlib._bootstrap_external>", line 947, in source_to_code
  File "<frozen importlib._bootstrap>", line 241, in _call_with_frames_removed
  File "/home/ubuntu/airflow/dags/etl.py", line 7
    'start_date': datetime(2023, 5. 12),
                                 ^^^^^
SyntaxError: invalid syntax. Perhaps you forgot a comma?
[2023-12-05T18:24:08.571+0000] {processor.py:841} WARNING - No viable dags retrieved from /home/ubuntu/airflow/dags/etl.py
[2023-12-05T18:24:08.594+0000] {processor.py:179} INFO - Processing /home/ubuntu/airflow/dags/etl.py took 0.033 seconds
[2023-12-05T18:24:38.704+0000] {processor.py:157} INFO - Started process (PID=16738) to work on /home/ubuntu/airflow/dags/etl.py
[2023-12-05T18:24:38.705+0000] {processor.py:829} INFO - Processing file /home/ubuntu/airflow/dags/etl.py for tasks to queue
[2023-12-05T18:24:38.710+0000] {logging_mixin.py:154} INFO - [2023-12-05T18:24:38.709+0000] {dagbag.py:536} INFO - Filling up the DagBag from /home/ubuntu/airflow/dags/etl.py
[2023-12-05T18:24:38.718+0000] {logging_mixin.py:154} INFO - [2023-12-05T18:24:38.715+0000] {dagbag.py:346} ERROR - Failed to import: /home/ubuntu/airflow/dags/etl.py
Traceback (most recent call last):
  File "/usr/local/lib/python3.10/dist-packages/airflow/models/dagbag.py", line 342, in parse
    loader.exec_module(new_module)
  File "<frozen importlib._bootstrap_external>", line 879, in exec_module
  File "<frozen importlib._bootstrap_external>", line 1017, in get_code
  File "<frozen importlib._bootstrap_external>", line 947, in source_to_code
  File "<frozen importlib._bootstrap>", line 241, in _call_with_frames_removed
  File "/home/ubuntu/airflow/dags/etl.py", line 7
    'start_date': datetime(2023, 5. 12),
                                 ^^^^^
SyntaxError: invalid syntax. Perhaps you forgot a comma?
[2023-12-05T18:24:38.720+0000] {processor.py:841} WARNING - No viable dags retrieved from /home/ubuntu/airflow/dags/etl.py
[2023-12-05T18:24:38.750+0000] {processor.py:179} INFO - Processing /home/ubuntu/airflow/dags/etl.py took 0.052 seconds
[2023-12-05T18:25:08.893+0000] {processor.py:157} INFO - Started process (PID=16885) to work on /home/ubuntu/airflow/dags/etl.py
[2023-12-05T18:25:08.894+0000] {processor.py:829} INFO - Processing file /home/ubuntu/airflow/dags/etl.py for tasks to queue
[2023-12-05T18:25:08.895+0000] {logging_mixin.py:154} INFO - [2023-12-05T18:25:08.895+0000] {dagbag.py:536} INFO - Filling up the DagBag from /home/ubuntu/airflow/dags/etl.py
[2023-12-05T18:25:08.899+0000] {logging_mixin.py:154} INFO - [2023-12-05T18:25:08.897+0000] {dagbag.py:346} ERROR - Failed to import: /home/ubuntu/airflow/dags/etl.py
Traceback (most recent call last):
  File "/usr/local/lib/python3.10/dist-packages/airflow/models/dagbag.py", line 342, in parse
    loader.exec_module(new_module)
  File "<frozen importlib._bootstrap_external>", line 879, in exec_module
  File "<frozen importlib._bootstrap_external>", line 1017, in get_code
  File "<frozen importlib._bootstrap_external>", line 947, in source_to_code
  File "<frozen importlib._bootstrap>", line 241, in _call_with_frames_removed
  File "/home/ubuntu/airflow/dags/etl.py", line 7
    'start_date': datetime(2023, 5. 12),
                                 ^^^^^
SyntaxError: invalid syntax. Perhaps you forgot a comma?
[2023-12-05T18:25:08.899+0000] {processor.py:841} WARNING - No viable dags retrieved from /home/ubuntu/airflow/dags/etl.py
[2023-12-05T18:25:08.925+0000] {processor.py:179} INFO - Processing /home/ubuntu/airflow/dags/etl.py took 0.035 seconds
[2023-12-05T18:25:39.098+0000] {processor.py:157} INFO - Started process (PID=16992) to work on /home/ubuntu/airflow/dags/etl.py
[2023-12-05T18:25:39.101+0000] {processor.py:829} INFO - Processing file /home/ubuntu/airflow/dags/etl.py for tasks to queue
[2023-12-05T18:25:39.102+0000] {logging_mixin.py:154} INFO - [2023-12-05T18:25:39.101+0000] {dagbag.py:536} INFO - Filling up the DagBag from /home/ubuntu/airflow/dags/etl.py
[2023-12-05T18:25:39.108+0000] {logging_mixin.py:154} INFO - [2023-12-05T18:25:39.107+0000] {dagbag.py:346} ERROR - Failed to import: /home/ubuntu/airflow/dags/etl.py
Traceback (most recent call last):
  File "/usr/local/lib/python3.10/dist-packages/airflow/models/dagbag.py", line 342, in parse
    loader.exec_module(new_module)
  File "<frozen importlib._bootstrap_external>", line 879, in exec_module
  File "<frozen importlib._bootstrap_external>", line 1017, in get_code
  File "<frozen importlib._bootstrap_external>", line 947, in source_to_code
  File "<frozen importlib._bootstrap>", line 241, in _call_with_frames_removed
  File "/home/ubuntu/airflow/dags/etl.py", line 7
    'start_date': datetime(2023, 5. 12),
                                 ^^^^^
SyntaxError: invalid syntax. Perhaps you forgot a comma?
[2023-12-05T18:25:39.109+0000] {processor.py:841} WARNING - No viable dags retrieved from /home/ubuntu/airflow/dags/etl.py
[2023-12-05T18:25:39.131+0000] {processor.py:179} INFO - Processing /home/ubuntu/airflow/dags/etl.py took 0.042 seconds
[2023-12-05T18:26:09.280+0000] {processor.py:157} INFO - Started process (PID=17065) to work on /home/ubuntu/airflow/dags/etl.py
[2023-12-05T18:26:09.282+0000] {processor.py:829} INFO - Processing file /home/ubuntu/airflow/dags/etl.py for tasks to queue
[2023-12-05T18:26:09.283+0000] {logging_mixin.py:154} INFO - [2023-12-05T18:26:09.282+0000] {dagbag.py:536} INFO - Filling up the DagBag from /home/ubuntu/airflow/dags/etl.py
[2023-12-05T18:26:09.288+0000] {logging_mixin.py:154} INFO - [2023-12-05T18:26:09.286+0000] {dagbag.py:346} ERROR - Failed to import: /home/ubuntu/airflow/dags/etl.py
Traceback (most recent call last):
  File "/usr/local/lib/python3.10/dist-packages/airflow/models/dagbag.py", line 342, in parse
    loader.exec_module(new_module)
  File "<frozen importlib._bootstrap_external>", line 879, in exec_module
  File "<frozen importlib._bootstrap_external>", line 1017, in get_code
  File "<frozen importlib._bootstrap_external>", line 947, in source_to_code
  File "<frozen importlib._bootstrap>", line 241, in _call_with_frames_removed
  File "/home/ubuntu/airflow/dags/etl.py", line 7
    'start_date': datetime(2023, 5. 12),
                                 ^^^^^
SyntaxError: invalid syntax. Perhaps you forgot a comma?
[2023-12-05T18:26:09.289+0000] {processor.py:841} WARNING - No viable dags retrieved from /home/ubuntu/airflow/dags/etl.py
[2023-12-05T18:26:09.332+0000] {processor.py:179} INFO - Processing /home/ubuntu/airflow/dags/etl.py took 0.056 seconds
[2023-12-05T18:26:39.492+0000] {processor.py:157} INFO - Started process (PID=17299) to work on /home/ubuntu/airflow/dags/etl.py
[2023-12-05T18:26:39.494+0000] {processor.py:829} INFO - Processing file /home/ubuntu/airflow/dags/etl.py for tasks to queue
[2023-12-05T18:26:39.494+0000] {logging_mixin.py:154} INFO - [2023-12-05T18:26:39.494+0000] {dagbag.py:536} INFO - Filling up the DagBag from /home/ubuntu/airflow/dags/etl.py
[2023-12-05T18:26:39.499+0000] {logging_mixin.py:154} INFO - [2023-12-05T18:26:39.497+0000] {dagbag.py:346} ERROR - Failed to import: /home/ubuntu/airflow/dags/etl.py
Traceback (most recent call last):
  File "/usr/local/lib/python3.10/dist-packages/airflow/models/dagbag.py", line 342, in parse
    loader.exec_module(new_module)
  File "<frozen importlib._bootstrap_external>", line 879, in exec_module
  File "<frozen importlib._bootstrap_external>", line 1017, in get_code
  File "<frozen importlib._bootstrap_external>", line 947, in source_to_code
  File "<frozen importlib._bootstrap>", line 241, in _call_with_frames_removed
  File "/home/ubuntu/airflow/dags/etl.py", line 7
    'start_date': datetime(2023, 5. 12),
                                 ^^^^^
SyntaxError: invalid syntax. Perhaps you forgot a comma?
[2023-12-05T18:26:39.499+0000] {processor.py:841} WARNING - No viable dags retrieved from /home/ubuntu/airflow/dags/etl.py
[2023-12-05T18:26:39.528+0000] {processor.py:179} INFO - Processing /home/ubuntu/airflow/dags/etl.py took 0.040 seconds
[2023-12-05T18:27:09.685+0000] {processor.py:157} INFO - Started process (PID=17417) to work on /home/ubuntu/airflow/dags/etl.py
[2023-12-05T18:27:09.688+0000] {processor.py:829} INFO - Processing file /home/ubuntu/airflow/dags/etl.py for tasks to queue
[2023-12-05T18:27:09.690+0000] {logging_mixin.py:154} INFO - [2023-12-05T18:27:09.690+0000] {dagbag.py:536} INFO - Filling up the DagBag from /home/ubuntu/airflow/dags/etl.py
[2023-12-05T18:27:09.702+0000] {logging_mixin.py:154} INFO - [2023-12-05T18:27:09.701+0000] {dagbag.py:346} ERROR - Failed to import: /home/ubuntu/airflow/dags/etl.py
Traceback (most recent call last):
  File "/usr/local/lib/python3.10/dist-packages/airflow/models/dagbag.py", line 342, in parse
    loader.exec_module(new_module)
  File "<frozen importlib._bootstrap_external>", line 879, in exec_module
  File "<frozen importlib._bootstrap_external>", line 1017, in get_code
  File "<frozen importlib._bootstrap_external>", line 947, in source_to_code
  File "<frozen importlib._bootstrap>", line 241, in _call_with_frames_removed
  File "/home/ubuntu/airflow/dags/etl.py", line 7
    'start_date': datetime(2023, 5. 12),
                                 ^^^^^
SyntaxError: invalid syntax. Perhaps you forgot a comma?
[2023-12-05T18:27:09.703+0000] {processor.py:841} WARNING - No viable dags retrieved from /home/ubuntu/airflow/dags/etl.py
[2023-12-05T18:27:09.744+0000] {processor.py:179} INFO - Processing /home/ubuntu/airflow/dags/etl.py took 0.067 seconds
[2023-12-05T18:27:39.876+0000] {processor.py:157} INFO - Started process (PID=17490) to work on /home/ubuntu/airflow/dags/etl.py
[2023-12-05T18:27:39.877+0000] {processor.py:829} INFO - Processing file /home/ubuntu/airflow/dags/etl.py for tasks to queue
[2023-12-05T18:27:39.879+0000] {logging_mixin.py:154} INFO - [2023-12-05T18:27:39.879+0000] {dagbag.py:536} INFO - Filling up the DagBag from /home/ubuntu/airflow/dags/etl.py
[2023-12-05T18:27:39.883+0000] {logging_mixin.py:154} INFO - [2023-12-05T18:27:39.881+0000] {dagbag.py:346} ERROR - Failed to import: /home/ubuntu/airflow/dags/etl.py
Traceback (most recent call last):
  File "/usr/local/lib/python3.10/dist-packages/airflow/models/dagbag.py", line 342, in parse
    loader.exec_module(new_module)
  File "<frozen importlib._bootstrap_external>", line 879, in exec_module
  File "<frozen importlib._bootstrap_external>", line 1017, in get_code
  File "<frozen importlib._bootstrap_external>", line 947, in source_to_code
  File "<frozen importlib._bootstrap>", line 241, in _call_with_frames_removed
  File "/home/ubuntu/airflow/dags/etl.py", line 7
    'start_date': datetime(2023, 5. 12),
                                 ^^^^^
SyntaxError: invalid syntax. Perhaps you forgot a comma?
[2023-12-05T18:27:39.883+0000] {processor.py:841} WARNING - No viable dags retrieved from /home/ubuntu/airflow/dags/etl.py
[2023-12-05T18:27:39.919+0000] {processor.py:179} INFO - Processing /home/ubuntu/airflow/dags/etl.py took 0.048 seconds
[2023-12-05T18:28:10.033+0000] {processor.py:157} INFO - Started process (PID=17677) to work on /home/ubuntu/airflow/dags/etl.py
[2023-12-05T18:28:10.035+0000] {processor.py:829} INFO - Processing file /home/ubuntu/airflow/dags/etl.py for tasks to queue
[2023-12-05T18:28:10.036+0000] {logging_mixin.py:154} INFO - [2023-12-05T18:28:10.035+0000] {dagbag.py:536} INFO - Filling up the DagBag from /home/ubuntu/airflow/dags/etl.py
[2023-12-05T18:28:10.044+0000] {logging_mixin.py:154} INFO - [2023-12-05T18:28:10.042+0000] {dagbag.py:346} ERROR - Failed to import: /home/ubuntu/airflow/dags/etl.py
Traceback (most recent call last):
  File "/usr/local/lib/python3.10/dist-packages/airflow/models/dagbag.py", line 342, in parse
    loader.exec_module(new_module)
  File "<frozen importlib._bootstrap_external>", line 879, in exec_module
  File "<frozen importlib._bootstrap_external>", line 1017, in get_code
  File "<frozen importlib._bootstrap_external>", line 947, in source_to_code
  File "<frozen importlib._bootstrap>", line 241, in _call_with_frames_removed
  File "/home/ubuntu/airflow/dags/etl.py", line 7
    'start_date': datetime(2023, 5. 12),
                                 ^^^^^
SyntaxError: invalid syntax. Perhaps you forgot a comma?
[2023-12-05T18:28:10.044+0000] {processor.py:841} WARNING - No viable dags retrieved from /home/ubuntu/airflow/dags/etl.py
[2023-12-05T18:28:10.083+0000] {processor.py:179} INFO - Processing /home/ubuntu/airflow/dags/etl.py took 0.055 seconds
[2023-12-05T18:28:40.213+0000] {processor.py:157} INFO - Started process (PID=17816) to work on /home/ubuntu/airflow/dags/etl.py
[2023-12-05T18:28:40.214+0000] {processor.py:829} INFO - Processing file /home/ubuntu/airflow/dags/etl.py for tasks to queue
[2023-12-05T18:28:40.216+0000] {logging_mixin.py:154} INFO - [2023-12-05T18:28:40.215+0000] {dagbag.py:536} INFO - Filling up the DagBag from /home/ubuntu/airflow/dags/etl.py
[2023-12-05T18:28:40.219+0000] {logging_mixin.py:154} INFO - [2023-12-05T18:28:40.218+0000] {dagbag.py:346} ERROR - Failed to import: /home/ubuntu/airflow/dags/etl.py
Traceback (most recent call last):
  File "/usr/local/lib/python3.10/dist-packages/airflow/models/dagbag.py", line 342, in parse
    loader.exec_module(new_module)
  File "<frozen importlib._bootstrap_external>", line 879, in exec_module
  File "<frozen importlib._bootstrap_external>", line 1017, in get_code
  File "<frozen importlib._bootstrap_external>", line 947, in source_to_code
  File "<frozen importlib._bootstrap>", line 241, in _call_with_frames_removed
  File "/home/ubuntu/airflow/dags/etl.py", line 7
    'start_date': datetime(2023, 5. 12),
                                 ^^^^^
SyntaxError: invalid syntax. Perhaps you forgot a comma?
[2023-12-05T18:28:40.220+0000] {processor.py:841} WARNING - No viable dags retrieved from /home/ubuntu/airflow/dags/etl.py
[2023-12-05T18:28:40.242+0000] {processor.py:179} INFO - Processing /home/ubuntu/airflow/dags/etl.py took 0.035 seconds
[2023-12-05T18:29:10.404+0000] {processor.py:157} INFO - Started process (PID=17895) to work on /home/ubuntu/airflow/dags/etl.py
[2023-12-05T18:29:10.406+0000] {processor.py:829} INFO - Processing file /home/ubuntu/airflow/dags/etl.py for tasks to queue
[2023-12-05T18:29:10.407+0000] {logging_mixin.py:154} INFO - [2023-12-05T18:29:10.407+0000] {dagbag.py:536} INFO - Filling up the DagBag from /home/ubuntu/airflow/dags/etl.py
[2023-12-05T18:29:10.413+0000] {logging_mixin.py:154} INFO - [2023-12-05T18:29:10.412+0000] {dagbag.py:346} ERROR - Failed to import: /home/ubuntu/airflow/dags/etl.py
Traceback (most recent call last):
  File "/usr/local/lib/python3.10/dist-packages/airflow/models/dagbag.py", line 342, in parse
    loader.exec_module(new_module)
  File "<frozen importlib._bootstrap_external>", line 879, in exec_module
  File "<frozen importlib._bootstrap_external>", line 1017, in get_code
  File "<frozen importlib._bootstrap_external>", line 947, in source_to_code
  File "<frozen importlib._bootstrap>", line 241, in _call_with_frames_removed
  File "/home/ubuntu/airflow/dags/etl.py", line 7
    'start_date': datetime(2023, 5. 12),
                                 ^^^^^
SyntaxError: invalid syntax. Perhaps you forgot a comma?
[2023-12-05T18:29:10.414+0000] {processor.py:841} WARNING - No viable dags retrieved from /home/ubuntu/airflow/dags/etl.py
[2023-12-05T18:29:10.447+0000] {processor.py:179} INFO - Processing /home/ubuntu/airflow/dags/etl.py took 0.048 seconds
[2023-12-05T18:29:40.602+0000] {processor.py:157} INFO - Started process (PID=17944) to work on /home/ubuntu/airflow/dags/etl.py
[2023-12-05T18:29:40.603+0000] {processor.py:829} INFO - Processing file /home/ubuntu/airflow/dags/etl.py for tasks to queue
[2023-12-05T18:29:40.604+0000] {logging_mixin.py:154} INFO - [2023-12-05T18:29:40.604+0000] {dagbag.py:536} INFO - Filling up the DagBag from /home/ubuntu/airflow/dags/etl.py
[2023-12-05T18:29:40.607+0000] {logging_mixin.py:154} INFO - [2023-12-05T18:29:40.606+0000] {dagbag.py:346} ERROR - Failed to import: /home/ubuntu/airflow/dags/etl.py
Traceback (most recent call last):
  File "/usr/local/lib/python3.10/dist-packages/airflow/models/dagbag.py", line 342, in parse
    loader.exec_module(new_module)
  File "<frozen importlib._bootstrap_external>", line 879, in exec_module
  File "<frozen importlib._bootstrap_external>", line 1017, in get_code
  File "<frozen importlib._bootstrap_external>", line 947, in source_to_code
  File "<frozen importlib._bootstrap>", line 241, in _call_with_frames_removed
  File "/home/ubuntu/airflow/dags/etl.py", line 7
    'start_date': datetime(2023, 5. 12),
                                 ^^^^^
SyntaxError: invalid syntax. Perhaps you forgot a comma?
[2023-12-05T18:29:40.608+0000] {processor.py:841} WARNING - No viable dags retrieved from /home/ubuntu/airflow/dags/etl.py
[2023-12-05T18:29:40.631+0000] {processor.py:179} INFO - Processing /home/ubuntu/airflow/dags/etl.py took 0.032 seconds
[2023-12-05T18:30:10.791+0000] {processor.py:157} INFO - Started process (PID=18108) to work on /home/ubuntu/airflow/dags/etl.py
[2023-12-05T18:30:10.792+0000] {processor.py:829} INFO - Processing file /home/ubuntu/airflow/dags/etl.py for tasks to queue
[2023-12-05T18:30:10.793+0000] {logging_mixin.py:154} INFO - [2023-12-05T18:30:10.793+0000] {dagbag.py:536} INFO - Filling up the DagBag from /home/ubuntu/airflow/dags/etl.py
[2023-12-05T18:30:10.797+0000] {logging_mixin.py:154} INFO - [2023-12-05T18:30:10.796+0000] {dagbag.py:346} ERROR - Failed to import: /home/ubuntu/airflow/dags/etl.py
Traceback (most recent call last):
  File "/usr/local/lib/python3.10/dist-packages/airflow/models/dagbag.py", line 342, in parse
    loader.exec_module(new_module)
  File "<frozen importlib._bootstrap_external>", line 879, in exec_module
  File "<frozen importlib._bootstrap_external>", line 1017, in get_code
  File "<frozen importlib._bootstrap_external>", line 947, in source_to_code
  File "<frozen importlib._bootstrap>", line 241, in _call_with_frames_removed
  File "/home/ubuntu/airflow/dags/etl.py", line 7
    'start_date': datetime(2023, 5. 12),
                                 ^^^^^
SyntaxError: invalid syntax. Perhaps you forgot a comma?
[2023-12-05T18:30:10.797+0000] {processor.py:841} WARNING - No viable dags retrieved from /home/ubuntu/airflow/dags/etl.py
[2023-12-05T18:30:10.819+0000] {processor.py:179} INFO - Processing /home/ubuntu/airflow/dags/etl.py took 0.034 seconds
