[2023-12-05T18:21:06.076+0000] {processor.py:157} INFO - Started process (PID=15657) to work on /home/ubuntu/airflow/dags/etl.py
[2023-12-05T18:21:06.077+0000] {processor.py:829} INFO - Processing file /home/ubuntu/airflow/dags/etl.py for tasks to queue
[2023-12-05T18:21:06.078+0000] {logging_mixin.py:154} INFO - [2023-12-05T18:21:06.077+0000] {dagbag.py:536} INFO - Filling up the DagBag from /home/ubuntu/airflow/dags/etl.py
[2023-12-05T18:21:06.084+0000] {logging_mixin.py:154} INFO - [2023-12-05T18:21:06.081+0000] {dagbag.py:346} ERROR - Failed to import: /home/ubuntu/airflow/dags/etl.py
Traceback (most recent call last):
  File "/usr/local/lib/python3.10/dist-packages/airflow/models/dagbag.py", line 342, in parse
    loader.exec_module(new_module)
  File "<frozen importlib._bootstrap_external>", line 879, in exec_module
  File "<frozen importlib._bootstrap_external>", line 1017, in get_code
  File "<frozen importlib._bootstrap_external>", line 947, in source_to_code
  File "<frozen importlib._bootstrap>", line 241, in _call_with_frames_removed
  File "/home/ubuntu/airflow/dags/etl.py", line 7
    'start_date': datetime(2023, 5. 12),
                                 ^^^^^
SyntaxError: invalid syntax. Perhaps you forgot a comma?
[2023-12-05T18:21:06.089+0000] {processor.py:841} WARNING - No viable dags retrieved from /home/ubuntu/airflow/dags/etl.py
[2023-12-05T18:21:06.132+0000] {processor.py:179} INFO - Processing /home/ubuntu/airflow/dags/etl.py took 0.067 seconds
[2023-12-05T18:21:36.835+0000] {processor.py:157} INFO - Started process (PID=15881) to work on /home/ubuntu/airflow/dags/etl.py
[2023-12-05T18:21:36.836+0000] {processor.py:829} INFO - Processing file /home/ubuntu/airflow/dags/etl.py for tasks to queue
[2023-12-05T18:21:36.837+0000] {logging_mixin.py:154} INFO - [2023-12-05T18:21:36.836+0000] {dagbag.py:536} INFO - Filling up the DagBag from /home/ubuntu/airflow/dags/etl.py
[2023-12-05T18:21:36.841+0000] {logging_mixin.py:154} INFO - [2023-12-05T18:21:36.840+0000] {dagbag.py:346} ERROR - Failed to import: /home/ubuntu/airflow/dags/etl.py
Traceback (most recent call last):
  File "/usr/local/lib/python3.10/dist-packages/airflow/models/dagbag.py", line 342, in parse
    loader.exec_module(new_module)
  File "<frozen importlib._bootstrap_external>", line 879, in exec_module
  File "<frozen importlib._bootstrap_external>", line 1017, in get_code
  File "<frozen importlib._bootstrap_external>", line 947, in source_to_code
  File "<frozen importlib._bootstrap>", line 241, in _call_with_frames_removed
  File "/home/ubuntu/airflow/dags/etl.py", line 7
    'start_date': datetime(2023, 5. 12),
                                 ^^^^^
SyntaxError: invalid syntax. Perhaps you forgot a comma?
[2023-12-05T18:21:36.841+0000] {processor.py:841} WARNING - No viable dags retrieved from /home/ubuntu/airflow/dags/etl.py
[2023-12-05T18:21:36.864+0000] {processor.py:179} INFO - Processing /home/ubuntu/airflow/dags/etl.py took 0.034 seconds
[2023-12-05T18:22:07.516+0000] {processor.py:157} INFO - Started process (PID=15957) to work on /home/ubuntu/airflow/dags/etl.py
[2023-12-05T18:22:07.517+0000] {processor.py:829} INFO - Processing file /home/ubuntu/airflow/dags/etl.py for tasks to queue
[2023-12-05T18:22:07.518+0000] {logging_mixin.py:154} INFO - [2023-12-05T18:22:07.518+0000] {dagbag.py:536} INFO - Filling up the DagBag from /home/ubuntu/airflow/dags/etl.py
[2023-12-05T18:22:07.522+0000] {logging_mixin.py:154} INFO - [2023-12-05T18:22:07.520+0000] {dagbag.py:346} ERROR - Failed to import: /home/ubuntu/airflow/dags/etl.py
Traceback (most recent call last):
  File "/usr/local/lib/python3.10/dist-packages/airflow/models/dagbag.py", line 342, in parse
    loader.exec_module(new_module)
  File "<frozen importlib._bootstrap_external>", line 879, in exec_module
  File "<frozen importlib._bootstrap_external>", line 1017, in get_code
  File "<frozen importlib._bootstrap_external>", line 947, in source_to_code
  File "<frozen importlib._bootstrap>", line 241, in _call_with_frames_removed
  File "/home/ubuntu/airflow/dags/etl.py", line 7
    'start_date': datetime(2023, 5. 12),
                                 ^^^^^
SyntaxError: invalid syntax. Perhaps you forgot a comma?
[2023-12-05T18:22:07.522+0000] {processor.py:841} WARNING - No viable dags retrieved from /home/ubuntu/airflow/dags/etl.py
[2023-12-05T18:22:07.559+0000] {processor.py:179} INFO - Processing /home/ubuntu/airflow/dags/etl.py took 0.046 seconds
[2023-12-05T18:22:37.969+0000] {processor.py:157} INFO - Started process (PID=16134) to work on /home/ubuntu/airflow/dags/etl.py
[2023-12-05T18:22:37.970+0000] {processor.py:829} INFO - Processing file /home/ubuntu/airflow/dags/etl.py for tasks to queue
[2023-12-05T18:22:37.971+0000] {logging_mixin.py:154} INFO - [2023-12-05T18:22:37.971+0000] {dagbag.py:536} INFO - Filling up the DagBag from /home/ubuntu/airflow/dags/etl.py
[2023-12-05T18:22:37.976+0000] {logging_mixin.py:154} INFO - [2023-12-05T18:22:37.974+0000] {dagbag.py:346} ERROR - Failed to import: /home/ubuntu/airflow/dags/etl.py
Traceback (most recent call last):
  File "/usr/local/lib/python3.10/dist-packages/airflow/models/dagbag.py", line 342, in parse
    loader.exec_module(new_module)
  File "<frozen importlib._bootstrap_external>", line 879, in exec_module
  File "<frozen importlib._bootstrap_external>", line 1017, in get_code
  File "<frozen importlib._bootstrap_external>", line 947, in source_to_code
  File "<frozen importlib._bootstrap>", line 241, in _call_with_frames_removed
  File "/home/ubuntu/airflow/dags/etl.py", line 7
    'start_date': datetime(2023, 5. 12),
                                 ^^^^^
SyntaxError: invalid syntax. Perhaps you forgot a comma?
[2023-12-05T18:22:37.976+0000] {processor.py:841} WARNING - No viable dags retrieved from /home/ubuntu/airflow/dags/etl.py
[2023-12-05T18:22:37.999+0000] {processor.py:179} INFO - Processing /home/ubuntu/airflow/dags/etl.py took 0.036 seconds
[2023-12-05T18:23:08.150+0000] {processor.py:157} INFO - Started process (PID=16274) to work on /home/ubuntu/airflow/dags/etl.py
[2023-12-05T18:23:08.151+0000] {processor.py:829} INFO - Processing file /home/ubuntu/airflow/dags/etl.py for tasks to queue
[2023-12-05T18:23:08.152+0000] {logging_mixin.py:154} INFO - [2023-12-05T18:23:08.152+0000] {dagbag.py:536} INFO - Filling up the DagBag from /home/ubuntu/airflow/dags/etl.py
[2023-12-05T18:23:08.155+0000] {logging_mixin.py:154} INFO - [2023-12-05T18:23:08.154+0000] {dagbag.py:346} ERROR - Failed to import: /home/ubuntu/airflow/dags/etl.py
Traceback (most recent call last):
  File "/usr/local/lib/python3.10/dist-packages/airflow/models/dagbag.py", line 342, in parse
    loader.exec_module(new_module)
  File "<frozen importlib._bootstrap_external>", line 879, in exec_module
  File "<frozen importlib._bootstrap_external>", line 1017, in get_code
  File "<frozen importlib._bootstrap_external>", line 947, in source_to_code
  File "<frozen importlib._bootstrap>", line 241, in _call_with_frames_removed
  File "/home/ubuntu/airflow/dags/etl.py", line 7
    'start_date': datetime(2023, 5. 12),
                                 ^^^^^
SyntaxError: invalid syntax. Perhaps you forgot a comma?
[2023-12-05T18:23:08.156+0000] {processor.py:841} WARNING - No viable dags retrieved from /home/ubuntu/airflow/dags/etl.py
[2023-12-05T18:23:08.179+0000] {processor.py:179} INFO - Processing /home/ubuntu/airflow/dags/etl.py took 0.033 seconds
[2023-12-05T18:23:38.376+0000] {processor.py:157} INFO - Started process (PID=16403) to work on /home/ubuntu/airflow/dags/etl.py
[2023-12-05T18:23:38.378+0000] {processor.py:829} INFO - Processing file /home/ubuntu/airflow/dags/etl.py for tasks to queue
[2023-12-05T18:23:38.382+0000] {logging_mixin.py:154} INFO - [2023-12-05T18:23:38.379+0000] {dagbag.py:536} INFO - Filling up the DagBag from /home/ubuntu/airflow/dags/etl.py
[2023-12-05T18:23:38.389+0000] {logging_mixin.py:154} INFO - [2023-12-05T18:23:38.388+0000] {dagbag.py:346} ERROR - Failed to import: /home/ubuntu/airflow/dags/etl.py
Traceback (most recent call last):
  File "/usr/local/lib/python3.10/dist-packages/airflow/models/dagbag.py", line 342, in parse
    loader.exec_module(new_module)
  File "<frozen importlib._bootstrap_external>", line 879, in exec_module
  File "<frozen importlib._bootstrap_external>", line 1017, in get_code
  File "<frozen importlib._bootstrap_external>", line 947, in source_to_code
  File "<frozen importlib._bootstrap>", line 241, in _call_with_frames_removed
  File "/home/ubuntu/airflow/dags/etl.py", line 7
    'start_date': datetime(2023, 5. 12),
                                 ^^^^^
SyntaxError: invalid syntax. Perhaps you forgot a comma?
[2023-12-05T18:23:38.391+0000] {processor.py:841} WARNING - No viable dags retrieved from /home/ubuntu/airflow/dags/etl.py
[2023-12-05T18:23:38.416+0000] {processor.py:179} INFO - Processing /home/ubuntu/airflow/dags/etl.py took 0.044 seconds
[2023-12-05T18:24:08.565+0000] {processor.py:157} INFO - Started process (PID=16591) to work on /home/ubuntu/airflow/dags/etl.py
[2023-12-05T18:24:08.566+0000] {processor.py:829} INFO - Processing file /home/ubuntu/airflow/dags/etl.py for tasks to queue
[2023-12-05T18:24:08.567+0000] {logging_mixin.py:154} INFO - [2023-12-05T18:24:08.566+0000] {dagbag.py:536} INFO - Filling up the DagBag from /home/ubuntu/airflow/dags/etl.py
[2023-12-05T18:24:08.571+0000] {logging_mixin.py:154} INFO - [2023-12-05T18:24:08.569+0000] {dagbag.py:346} ERROR - Failed to import: /home/ubuntu/airflow/dags/etl.py
Traceback (most recent call last):
  File "/usr/local/lib/python3.10/dist-packages/airflow/models/dagbag.py", line 342, in parse
    loader.exec_module(new_module)
  File "<frozen importlib._bootstrap_external>", line 879, in exec_module
  File "<frozen importlib._bootstrap_external>", line 1017, in get_code
  File "<frozen importlib._bootstrap_external>", line 947, in source_to_code
  File "<frozen importlib._bootstrap>", line 241, in _call_with_frames_removed
  File "/home/ubuntu/airflow/dags/etl.py", line 7
    'start_date': datetime(2023, 5. 12),
                                 ^^^^^
SyntaxError: invalid syntax. Perhaps you forgot a comma?
[2023-12-05T18:24:08.571+0000] {processor.py:841} WARNING - No viable dags retrieved from /home/ubuntu/airflow/dags/etl.py
[2023-12-05T18:24:08.594+0000] {processor.py:179} INFO - Processing /home/ubuntu/airflow/dags/etl.py took 0.033 seconds
[2023-12-05T18:24:38.704+0000] {processor.py:157} INFO - Started process (PID=16738) to work on /home/ubuntu/airflow/dags/etl.py
[2023-12-05T18:24:38.705+0000] {processor.py:829} INFO - Processing file /home/ubuntu/airflow/dags/etl.py for tasks to queue
[2023-12-05T18:24:38.710+0000] {logging_mixin.py:154} INFO - [2023-12-05T18:24:38.709+0000] {dagbag.py:536} INFO - Filling up the DagBag from /home/ubuntu/airflow/dags/etl.py
[2023-12-05T18:24:38.718+0000] {logging_mixin.py:154} INFO - [2023-12-05T18:24:38.715+0000] {dagbag.py:346} ERROR - Failed to import: /home/ubuntu/airflow/dags/etl.py
Traceback (most recent call last):
  File "/usr/local/lib/python3.10/dist-packages/airflow/models/dagbag.py", line 342, in parse
    loader.exec_module(new_module)
  File "<frozen importlib._bootstrap_external>", line 879, in exec_module
  File "<frozen importlib._bootstrap_external>", line 1017, in get_code
  File "<frozen importlib._bootstrap_external>", line 947, in source_to_code
  File "<frozen importlib._bootstrap>", line 241, in _call_with_frames_removed
  File "/home/ubuntu/airflow/dags/etl.py", line 7
    'start_date': datetime(2023, 5. 12),
                                 ^^^^^
SyntaxError: invalid syntax. Perhaps you forgot a comma?
[2023-12-05T18:24:38.720+0000] {processor.py:841} WARNING - No viable dags retrieved from /home/ubuntu/airflow/dags/etl.py
[2023-12-05T18:24:38.750+0000] {processor.py:179} INFO - Processing /home/ubuntu/airflow/dags/etl.py took 0.052 seconds
[2023-12-05T18:25:08.893+0000] {processor.py:157} INFO - Started process (PID=16885) to work on /home/ubuntu/airflow/dags/etl.py
[2023-12-05T18:25:08.894+0000] {processor.py:829} INFO - Processing file /home/ubuntu/airflow/dags/etl.py for tasks to queue
[2023-12-05T18:25:08.895+0000] {logging_mixin.py:154} INFO - [2023-12-05T18:25:08.895+0000] {dagbag.py:536} INFO - Filling up the DagBag from /home/ubuntu/airflow/dags/etl.py
[2023-12-05T18:25:08.899+0000] {logging_mixin.py:154} INFO - [2023-12-05T18:25:08.897+0000] {dagbag.py:346} ERROR - Failed to import: /home/ubuntu/airflow/dags/etl.py
Traceback (most recent call last):
  File "/usr/local/lib/python3.10/dist-packages/airflow/models/dagbag.py", line 342, in parse
    loader.exec_module(new_module)
  File "<frozen importlib._bootstrap_external>", line 879, in exec_module
  File "<frozen importlib._bootstrap_external>", line 1017, in get_code
  File "<frozen importlib._bootstrap_external>", line 947, in source_to_code
  File "<frozen importlib._bootstrap>", line 241, in _call_with_frames_removed
  File "/home/ubuntu/airflow/dags/etl.py", line 7
    'start_date': datetime(2023, 5. 12),
                                 ^^^^^
SyntaxError: invalid syntax. Perhaps you forgot a comma?
[2023-12-05T18:25:08.899+0000] {processor.py:841} WARNING - No viable dags retrieved from /home/ubuntu/airflow/dags/etl.py
[2023-12-05T18:25:08.925+0000] {processor.py:179} INFO - Processing /home/ubuntu/airflow/dags/etl.py took 0.035 seconds
[2023-12-05T18:25:39.098+0000] {processor.py:157} INFO - Started process (PID=16992) to work on /home/ubuntu/airflow/dags/etl.py
[2023-12-05T18:25:39.101+0000] {processor.py:829} INFO - Processing file /home/ubuntu/airflow/dags/etl.py for tasks to queue
[2023-12-05T18:25:39.102+0000] {logging_mixin.py:154} INFO - [2023-12-05T18:25:39.101+0000] {dagbag.py:536} INFO - Filling up the DagBag from /home/ubuntu/airflow/dags/etl.py
[2023-12-05T18:25:39.108+0000] {logging_mixin.py:154} INFO - [2023-12-05T18:25:39.107+0000] {dagbag.py:346} ERROR - Failed to import: /home/ubuntu/airflow/dags/etl.py
Traceback (most recent call last):
  File "/usr/local/lib/python3.10/dist-packages/airflow/models/dagbag.py", line 342, in parse
    loader.exec_module(new_module)
  File "<frozen importlib._bootstrap_external>", line 879, in exec_module
  File "<frozen importlib._bootstrap_external>", line 1017, in get_code
  File "<frozen importlib._bootstrap_external>", line 947, in source_to_code
  File "<frozen importlib._bootstrap>", line 241, in _call_with_frames_removed
  File "/home/ubuntu/airflow/dags/etl.py", line 7
    'start_date': datetime(2023, 5. 12),
                                 ^^^^^
SyntaxError: invalid syntax. Perhaps you forgot a comma?
[2023-12-05T18:25:39.109+0000] {processor.py:841} WARNING - No viable dags retrieved from /home/ubuntu/airflow/dags/etl.py
[2023-12-05T18:25:39.131+0000] {processor.py:179} INFO - Processing /home/ubuntu/airflow/dags/etl.py took 0.042 seconds
[2023-12-05T18:26:09.280+0000] {processor.py:157} INFO - Started process (PID=17065) to work on /home/ubuntu/airflow/dags/etl.py
[2023-12-05T18:26:09.282+0000] {processor.py:829} INFO - Processing file /home/ubuntu/airflow/dags/etl.py for tasks to queue
[2023-12-05T18:26:09.283+0000] {logging_mixin.py:154} INFO - [2023-12-05T18:26:09.282+0000] {dagbag.py:536} INFO - Filling up the DagBag from /home/ubuntu/airflow/dags/etl.py
[2023-12-05T18:26:09.288+0000] {logging_mixin.py:154} INFO - [2023-12-05T18:26:09.286+0000] {dagbag.py:346} ERROR - Failed to import: /home/ubuntu/airflow/dags/etl.py
Traceback (most recent call last):
  File "/usr/local/lib/python3.10/dist-packages/airflow/models/dagbag.py", line 342, in parse
    loader.exec_module(new_module)
  File "<frozen importlib._bootstrap_external>", line 879, in exec_module
  File "<frozen importlib._bootstrap_external>", line 1017, in get_code
  File "<frozen importlib._bootstrap_external>", line 947, in source_to_code
  File "<frozen importlib._bootstrap>", line 241, in _call_with_frames_removed
  File "/home/ubuntu/airflow/dags/etl.py", line 7
    'start_date': datetime(2023, 5. 12),
                                 ^^^^^
SyntaxError: invalid syntax. Perhaps you forgot a comma?
[2023-12-05T18:26:09.289+0000] {processor.py:841} WARNING - No viable dags retrieved from /home/ubuntu/airflow/dags/etl.py
[2023-12-05T18:26:09.332+0000] {processor.py:179} INFO - Processing /home/ubuntu/airflow/dags/etl.py took 0.056 seconds
[2023-12-05T18:26:39.492+0000] {processor.py:157} INFO - Started process (PID=17299) to work on /home/ubuntu/airflow/dags/etl.py
[2023-12-05T18:26:39.494+0000] {processor.py:829} INFO - Processing file /home/ubuntu/airflow/dags/etl.py for tasks to queue
[2023-12-05T18:26:39.494+0000] {logging_mixin.py:154} INFO - [2023-12-05T18:26:39.494+0000] {dagbag.py:536} INFO - Filling up the DagBag from /home/ubuntu/airflow/dags/etl.py
[2023-12-05T18:26:39.499+0000] {logging_mixin.py:154} INFO - [2023-12-05T18:26:39.497+0000] {dagbag.py:346} ERROR - Failed to import: /home/ubuntu/airflow/dags/etl.py
Traceback (most recent call last):
  File "/usr/local/lib/python3.10/dist-packages/airflow/models/dagbag.py", line 342, in parse
    loader.exec_module(new_module)
  File "<frozen importlib._bootstrap_external>", line 879, in exec_module
  File "<frozen importlib._bootstrap_external>", line 1017, in get_code
  File "<frozen importlib._bootstrap_external>", line 947, in source_to_code
  File "<frozen importlib._bootstrap>", line 241, in _call_with_frames_removed
  File "/home/ubuntu/airflow/dags/etl.py", line 7
    'start_date': datetime(2023, 5. 12),
                                 ^^^^^
SyntaxError: invalid syntax. Perhaps you forgot a comma?
[2023-12-05T18:26:39.499+0000] {processor.py:841} WARNING - No viable dags retrieved from /home/ubuntu/airflow/dags/etl.py
[2023-12-05T18:26:39.528+0000] {processor.py:179} INFO - Processing /home/ubuntu/airflow/dags/etl.py took 0.040 seconds
[2023-12-05T18:27:09.685+0000] {processor.py:157} INFO - Started process (PID=17417) to work on /home/ubuntu/airflow/dags/etl.py
[2023-12-05T18:27:09.688+0000] {processor.py:829} INFO - Processing file /home/ubuntu/airflow/dags/etl.py for tasks to queue
[2023-12-05T18:27:09.690+0000] {logging_mixin.py:154} INFO - [2023-12-05T18:27:09.690+0000] {dagbag.py:536} INFO - Filling up the DagBag from /home/ubuntu/airflow/dags/etl.py
[2023-12-05T18:27:09.702+0000] {logging_mixin.py:154} INFO - [2023-12-05T18:27:09.701+0000] {dagbag.py:346} ERROR - Failed to import: /home/ubuntu/airflow/dags/etl.py
Traceback (most recent call last):
  File "/usr/local/lib/python3.10/dist-packages/airflow/models/dagbag.py", line 342, in parse
    loader.exec_module(new_module)
  File "<frozen importlib._bootstrap_external>", line 879, in exec_module
  File "<frozen importlib._bootstrap_external>", line 1017, in get_code
  File "<frozen importlib._bootstrap_external>", line 947, in source_to_code
  File "<frozen importlib._bootstrap>", line 241, in _call_with_frames_removed
  File "/home/ubuntu/airflow/dags/etl.py", line 7
    'start_date': datetime(2023, 5. 12),
                                 ^^^^^
SyntaxError: invalid syntax. Perhaps you forgot a comma?
[2023-12-05T18:27:09.703+0000] {processor.py:841} WARNING - No viable dags retrieved from /home/ubuntu/airflow/dags/etl.py
[2023-12-05T18:27:09.744+0000] {processor.py:179} INFO - Processing /home/ubuntu/airflow/dags/etl.py took 0.067 seconds
[2023-12-05T18:27:39.876+0000] {processor.py:157} INFO - Started process (PID=17490) to work on /home/ubuntu/airflow/dags/etl.py
[2023-12-05T18:27:39.877+0000] {processor.py:829} INFO - Processing file /home/ubuntu/airflow/dags/etl.py for tasks to queue
[2023-12-05T18:27:39.879+0000] {logging_mixin.py:154} INFO - [2023-12-05T18:27:39.879+0000] {dagbag.py:536} INFO - Filling up the DagBag from /home/ubuntu/airflow/dags/etl.py
[2023-12-05T18:27:39.883+0000] {logging_mixin.py:154} INFO - [2023-12-05T18:27:39.881+0000] {dagbag.py:346} ERROR - Failed to import: /home/ubuntu/airflow/dags/etl.py
Traceback (most recent call last):
  File "/usr/local/lib/python3.10/dist-packages/airflow/models/dagbag.py", line 342, in parse
    loader.exec_module(new_module)
  File "<frozen importlib._bootstrap_external>", line 879, in exec_module
  File "<frozen importlib._bootstrap_external>", line 1017, in get_code
  File "<frozen importlib._bootstrap_external>", line 947, in source_to_code
  File "<frozen importlib._bootstrap>", line 241, in _call_with_frames_removed
  File "/home/ubuntu/airflow/dags/etl.py", line 7
    'start_date': datetime(2023, 5. 12),
                                 ^^^^^
SyntaxError: invalid syntax. Perhaps you forgot a comma?
[2023-12-05T18:27:39.883+0000] {processor.py:841} WARNING - No viable dags retrieved from /home/ubuntu/airflow/dags/etl.py
[2023-12-05T18:27:39.919+0000] {processor.py:179} INFO - Processing /home/ubuntu/airflow/dags/etl.py took 0.048 seconds
[2023-12-05T18:28:10.033+0000] {processor.py:157} INFO - Started process (PID=17677) to work on /home/ubuntu/airflow/dags/etl.py
[2023-12-05T18:28:10.035+0000] {processor.py:829} INFO - Processing file /home/ubuntu/airflow/dags/etl.py for tasks to queue
[2023-12-05T18:28:10.036+0000] {logging_mixin.py:154} INFO - [2023-12-05T18:28:10.035+0000] {dagbag.py:536} INFO - Filling up the DagBag from /home/ubuntu/airflow/dags/etl.py
[2023-12-05T18:28:10.044+0000] {logging_mixin.py:154} INFO - [2023-12-05T18:28:10.042+0000] {dagbag.py:346} ERROR - Failed to import: /home/ubuntu/airflow/dags/etl.py
Traceback (most recent call last):
  File "/usr/local/lib/python3.10/dist-packages/airflow/models/dagbag.py", line 342, in parse
    loader.exec_module(new_module)
  File "<frozen importlib._bootstrap_external>", line 879, in exec_module
  File "<frozen importlib._bootstrap_external>", line 1017, in get_code
  File "<frozen importlib._bootstrap_external>", line 947, in source_to_code
  File "<frozen importlib._bootstrap>", line 241, in _call_with_frames_removed
  File "/home/ubuntu/airflow/dags/etl.py", line 7
    'start_date': datetime(2023, 5. 12),
                                 ^^^^^
SyntaxError: invalid syntax. Perhaps you forgot a comma?
[2023-12-05T18:28:10.044+0000] {processor.py:841} WARNING - No viable dags retrieved from /home/ubuntu/airflow/dags/etl.py
[2023-12-05T18:28:10.083+0000] {processor.py:179} INFO - Processing /home/ubuntu/airflow/dags/etl.py took 0.055 seconds
[2023-12-05T18:28:40.213+0000] {processor.py:157} INFO - Started process (PID=17816) to work on /home/ubuntu/airflow/dags/etl.py
[2023-12-05T18:28:40.214+0000] {processor.py:829} INFO - Processing file /home/ubuntu/airflow/dags/etl.py for tasks to queue
[2023-12-05T18:28:40.216+0000] {logging_mixin.py:154} INFO - [2023-12-05T18:28:40.215+0000] {dagbag.py:536} INFO - Filling up the DagBag from /home/ubuntu/airflow/dags/etl.py
[2023-12-05T18:28:40.219+0000] {logging_mixin.py:154} INFO - [2023-12-05T18:28:40.218+0000] {dagbag.py:346} ERROR - Failed to import: /home/ubuntu/airflow/dags/etl.py
Traceback (most recent call last):
  File "/usr/local/lib/python3.10/dist-packages/airflow/models/dagbag.py", line 342, in parse
    loader.exec_module(new_module)
  File "<frozen importlib._bootstrap_external>", line 879, in exec_module
  File "<frozen importlib._bootstrap_external>", line 1017, in get_code
  File "<frozen importlib._bootstrap_external>", line 947, in source_to_code
  File "<frozen importlib._bootstrap>", line 241, in _call_with_frames_removed
  File "/home/ubuntu/airflow/dags/etl.py", line 7
    'start_date': datetime(2023, 5. 12),
                                 ^^^^^
SyntaxError: invalid syntax. Perhaps you forgot a comma?
[2023-12-05T18:28:40.220+0000] {processor.py:841} WARNING - No viable dags retrieved from /home/ubuntu/airflow/dags/etl.py
[2023-12-05T18:28:40.242+0000] {processor.py:179} INFO - Processing /home/ubuntu/airflow/dags/etl.py took 0.035 seconds
[2023-12-05T18:29:10.404+0000] {processor.py:157} INFO - Started process (PID=17895) to work on /home/ubuntu/airflow/dags/etl.py
[2023-12-05T18:29:10.406+0000] {processor.py:829} INFO - Processing file /home/ubuntu/airflow/dags/etl.py for tasks to queue
[2023-12-05T18:29:10.407+0000] {logging_mixin.py:154} INFO - [2023-12-05T18:29:10.407+0000] {dagbag.py:536} INFO - Filling up the DagBag from /home/ubuntu/airflow/dags/etl.py
[2023-12-05T18:29:10.413+0000] {logging_mixin.py:154} INFO - [2023-12-05T18:29:10.412+0000] {dagbag.py:346} ERROR - Failed to import: /home/ubuntu/airflow/dags/etl.py
Traceback (most recent call last):
  File "/usr/local/lib/python3.10/dist-packages/airflow/models/dagbag.py", line 342, in parse
    loader.exec_module(new_module)
  File "<frozen importlib._bootstrap_external>", line 879, in exec_module
  File "<frozen importlib._bootstrap_external>", line 1017, in get_code
  File "<frozen importlib._bootstrap_external>", line 947, in source_to_code
  File "<frozen importlib._bootstrap>", line 241, in _call_with_frames_removed
  File "/home/ubuntu/airflow/dags/etl.py", line 7
    'start_date': datetime(2023, 5. 12),
                                 ^^^^^
SyntaxError: invalid syntax. Perhaps you forgot a comma?
[2023-12-05T18:29:10.414+0000] {processor.py:841} WARNING - No viable dags retrieved from /home/ubuntu/airflow/dags/etl.py
[2023-12-05T18:29:10.447+0000] {processor.py:179} INFO - Processing /home/ubuntu/airflow/dags/etl.py took 0.048 seconds
[2023-12-05T18:29:40.602+0000] {processor.py:157} INFO - Started process (PID=17944) to work on /home/ubuntu/airflow/dags/etl.py
[2023-12-05T18:29:40.603+0000] {processor.py:829} INFO - Processing file /home/ubuntu/airflow/dags/etl.py for tasks to queue
[2023-12-05T18:29:40.604+0000] {logging_mixin.py:154} INFO - [2023-12-05T18:29:40.604+0000] {dagbag.py:536} INFO - Filling up the DagBag from /home/ubuntu/airflow/dags/etl.py
[2023-12-05T18:29:40.607+0000] {logging_mixin.py:154} INFO - [2023-12-05T18:29:40.606+0000] {dagbag.py:346} ERROR - Failed to import: /home/ubuntu/airflow/dags/etl.py
Traceback (most recent call last):
  File "/usr/local/lib/python3.10/dist-packages/airflow/models/dagbag.py", line 342, in parse
    loader.exec_module(new_module)
  File "<frozen importlib._bootstrap_external>", line 879, in exec_module
  File "<frozen importlib._bootstrap_external>", line 1017, in get_code
  File "<frozen importlib._bootstrap_external>", line 947, in source_to_code
  File "<frozen importlib._bootstrap>", line 241, in _call_with_frames_removed
  File "/home/ubuntu/airflow/dags/etl.py", line 7
    'start_date': datetime(2023, 5. 12),
                                 ^^^^^
SyntaxError: invalid syntax. Perhaps you forgot a comma?
[2023-12-05T18:29:40.608+0000] {processor.py:841} WARNING - No viable dags retrieved from /home/ubuntu/airflow/dags/etl.py
[2023-12-05T18:29:40.631+0000] {processor.py:179} INFO - Processing /home/ubuntu/airflow/dags/etl.py took 0.032 seconds
[2023-12-05T18:30:10.791+0000] {processor.py:157} INFO - Started process (PID=18108) to work on /home/ubuntu/airflow/dags/etl.py
[2023-12-05T18:30:10.792+0000] {processor.py:829} INFO - Processing file /home/ubuntu/airflow/dags/etl.py for tasks to queue
[2023-12-05T18:30:10.793+0000] {logging_mixin.py:154} INFO - [2023-12-05T18:30:10.793+0000] {dagbag.py:536} INFO - Filling up the DagBag from /home/ubuntu/airflow/dags/etl.py
[2023-12-05T18:30:10.797+0000] {logging_mixin.py:154} INFO - [2023-12-05T18:30:10.796+0000] {dagbag.py:346} ERROR - Failed to import: /home/ubuntu/airflow/dags/etl.py
Traceback (most recent call last):
  File "/usr/local/lib/python3.10/dist-packages/airflow/models/dagbag.py", line 342, in parse
    loader.exec_module(new_module)
  File "<frozen importlib._bootstrap_external>", line 879, in exec_module
  File "<frozen importlib._bootstrap_external>", line 1017, in get_code
  File "<frozen importlib._bootstrap_external>", line 947, in source_to_code
  File "<frozen importlib._bootstrap>", line 241, in _call_with_frames_removed
  File "/home/ubuntu/airflow/dags/etl.py", line 7
    'start_date': datetime(2023, 5. 12),
                                 ^^^^^
SyntaxError: invalid syntax. Perhaps you forgot a comma?
[2023-12-05T18:30:10.797+0000] {processor.py:841} WARNING - No viable dags retrieved from /home/ubuntu/airflow/dags/etl.py
[2023-12-05T18:30:10.819+0000] {processor.py:179} INFO - Processing /home/ubuntu/airflow/dags/etl.py took 0.034 seconds
[2023-12-05T18:30:40.994+0000] {processor.py:157} INFO - Started process (PID=18204) to work on /home/ubuntu/airflow/dags/etl.py
[2023-12-05T18:30:40.998+0000] {processor.py:829} INFO - Processing file /home/ubuntu/airflow/dags/etl.py for tasks to queue
[2023-12-05T18:30:41.002+0000] {logging_mixin.py:154} INFO - [2023-12-05T18:30:41.000+0000] {dagbag.py:536} INFO - Filling up the DagBag from /home/ubuntu/airflow/dags/etl.py
[2023-12-05T18:30:41.009+0000] {logging_mixin.py:154} INFO - [2023-12-05T18:30:41.007+0000] {dagbag.py:346} ERROR - Failed to import: /home/ubuntu/airflow/dags/etl.py
Traceback (most recent call last):
  File "/usr/local/lib/python3.10/dist-packages/airflow/models/dagbag.py", line 342, in parse
    loader.exec_module(new_module)
  File "<frozen importlib._bootstrap_external>", line 879, in exec_module
  File "<frozen importlib._bootstrap_external>", line 1017, in get_code
  File "<frozen importlib._bootstrap_external>", line 947, in source_to_code
  File "<frozen importlib._bootstrap>", line 241, in _call_with_frames_removed
  File "/home/ubuntu/airflow/dags/etl.py", line 7
    'start_date': datetime(2023, 5. 12),
                                 ^^^^^
SyntaxError: invalid syntax. Perhaps you forgot a comma?
[2023-12-05T18:30:41.010+0000] {processor.py:841} WARNING - No viable dags retrieved from /home/ubuntu/airflow/dags/etl.py
[2023-12-05T18:30:41.055+0000] {processor.py:179} INFO - Processing /home/ubuntu/airflow/dags/etl.py took 0.074 seconds
[2023-12-05T18:31:11.235+0000] {processor.py:157} INFO - Started process (PID=18529) to work on /home/ubuntu/airflow/dags/etl.py
[2023-12-05T18:31:11.237+0000] {processor.py:829} INFO - Processing file /home/ubuntu/airflow/dags/etl.py for tasks to queue
[2023-12-05T18:31:11.238+0000] {logging_mixin.py:154} INFO - [2023-12-05T18:31:11.237+0000] {dagbag.py:536} INFO - Filling up the DagBag from /home/ubuntu/airflow/dags/etl.py
[2023-12-05T18:31:11.242+0000] {logging_mixin.py:154} INFO - [2023-12-05T18:31:11.241+0000] {dagbag.py:346} ERROR - Failed to import: /home/ubuntu/airflow/dags/etl.py
Traceback (most recent call last):
  File "/usr/local/lib/python3.10/dist-packages/airflow/models/dagbag.py", line 342, in parse
    loader.exec_module(new_module)
  File "<frozen importlib._bootstrap_external>", line 879, in exec_module
  File "<frozen importlib._bootstrap_external>", line 1017, in get_code
  File "<frozen importlib._bootstrap_external>", line 947, in source_to_code
  File "<frozen importlib._bootstrap>", line 241, in _call_with_frames_removed
  File "/home/ubuntu/airflow/dags/etl.py", line 7
    'start_date': datetime(2023, 5. 12),
                                 ^^^^^
SyntaxError: invalid syntax. Perhaps you forgot a comma?
[2023-12-05T18:31:11.242+0000] {processor.py:841} WARNING - No viable dags retrieved from /home/ubuntu/airflow/dags/etl.py
[2023-12-05T18:31:11.262+0000] {processor.py:179} INFO - Processing /home/ubuntu/airflow/dags/etl.py took 0.031 seconds
[2023-12-05T18:31:31.061+0000] {processor.py:157} INFO - Started process (PID=18594) to work on /home/ubuntu/airflow/dags/etl.py
[2023-12-05T18:31:31.062+0000] {processor.py:829} INFO - Processing file /home/ubuntu/airflow/dags/etl.py for tasks to queue
[2023-12-05T18:31:31.062+0000] {logging_mixin.py:154} INFO - [2023-12-05T18:31:31.062+0000] {dagbag.py:536} INFO - Filling up the DagBag from /home/ubuntu/airflow/dags/etl.py
[2023-12-05T18:31:31.066+0000] {logging_mixin.py:154} INFO - [2023-12-05T18:31:31.065+0000] {dagbag.py:346} ERROR - Failed to import: /home/ubuntu/airflow/dags/etl.py
Traceback (most recent call last):
  File "/usr/local/lib/python3.10/dist-packages/airflow/models/dagbag.py", line 342, in parse
    loader.exec_module(new_module)
  File "<frozen importlib._bootstrap_external>", line 879, in exec_module
  File "<frozen importlib._bootstrap_external>", line 1017, in get_code
  File "<frozen importlib._bootstrap_external>", line 947, in source_to_code
  File "<frozen importlib._bootstrap>", line 241, in _call_with_frames_removed
  File "/home/ubuntu/airflow/dags/etl.py", line 9
    'start_date': datetime(2023, 5. 12),
                                 ^^^^^
SyntaxError: invalid syntax. Perhaps you forgot a comma?
[2023-12-05T18:31:31.067+0000] {processor.py:841} WARNING - No viable dags retrieved from /home/ubuntu/airflow/dags/etl.py
[2023-12-05T18:31:31.090+0000] {processor.py:179} INFO - Processing /home/ubuntu/airflow/dags/etl.py took 0.035 seconds
[2023-12-05T18:32:01.304+0000] {processor.py:157} INFO - Started process (PID=18618) to work on /home/ubuntu/airflow/dags/etl.py
[2023-12-05T18:32:01.306+0000] {processor.py:829} INFO - Processing file /home/ubuntu/airflow/dags/etl.py for tasks to queue
[2023-12-05T18:32:01.307+0000] {logging_mixin.py:154} INFO - [2023-12-05T18:32:01.307+0000] {dagbag.py:536} INFO - Filling up the DagBag from /home/ubuntu/airflow/dags/etl.py
[2023-12-05T18:32:01.311+0000] {logging_mixin.py:154} INFO - [2023-12-05T18:32:01.310+0000] {dagbag.py:346} ERROR - Failed to import: /home/ubuntu/airflow/dags/etl.py
Traceback (most recent call last):
  File "/usr/local/lib/python3.10/dist-packages/airflow/models/dagbag.py", line 342, in parse
    loader.exec_module(new_module)
  File "<frozen importlib._bootstrap_external>", line 879, in exec_module
  File "<frozen importlib._bootstrap_external>", line 1017, in get_code
  File "<frozen importlib._bootstrap_external>", line 947, in source_to_code
  File "<frozen importlib._bootstrap>", line 241, in _call_with_frames_removed
  File "/home/ubuntu/airflow/dags/etl.py", line 9
    'start_date': datetime(2023, 5. 12),
                                 ^^^^^
SyntaxError: invalid syntax. Perhaps you forgot a comma?
[2023-12-05T18:32:01.312+0000] {processor.py:841} WARNING - No viable dags retrieved from /home/ubuntu/airflow/dags/etl.py
[2023-12-05T18:32:01.332+0000] {processor.py:179} INFO - Processing /home/ubuntu/airflow/dags/etl.py took 0.032 seconds
[2023-12-05T18:32:31.649+0000] {processor.py:157} INFO - Started process (PID=18697) to work on /home/ubuntu/airflow/dags/etl.py
[2023-12-05T18:32:31.650+0000] {processor.py:829} INFO - Processing file /home/ubuntu/airflow/dags/etl.py for tasks to queue
[2023-12-05T18:32:31.651+0000] {logging_mixin.py:154} INFO - [2023-12-05T18:32:31.651+0000] {dagbag.py:536} INFO - Filling up the DagBag from /home/ubuntu/airflow/dags/etl.py
[2023-12-05T18:32:31.654+0000] {logging_mixin.py:154} INFO - [2023-12-05T18:32:31.653+0000] {dagbag.py:346} ERROR - Failed to import: /home/ubuntu/airflow/dags/etl.py
Traceback (most recent call last):
  File "/usr/local/lib/python3.10/dist-packages/airflow/models/dagbag.py", line 342, in parse
    loader.exec_module(new_module)
  File "<frozen importlib._bootstrap_external>", line 879, in exec_module
  File "<frozen importlib._bootstrap_external>", line 1017, in get_code
  File "<frozen importlib._bootstrap_external>", line 947, in source_to_code
  File "<frozen importlib._bootstrap>", line 241, in _call_with_frames_removed
  File "/home/ubuntu/airflow/dags/etl.py", line 9
    'start_date': datetime(2023, 5. 12),
                                 ^^^^^
SyntaxError: invalid syntax. Perhaps you forgot a comma?
[2023-12-05T18:32:31.655+0000] {processor.py:841} WARNING - No viable dags retrieved from /home/ubuntu/airflow/dags/etl.py
[2023-12-05T18:32:31.680+0000] {processor.py:179} INFO - Processing /home/ubuntu/airflow/dags/etl.py took 0.035 seconds
[2023-12-05T18:32:59.754+0000] {processor.py:157} INFO - Started process (PID=18717) to work on /home/ubuntu/airflow/dags/etl.py
[2023-12-05T18:32:59.755+0000] {processor.py:829} INFO - Processing file /home/ubuntu/airflow/dags/etl.py for tasks to queue
[2023-12-05T18:32:59.756+0000] {logging_mixin.py:154} INFO - [2023-12-05T18:32:59.756+0000] {dagbag.py:536} INFO - Filling up the DagBag from /home/ubuntu/airflow/dags/etl.py
[2023-12-05T18:32:59.759+0000] {logging_mixin.py:154} INFO - [2023-12-05T18:32:59.758+0000] {dagbag.py:346} ERROR - Failed to import: /home/ubuntu/airflow/dags/etl.py
Traceback (most recent call last):
  File "/usr/local/lib/python3.10/dist-packages/airflow/models/dagbag.py", line 342, in parse
    loader.exec_module(new_module)
  File "<frozen importlib._bootstrap_external>", line 879, in exec_module
  File "<frozen importlib._bootstrap_external>", line 1017, in get_code
  File "<frozen importlib._bootstrap_external>", line 947, in source_to_code
  File "<frozen importlib._bootstrap>", line 241, in _call_with_frames_removed
  File "/home/ubuntu/airflow/dags/etl.py", line 9
    'start_date': datetime(2023, 5. 12),
                                 ^^^^^
SyntaxError: invalid syntax. Perhaps you forgot a comma?
[2023-12-05T18:32:59.759+0000] {processor.py:841} WARNING - No viable dags retrieved from /home/ubuntu/airflow/dags/etl.py
[2023-12-05T18:32:59.782+0000] {processor.py:179} INFO - Processing /home/ubuntu/airflow/dags/etl.py took 0.032 seconds
[2023-12-05T18:33:30.158+0000] {processor.py:157} INFO - Started process (PID=18796) to work on /home/ubuntu/airflow/dags/etl.py
[2023-12-05T18:33:30.159+0000] {processor.py:829} INFO - Processing file /home/ubuntu/airflow/dags/etl.py for tasks to queue
[2023-12-05T18:33:30.160+0000] {logging_mixin.py:154} INFO - [2023-12-05T18:33:30.160+0000] {dagbag.py:536} INFO - Filling up the DagBag from /home/ubuntu/airflow/dags/etl.py
[2023-12-05T18:33:30.164+0000] {logging_mixin.py:154} INFO - [2023-12-05T18:33:30.163+0000] {dagbag.py:346} ERROR - Failed to import: /home/ubuntu/airflow/dags/etl.py
Traceback (most recent call last):
  File "/usr/local/lib/python3.10/dist-packages/airflow/models/dagbag.py", line 342, in parse
    loader.exec_module(new_module)
  File "<frozen importlib._bootstrap_external>", line 879, in exec_module
  File "<frozen importlib._bootstrap_external>", line 1017, in get_code
  File "<frozen importlib._bootstrap_external>", line 947, in source_to_code
  File "<frozen importlib._bootstrap>", line 241, in _call_with_frames_removed
  File "/home/ubuntu/airflow/dags/etl.py", line 9
    'start_date': datetime(2023, 5. 12),
                                 ^^^^^
SyntaxError: invalid syntax. Perhaps you forgot a comma?
[2023-12-05T18:33:30.165+0000] {processor.py:841} WARNING - No viable dags retrieved from /home/ubuntu/airflow/dags/etl.py
[2023-12-05T18:33:30.190+0000] {processor.py:179} INFO - Processing /home/ubuntu/airflow/dags/etl.py took 0.035 seconds
[2023-12-05T18:34:00.569+0000] {processor.py:157} INFO - Started process (PID=18815) to work on /home/ubuntu/airflow/dags/etl.py
[2023-12-05T18:34:00.570+0000] {processor.py:829} INFO - Processing file /home/ubuntu/airflow/dags/etl.py for tasks to queue
[2023-12-05T18:34:00.571+0000] {logging_mixin.py:154} INFO - [2023-12-05T18:34:00.570+0000] {dagbag.py:536} INFO - Filling up the DagBag from /home/ubuntu/airflow/dags/etl.py
[2023-12-05T18:34:00.574+0000] {logging_mixin.py:154} INFO - [2023-12-05T18:34:00.573+0000] {dagbag.py:346} ERROR - Failed to import: /home/ubuntu/airflow/dags/etl.py
Traceback (most recent call last):
  File "/usr/local/lib/python3.10/dist-packages/airflow/models/dagbag.py", line 342, in parse
    loader.exec_module(new_module)
  File "<frozen importlib._bootstrap_external>", line 879, in exec_module
  File "<frozen importlib._bootstrap_external>", line 1017, in get_code
  File "<frozen importlib._bootstrap_external>", line 947, in source_to_code
  File "<frozen importlib._bootstrap>", line 241, in _call_with_frames_removed
  File "/home/ubuntu/airflow/dags/etl.py", line 9
    'start_date': datetime(2023, 5. 12),
                                 ^^^^^
SyntaxError: invalid syntax. Perhaps you forgot a comma?
[2023-12-05T18:34:00.575+0000] {processor.py:841} WARNING - No viable dags retrieved from /home/ubuntu/airflow/dags/etl.py
[2023-12-05T18:34:00.597+0000] {processor.py:179} INFO - Processing /home/ubuntu/airflow/dags/etl.py took 0.031 seconds
[2023-12-05T18:34:30.969+0000] {processor.py:157} INFO - Started process (PID=18942) to work on /home/ubuntu/airflow/dags/etl.py
[2023-12-05T18:34:30.971+0000] {processor.py:829} INFO - Processing file /home/ubuntu/airflow/dags/etl.py for tasks to queue
[2023-12-05T18:34:30.972+0000] {logging_mixin.py:154} INFO - [2023-12-05T18:34:30.971+0000] {dagbag.py:536} INFO - Filling up the DagBag from /home/ubuntu/airflow/dags/etl.py
[2023-12-05T18:34:30.976+0000] {logging_mixin.py:154} INFO - [2023-12-05T18:34:30.975+0000] {dagbag.py:346} ERROR - Failed to import: /home/ubuntu/airflow/dags/etl.py
Traceback (most recent call last):
  File "/usr/local/lib/python3.10/dist-packages/airflow/models/dagbag.py", line 342, in parse
    loader.exec_module(new_module)
  File "<frozen importlib._bootstrap_external>", line 879, in exec_module
  File "<frozen importlib._bootstrap_external>", line 1017, in get_code
  File "<frozen importlib._bootstrap_external>", line 947, in source_to_code
  File "<frozen importlib._bootstrap>", line 241, in _call_with_frames_removed
  File "/home/ubuntu/airflow/dags/etl.py", line 9
    'start_date': datetime(2023, 5. 12),
                                 ^^^^^
SyntaxError: invalid syntax. Perhaps you forgot a comma?
[2023-12-05T18:34:30.977+0000] {processor.py:841} WARNING - No viable dags retrieved from /home/ubuntu/airflow/dags/etl.py
[2023-12-05T18:34:31.003+0000] {processor.py:179} INFO - Processing /home/ubuntu/airflow/dags/etl.py took 0.038 seconds
[2023-12-05T18:35:01.163+0000] {processor.py:157} INFO - Started process (PID=18966) to work on /home/ubuntu/airflow/dags/etl.py
[2023-12-05T18:35:01.164+0000] {processor.py:829} INFO - Processing file /home/ubuntu/airflow/dags/etl.py for tasks to queue
[2023-12-05T18:35:01.165+0000] {logging_mixin.py:154} INFO - [2023-12-05T18:35:01.164+0000] {dagbag.py:536} INFO - Filling up the DagBag from /home/ubuntu/airflow/dags/etl.py
[2023-12-05T18:35:01.168+0000] {logging_mixin.py:154} INFO - [2023-12-05T18:35:01.167+0000] {dagbag.py:346} ERROR - Failed to import: /home/ubuntu/airflow/dags/etl.py
Traceback (most recent call last):
  File "/usr/local/lib/python3.10/dist-packages/airflow/models/dagbag.py", line 342, in parse
    loader.exec_module(new_module)
  File "<frozen importlib._bootstrap_external>", line 879, in exec_module
  File "<frozen importlib._bootstrap_external>", line 1017, in get_code
  File "<frozen importlib._bootstrap_external>", line 947, in source_to_code
  File "<frozen importlib._bootstrap>", line 241, in _call_with_frames_removed
  File "/home/ubuntu/airflow/dags/etl.py", line 9
    'start_date': datetime(2023, 5. 12),
                                 ^^^^^
SyntaxError: invalid syntax. Perhaps you forgot a comma?
[2023-12-05T18:35:01.170+0000] {processor.py:841} WARNING - No viable dags retrieved from /home/ubuntu/airflow/dags/etl.py
[2023-12-05T18:35:01.200+0000] {processor.py:179} INFO - Processing /home/ubuntu/airflow/dags/etl.py took 0.041 seconds
[2023-12-05T18:35:09.170+0000] {processor.py:157} INFO - Started process (PID=19030) to work on /home/ubuntu/airflow/dags/etl.py
[2023-12-05T18:35:09.172+0000] {processor.py:829} INFO - Processing file /home/ubuntu/airflow/dags/etl.py for tasks to queue
[2023-12-05T18:35:09.176+0000] {logging_mixin.py:154} INFO - [2023-12-05T18:35:09.175+0000] {dagbag.py:536} INFO - Filling up the DagBag from /home/ubuntu/airflow/dags/etl.py
[2023-12-05T18:35:09.185+0000] {logging_mixin.py:154} INFO - [2023-12-05T18:35:09.183+0000] {dagbag.py:346} ERROR - Failed to import: /home/ubuntu/airflow/dags/etl.py
Traceback (most recent call last):
  File "/usr/local/lib/python3.10/dist-packages/airflow/models/dagbag.py", line 342, in parse
    loader.exec_module(new_module)
  File "<frozen importlib._bootstrap_external>", line 879, in exec_module
  File "<frozen importlib._bootstrap_external>", line 1017, in get_code
  File "<frozen importlib._bootstrap_external>", line 947, in source_to_code
  File "<frozen importlib._bootstrap>", line 241, in _call_with_frames_removed
  File "/home/ubuntu/airflow/dags/etl.py", line 10
    'start_date': datetime(2023, 5. 12),
                                 ^^^^^
SyntaxError: invalid syntax. Perhaps you forgot a comma?
[2023-12-05T18:35:09.186+0000] {processor.py:841} WARNING - No viable dags retrieved from /home/ubuntu/airflow/dags/etl.py
[2023-12-05T18:35:09.213+0000] {processor.py:179} INFO - Processing /home/ubuntu/airflow/dags/etl.py took 0.047 seconds
[2023-12-05T18:35:39.890+0000] {processor.py:157} INFO - Started process (PID=19046) to work on /home/ubuntu/airflow/dags/etl.py
[2023-12-05T18:35:39.891+0000] {processor.py:829} INFO - Processing file /home/ubuntu/airflow/dags/etl.py for tasks to queue
[2023-12-05T18:35:39.892+0000] {logging_mixin.py:154} INFO - [2023-12-05T18:35:39.891+0000] {dagbag.py:536} INFO - Filling up the DagBag from /home/ubuntu/airflow/dags/etl.py
[2023-12-05T18:35:39.897+0000] {logging_mixin.py:154} INFO - [2023-12-05T18:35:39.896+0000] {dagbag.py:346} ERROR - Failed to import: /home/ubuntu/airflow/dags/etl.py
Traceback (most recent call last):
  File "/usr/local/lib/python3.10/dist-packages/airflow/models/dagbag.py", line 342, in parse
    loader.exec_module(new_module)
  File "<frozen importlib._bootstrap_external>", line 879, in exec_module
  File "<frozen importlib._bootstrap_external>", line 1017, in get_code
  File "<frozen importlib._bootstrap_external>", line 947, in source_to_code
  File "<frozen importlib._bootstrap>", line 241, in _call_with_frames_removed
  File "/home/ubuntu/airflow/dags/etl.py", line 10
    'start_date': datetime(2023, 5. 12),
                                 ^^^^^
SyntaxError: invalid syntax. Perhaps you forgot a comma?
[2023-12-05T18:35:39.897+0000] {processor.py:841} WARNING - No viable dags retrieved from /home/ubuntu/airflow/dags/etl.py
[2023-12-05T18:35:39.920+0000] {processor.py:179} INFO - Processing /home/ubuntu/airflow/dags/etl.py took 0.037 seconds
[2023-12-05T18:36:10.261+0000] {processor.py:157} INFO - Started process (PID=19107) to work on /home/ubuntu/airflow/dags/etl.py
[2023-12-05T18:36:10.262+0000] {processor.py:829} INFO - Processing file /home/ubuntu/airflow/dags/etl.py for tasks to queue
[2023-12-05T18:36:10.263+0000] {logging_mixin.py:154} INFO - [2023-12-05T18:36:10.263+0000] {dagbag.py:536} INFO - Filling up the DagBag from /home/ubuntu/airflow/dags/etl.py
[2023-12-05T18:36:10.266+0000] {logging_mixin.py:154} INFO - [2023-12-05T18:36:10.265+0000] {dagbag.py:346} ERROR - Failed to import: /home/ubuntu/airflow/dags/etl.py
Traceback (most recent call last):
  File "/usr/local/lib/python3.10/dist-packages/airflow/models/dagbag.py", line 342, in parse
    loader.exec_module(new_module)
  File "<frozen importlib._bootstrap_external>", line 879, in exec_module
  File "<frozen importlib._bootstrap_external>", line 1017, in get_code
  File "<frozen importlib._bootstrap_external>", line 947, in source_to_code
  File "<frozen importlib._bootstrap>", line 241, in _call_with_frames_removed
  File "/home/ubuntu/airflow/dags/etl.py", line 10
    'start_date': datetime(2023, 5. 12),
                                 ^^^^^
SyntaxError: invalid syntax. Perhaps you forgot a comma?
[2023-12-05T18:36:10.267+0000] {processor.py:841} WARNING - No viable dags retrieved from /home/ubuntu/airflow/dags/etl.py
[2023-12-05T18:36:10.286+0000] {processor.py:179} INFO - Processing /home/ubuntu/airflow/dags/etl.py took 0.028 seconds
[2023-12-05T18:36:40.564+0000] {processor.py:157} INFO - Started process (PID=19170) to work on /home/ubuntu/airflow/dags/etl.py
[2023-12-05T18:36:40.565+0000] {processor.py:829} INFO - Processing file /home/ubuntu/airflow/dags/etl.py for tasks to queue
[2023-12-05T18:36:40.566+0000] {logging_mixin.py:154} INFO - [2023-12-05T18:36:40.565+0000] {dagbag.py:536} INFO - Filling up the DagBag from /home/ubuntu/airflow/dags/etl.py
[2023-12-05T18:36:40.571+0000] {logging_mixin.py:154} INFO - [2023-12-05T18:36:40.569+0000] {dagbag.py:346} ERROR - Failed to import: /home/ubuntu/airflow/dags/etl.py
Traceback (most recent call last):
  File "/usr/local/lib/python3.10/dist-packages/airflow/models/dagbag.py", line 342, in parse
    loader.exec_module(new_module)
  File "<frozen importlib._bootstrap_external>", line 879, in exec_module
  File "<frozen importlib._bootstrap_external>", line 1017, in get_code
  File "<frozen importlib._bootstrap_external>", line 947, in source_to_code
  File "<frozen importlib._bootstrap>", line 241, in _call_with_frames_removed
  File "/home/ubuntu/airflow/dags/etl.py", line 10
    'start_date': datetime(2023, 5. 12),
                                 ^^^^^
SyntaxError: invalid syntax. Perhaps you forgot a comma?
[2023-12-05T18:36:40.571+0000] {processor.py:841} WARNING - No viable dags retrieved from /home/ubuntu/airflow/dags/etl.py
[2023-12-05T18:36:40.590+0000] {processor.py:179} INFO - Processing /home/ubuntu/airflow/dags/etl.py took 0.030 seconds
[2023-12-05T18:37:10.822+0000] {processor.py:157} INFO - Started process (PID=19231) to work on /home/ubuntu/airflow/dags/etl.py
[2023-12-05T18:37:10.824+0000] {processor.py:829} INFO - Processing file /home/ubuntu/airflow/dags/etl.py for tasks to queue
[2023-12-05T18:37:10.825+0000] {logging_mixin.py:154} INFO - [2023-12-05T18:37:10.825+0000] {dagbag.py:536} INFO - Filling up the DagBag from /home/ubuntu/airflow/dags/etl.py
[2023-12-05T18:37:10.830+0000] {logging_mixin.py:154} INFO - [2023-12-05T18:37:10.828+0000] {dagbag.py:346} ERROR - Failed to import: /home/ubuntu/airflow/dags/etl.py
Traceback (most recent call last):
  File "/usr/local/lib/python3.10/dist-packages/airflow/models/dagbag.py", line 342, in parse
    loader.exec_module(new_module)
  File "<frozen importlib._bootstrap_external>", line 879, in exec_module
  File "<frozen importlib._bootstrap_external>", line 1017, in get_code
  File "<frozen importlib._bootstrap_external>", line 947, in source_to_code
  File "<frozen importlib._bootstrap>", line 241, in _call_with_frames_removed
  File "/home/ubuntu/airflow/dags/etl.py", line 10
    'start_date': datetime(2023, 5. 12),
                                 ^^^^^
SyntaxError: invalid syntax. Perhaps you forgot a comma?
[2023-12-05T18:37:10.830+0000] {processor.py:841} WARNING - No viable dags retrieved from /home/ubuntu/airflow/dags/etl.py
[2023-12-05T18:37:10.851+0000] {processor.py:179} INFO - Processing /home/ubuntu/airflow/dags/etl.py took 0.032 seconds
[2023-12-05T18:37:41.100+0000] {processor.py:157} INFO - Started process (PID=19235) to work on /home/ubuntu/airflow/dags/etl.py
[2023-12-05T18:37:41.102+0000] {processor.py:829} INFO - Processing file /home/ubuntu/airflow/dags/etl.py for tasks to queue
[2023-12-05T18:37:41.103+0000] {logging_mixin.py:154} INFO - [2023-12-05T18:37:41.103+0000] {dagbag.py:536} INFO - Filling up the DagBag from /home/ubuntu/airflow/dags/etl.py
[2023-12-05T18:37:41.107+0000] {logging_mixin.py:154} INFO - [2023-12-05T18:37:41.106+0000] {dagbag.py:346} ERROR - Failed to import: /home/ubuntu/airflow/dags/etl.py
Traceback (most recent call last):
  File "/usr/local/lib/python3.10/dist-packages/airflow/models/dagbag.py", line 342, in parse
    loader.exec_module(new_module)
  File "<frozen importlib._bootstrap_external>", line 879, in exec_module
  File "<frozen importlib._bootstrap_external>", line 1017, in get_code
  File "<frozen importlib._bootstrap_external>", line 947, in source_to_code
  File "<frozen importlib._bootstrap>", line 241, in _call_with_frames_removed
  File "/home/ubuntu/airflow/dags/etl.py", line 10
    'start_date': datetime(2023, 5. 12),
                                 ^^^^^
SyntaxError: invalid syntax. Perhaps you forgot a comma?
[2023-12-05T18:37:41.108+0000] {processor.py:841} WARNING - No viable dags retrieved from /home/ubuntu/airflow/dags/etl.py
[2023-12-05T18:37:41.127+0000] {processor.py:179} INFO - Processing /home/ubuntu/airflow/dags/etl.py took 0.029 seconds
[2023-12-05T18:38:11.458+0000] {processor.py:157} INFO - Started process (PID=19301) to work on /home/ubuntu/airflow/dags/etl.py
[2023-12-05T18:38:11.459+0000] {processor.py:829} INFO - Processing file /home/ubuntu/airflow/dags/etl.py for tasks to queue
[2023-12-05T18:38:11.460+0000] {logging_mixin.py:154} INFO - [2023-12-05T18:38:11.459+0000] {dagbag.py:536} INFO - Filling up the DagBag from /home/ubuntu/airflow/dags/etl.py
[2023-12-05T18:38:11.463+0000] {logging_mixin.py:154} INFO - [2023-12-05T18:38:11.462+0000] {dagbag.py:346} ERROR - Failed to import: /home/ubuntu/airflow/dags/etl.py
Traceback (most recent call last):
  File "/usr/local/lib/python3.10/dist-packages/airflow/models/dagbag.py", line 342, in parse
    loader.exec_module(new_module)
  File "<frozen importlib._bootstrap_external>", line 879, in exec_module
  File "<frozen importlib._bootstrap_external>", line 1017, in get_code
  File "<frozen importlib._bootstrap_external>", line 947, in source_to_code
  File "<frozen importlib._bootstrap>", line 241, in _call_with_frames_removed
  File "/home/ubuntu/airflow/dags/etl.py", line 10
    'start_date': datetime(2023, 5. 12),
                                 ^^^^^
SyntaxError: invalid syntax. Perhaps you forgot a comma?
[2023-12-05T18:38:11.463+0000] {processor.py:841} WARNING - No viable dags retrieved from /home/ubuntu/airflow/dags/etl.py
[2023-12-05T18:38:11.489+0000] {processor.py:179} INFO - Processing /home/ubuntu/airflow/dags/etl.py took 0.034 seconds
[2023-12-05T18:38:41.714+0000] {processor.py:157} INFO - Started process (PID=19302) to work on /home/ubuntu/airflow/dags/etl.py
[2023-12-05T18:38:41.716+0000] {processor.py:829} INFO - Processing file /home/ubuntu/airflow/dags/etl.py for tasks to queue
[2023-12-05T18:38:41.717+0000] {logging_mixin.py:154} INFO - [2023-12-05T18:38:41.716+0000] {dagbag.py:536} INFO - Filling up the DagBag from /home/ubuntu/airflow/dags/etl.py
[2023-12-05T18:38:41.721+0000] {logging_mixin.py:154} INFO - [2023-12-05T18:38:41.721+0000] {dagbag.py:346} ERROR - Failed to import: /home/ubuntu/airflow/dags/etl.py
Traceback (most recent call last):
  File "/usr/local/lib/python3.10/dist-packages/airflow/models/dagbag.py", line 342, in parse
    loader.exec_module(new_module)
  File "<frozen importlib._bootstrap_external>", line 879, in exec_module
  File "<frozen importlib._bootstrap_external>", line 1017, in get_code
  File "<frozen importlib._bootstrap_external>", line 947, in source_to_code
  File "<frozen importlib._bootstrap>", line 241, in _call_with_frames_removed
  File "/home/ubuntu/airflow/dags/etl.py", line 10
    'start_date': datetime(2023, 5. 12),
                                 ^^^^^
SyntaxError: invalid syntax. Perhaps you forgot a comma?
[2023-12-05T18:38:41.722+0000] {processor.py:841} WARNING - No viable dags retrieved from /home/ubuntu/airflow/dags/etl.py
[2023-12-05T18:38:41.739+0000] {processor.py:179} INFO - Processing /home/ubuntu/airflow/dags/etl.py took 0.029 seconds
[2023-12-05T18:39:12.007+0000] {processor.py:157} INFO - Started process (PID=19363) to work on /home/ubuntu/airflow/dags/etl.py
[2023-12-05T18:39:12.008+0000] {processor.py:829} INFO - Processing file /home/ubuntu/airflow/dags/etl.py for tasks to queue
[2023-12-05T18:39:12.009+0000] {logging_mixin.py:154} INFO - [2023-12-05T18:39:12.009+0000] {dagbag.py:536} INFO - Filling up the DagBag from /home/ubuntu/airflow/dags/etl.py
[2023-12-05T18:39:12.014+0000] {logging_mixin.py:154} INFO - [2023-12-05T18:39:12.013+0000] {dagbag.py:346} ERROR - Failed to import: /home/ubuntu/airflow/dags/etl.py
Traceback (most recent call last):
  File "/usr/local/lib/python3.10/dist-packages/airflow/models/dagbag.py", line 342, in parse
    loader.exec_module(new_module)
  File "<frozen importlib._bootstrap_external>", line 879, in exec_module
  File "<frozen importlib._bootstrap_external>", line 1017, in get_code
  File "<frozen importlib._bootstrap_external>", line 947, in source_to_code
  File "<frozen importlib._bootstrap>", line 241, in _call_with_frames_removed
  File "/home/ubuntu/airflow/dags/etl.py", line 10
    'start_date': datetime(2023, 5. 12),
                                 ^^^^^
SyntaxError: invalid syntax. Perhaps you forgot a comma?
[2023-12-05T18:39:12.014+0000] {processor.py:841} WARNING - No viable dags retrieved from /home/ubuntu/airflow/dags/etl.py
[2023-12-05T18:39:12.039+0000] {processor.py:179} INFO - Processing /home/ubuntu/airflow/dags/etl.py took 0.037 seconds
[2023-12-05T18:39:42.269+0000] {processor.py:157} INFO - Started process (PID=19424) to work on /home/ubuntu/airflow/dags/etl.py
[2023-12-05T18:39:42.271+0000] {processor.py:829} INFO - Processing file /home/ubuntu/airflow/dags/etl.py for tasks to queue
[2023-12-05T18:39:42.272+0000] {logging_mixin.py:154} INFO - [2023-12-05T18:39:42.271+0000] {dagbag.py:536} INFO - Filling up the DagBag from /home/ubuntu/airflow/dags/etl.py
[2023-12-05T18:39:42.276+0000] {logging_mixin.py:154} INFO - [2023-12-05T18:39:42.274+0000] {dagbag.py:346} ERROR - Failed to import: /home/ubuntu/airflow/dags/etl.py
Traceback (most recent call last):
  File "/usr/local/lib/python3.10/dist-packages/airflow/models/dagbag.py", line 342, in parse
    loader.exec_module(new_module)
  File "<frozen importlib._bootstrap_external>", line 879, in exec_module
  File "<frozen importlib._bootstrap_external>", line 1017, in get_code
  File "<frozen importlib._bootstrap_external>", line 947, in source_to_code
  File "<frozen importlib._bootstrap>", line 241, in _call_with_frames_removed
  File "/home/ubuntu/airflow/dags/etl.py", line 10
    'start_date': datetime(2023, 5. 12),
                                 ^^^^^
SyntaxError: invalid syntax. Perhaps you forgot a comma?
[2023-12-05T18:39:42.276+0000] {processor.py:841} WARNING - No viable dags retrieved from /home/ubuntu/airflow/dags/etl.py
[2023-12-05T18:39:42.297+0000] {processor.py:179} INFO - Processing /home/ubuntu/airflow/dags/etl.py took 0.031 seconds
[2023-12-05T18:40:12.570+0000] {processor.py:157} INFO - Started process (PID=19485) to work on /home/ubuntu/airflow/dags/etl.py
[2023-12-05T18:40:12.571+0000] {processor.py:829} INFO - Processing file /home/ubuntu/airflow/dags/etl.py for tasks to queue
[2023-12-05T18:40:12.572+0000] {logging_mixin.py:154} INFO - [2023-12-05T18:40:12.571+0000] {dagbag.py:536} INFO - Filling up the DagBag from /home/ubuntu/airflow/dags/etl.py
[2023-12-05T18:40:12.576+0000] {logging_mixin.py:154} INFO - [2023-12-05T18:40:12.575+0000] {dagbag.py:346} ERROR - Failed to import: /home/ubuntu/airflow/dags/etl.py
Traceback (most recent call last):
  File "/usr/local/lib/python3.10/dist-packages/airflow/models/dagbag.py", line 342, in parse
    loader.exec_module(new_module)
  File "<frozen importlib._bootstrap_external>", line 879, in exec_module
  File "<frozen importlib._bootstrap_external>", line 1017, in get_code
  File "<frozen importlib._bootstrap_external>", line 947, in source_to_code
  File "<frozen importlib._bootstrap>", line 241, in _call_with_frames_removed
  File "/home/ubuntu/airflow/dags/etl.py", line 10
    'start_date': datetime(2023, 5. 12),
                                 ^^^^^
SyntaxError: invalid syntax. Perhaps you forgot a comma?
[2023-12-05T18:40:12.576+0000] {processor.py:841} WARNING - No viable dags retrieved from /home/ubuntu/airflow/dags/etl.py
[2023-12-05T18:40:12.598+0000] {processor.py:179} INFO - Processing /home/ubuntu/airflow/dags/etl.py took 0.033 seconds
[2023-12-05T18:40:42.854+0000] {processor.py:157} INFO - Started process (PID=19491) to work on /home/ubuntu/airflow/dags/etl.py
[2023-12-05T18:40:42.855+0000] {processor.py:829} INFO - Processing file /home/ubuntu/airflow/dags/etl.py for tasks to queue
[2023-12-05T18:40:42.856+0000] {logging_mixin.py:154} INFO - [2023-12-05T18:40:42.856+0000] {dagbag.py:536} INFO - Filling up the DagBag from /home/ubuntu/airflow/dags/etl.py
[2023-12-05T18:40:42.860+0000] {logging_mixin.py:154} INFO - [2023-12-05T18:40:42.859+0000] {dagbag.py:346} ERROR - Failed to import: /home/ubuntu/airflow/dags/etl.py
Traceback (most recent call last):
  File "/usr/local/lib/python3.10/dist-packages/airflow/models/dagbag.py", line 342, in parse
    loader.exec_module(new_module)
  File "<frozen importlib._bootstrap_external>", line 879, in exec_module
  File "<frozen importlib._bootstrap_external>", line 1017, in get_code
  File "<frozen importlib._bootstrap_external>", line 947, in source_to_code
  File "<frozen importlib._bootstrap>", line 241, in _call_with_frames_removed
  File "/home/ubuntu/airflow/dags/etl.py", line 10
    'start_date': datetime(2023, 5. 12),
                                 ^^^^^
SyntaxError: invalid syntax. Perhaps you forgot a comma?
[2023-12-05T18:40:42.860+0000] {processor.py:841} WARNING - No viable dags retrieved from /home/ubuntu/airflow/dags/etl.py
[2023-12-05T18:40:42.879+0000] {processor.py:179} INFO - Processing /home/ubuntu/airflow/dags/etl.py took 0.031 seconds
[2023-12-05T18:41:13.036+0000] {processor.py:157} INFO - Started process (PID=19584) to work on /home/ubuntu/airflow/dags/etl.py
[2023-12-05T18:41:13.037+0000] {processor.py:829} INFO - Processing file /home/ubuntu/airflow/dags/etl.py for tasks to queue
[2023-12-05T18:41:13.038+0000] {logging_mixin.py:154} INFO - [2023-12-05T18:41:13.037+0000] {dagbag.py:536} INFO - Filling up the DagBag from /home/ubuntu/airflow/dags/etl.py
[2023-12-05T18:41:13.041+0000] {logging_mixin.py:154} INFO - [2023-12-05T18:41:13.041+0000] {dagbag.py:346} ERROR - Failed to import: /home/ubuntu/airflow/dags/etl.py
Traceback (most recent call last):
  File "/usr/local/lib/python3.10/dist-packages/airflow/models/dagbag.py", line 342, in parse
    loader.exec_module(new_module)
  File "<frozen importlib._bootstrap_external>", line 879, in exec_module
  File "<frozen importlib._bootstrap_external>", line 1017, in get_code
  File "<frozen importlib._bootstrap_external>", line 947, in source_to_code
  File "<frozen importlib._bootstrap>", line 241, in _call_with_frames_removed
  File "/home/ubuntu/airflow/dags/etl.py", line 10
    'start_date': datetime(2023, 5. 12),
                                 ^^^^^
SyntaxError: invalid syntax. Perhaps you forgot a comma?
[2023-12-05T18:41:13.042+0000] {processor.py:841} WARNING - No viable dags retrieved from /home/ubuntu/airflow/dags/etl.py
[2023-12-05T18:41:13.064+0000] {processor.py:179} INFO - Processing /home/ubuntu/airflow/dags/etl.py took 0.032 seconds
[2023-12-05T18:41:43.239+0000] {processor.py:157} INFO - Started process (PID=19623) to work on /home/ubuntu/airflow/dags/etl.py
[2023-12-05T18:41:43.244+0000] {processor.py:829} INFO - Processing file /home/ubuntu/airflow/dags/etl.py for tasks to queue
[2023-12-05T18:41:43.245+0000] {logging_mixin.py:154} INFO - [2023-12-05T18:41:43.245+0000] {dagbag.py:536} INFO - Filling up the DagBag from /home/ubuntu/airflow/dags/etl.py
[2023-12-05T18:41:43.250+0000] {logging_mixin.py:154} INFO - [2023-12-05T18:41:43.248+0000] {dagbag.py:346} ERROR - Failed to import: /home/ubuntu/airflow/dags/etl.py
Traceback (most recent call last):
  File "/usr/local/lib/python3.10/dist-packages/airflow/models/dagbag.py", line 342, in parse
    loader.exec_module(new_module)
  File "<frozen importlib._bootstrap_external>", line 879, in exec_module
  File "<frozen importlib._bootstrap_external>", line 1017, in get_code
  File "<frozen importlib._bootstrap_external>", line 947, in source_to_code
  File "<frozen importlib._bootstrap>", line 241, in _call_with_frames_removed
  File "/home/ubuntu/airflow/dags/etl.py", line 10
    'start_date': datetime(2023, 5. 12),
                                 ^^^^^
SyntaxError: invalid syntax. Perhaps you forgot a comma?
[2023-12-05T18:41:43.251+0000] {processor.py:841} WARNING - No viable dags retrieved from /home/ubuntu/airflow/dags/etl.py
[2023-12-05T18:41:43.280+0000] {processor.py:179} INFO - Processing /home/ubuntu/airflow/dags/etl.py took 0.048 seconds
[2023-12-05T18:42:13.453+0000] {processor.py:157} INFO - Started process (PID=19684) to work on /home/ubuntu/airflow/dags/etl.py
[2023-12-05T18:42:13.458+0000] {processor.py:829} INFO - Processing file /home/ubuntu/airflow/dags/etl.py for tasks to queue
[2023-12-05T18:42:13.459+0000] {logging_mixin.py:154} INFO - [2023-12-05T18:42:13.458+0000] {dagbag.py:536} INFO - Filling up the DagBag from /home/ubuntu/airflow/dags/etl.py
[2023-12-05T18:42:13.467+0000] {logging_mixin.py:154} INFO - [2023-12-05T18:42:13.465+0000] {dagbag.py:346} ERROR - Failed to import: /home/ubuntu/airflow/dags/etl.py
Traceback (most recent call last):
  File "/usr/local/lib/python3.10/dist-packages/airflow/models/dagbag.py", line 342, in parse
    loader.exec_module(new_module)
  File "<frozen importlib._bootstrap_external>", line 879, in exec_module
  File "<frozen importlib._bootstrap_external>", line 1017, in get_code
  File "<frozen importlib._bootstrap_external>", line 947, in source_to_code
  File "<frozen importlib._bootstrap>", line 241, in _call_with_frames_removed
  File "/home/ubuntu/airflow/dags/etl.py", line 10
    'start_date': datetime(2023, 5. 12),
                                 ^^^^^
SyntaxError: invalid syntax. Perhaps you forgot a comma?
[2023-12-05T18:42:13.469+0000] {processor.py:841} WARNING - No viable dags retrieved from /home/ubuntu/airflow/dags/etl.py
[2023-12-05T18:42:13.497+0000] {processor.py:179} INFO - Processing /home/ubuntu/airflow/dags/etl.py took 0.055 seconds
[2023-12-05T18:42:43.633+0000] {processor.py:157} INFO - Started process (PID=19685) to work on /home/ubuntu/airflow/dags/etl.py
[2023-12-05T18:42:43.635+0000] {processor.py:829} INFO - Processing file /home/ubuntu/airflow/dags/etl.py for tasks to queue
[2023-12-05T18:42:43.639+0000] {logging_mixin.py:154} INFO - [2023-12-05T18:42:43.635+0000] {dagbag.py:536} INFO - Filling up the DagBag from /home/ubuntu/airflow/dags/etl.py
[2023-12-05T18:42:43.646+0000] {logging_mixin.py:154} INFO - [2023-12-05T18:42:43.644+0000] {dagbag.py:346} ERROR - Failed to import: /home/ubuntu/airflow/dags/etl.py
Traceback (most recent call last):
  File "/usr/local/lib/python3.10/dist-packages/airflow/models/dagbag.py", line 342, in parse
    loader.exec_module(new_module)
  File "<frozen importlib._bootstrap_external>", line 879, in exec_module
  File "<frozen importlib._bootstrap_external>", line 1017, in get_code
  File "<frozen importlib._bootstrap_external>", line 947, in source_to_code
  File "<frozen importlib._bootstrap>", line 241, in _call_with_frames_removed
  File "/home/ubuntu/airflow/dags/etl.py", line 10
    'start_date': datetime(2023, 5. 12),
                                 ^^^^^
SyntaxError: invalid syntax. Perhaps you forgot a comma?
[2023-12-05T18:42:43.647+0000] {processor.py:841} WARNING - No viable dags retrieved from /home/ubuntu/airflow/dags/etl.py
[2023-12-05T18:42:43.678+0000] {processor.py:179} INFO - Processing /home/ubuntu/airflow/dags/etl.py took 0.051 seconds
[2023-12-05T18:43:13.825+0000] {processor.py:157} INFO - Started process (PID=19773) to work on /home/ubuntu/airflow/dags/etl.py
[2023-12-05T18:43:13.828+0000] {processor.py:829} INFO - Processing file /home/ubuntu/airflow/dags/etl.py for tasks to queue
[2023-12-05T18:43:13.830+0000] {logging_mixin.py:154} INFO - [2023-12-05T18:43:13.829+0000] {dagbag.py:536} INFO - Filling up the DagBag from /home/ubuntu/airflow/dags/etl.py
[2023-12-05T18:43:13.836+0000] {logging_mixin.py:154} INFO - [2023-12-05T18:43:13.835+0000] {dagbag.py:346} ERROR - Failed to import: /home/ubuntu/airflow/dags/etl.py
Traceback (most recent call last):
  File "/usr/local/lib/python3.10/dist-packages/airflow/models/dagbag.py", line 342, in parse
    loader.exec_module(new_module)
  File "<frozen importlib._bootstrap_external>", line 879, in exec_module
  File "<frozen importlib._bootstrap_external>", line 1017, in get_code
  File "<frozen importlib._bootstrap_external>", line 947, in source_to_code
  File "<frozen importlib._bootstrap>", line 241, in _call_with_frames_removed
  File "/home/ubuntu/airflow/dags/etl.py", line 10
    'start_date': datetime(2023, 5. 12),
                                 ^^^^^
SyntaxError: invalid syntax. Perhaps you forgot a comma?
[2023-12-05T18:43:13.837+0000] {processor.py:841} WARNING - No viable dags retrieved from /home/ubuntu/airflow/dags/etl.py
[2023-12-05T18:43:13.863+0000] {processor.py:179} INFO - Processing /home/ubuntu/airflow/dags/etl.py took 0.044 seconds
[2023-12-05T18:43:44.010+0000] {processor.py:157} INFO - Started process (PID=19930) to work on /home/ubuntu/airflow/dags/etl.py
[2023-12-05T18:43:44.011+0000] {processor.py:829} INFO - Processing file /home/ubuntu/airflow/dags/etl.py for tasks to queue
[2023-12-05T18:43:44.011+0000] {logging_mixin.py:154} INFO - [2023-12-05T18:43:44.011+0000] {dagbag.py:536} INFO - Filling up the DagBag from /home/ubuntu/airflow/dags/etl.py
[2023-12-05T18:43:44.015+0000] {logging_mixin.py:154} INFO - [2023-12-05T18:43:44.014+0000] {dagbag.py:346} ERROR - Failed to import: /home/ubuntu/airflow/dags/etl.py
Traceback (most recent call last):
  File "/usr/local/lib/python3.10/dist-packages/airflow/models/dagbag.py", line 342, in parse
    loader.exec_module(new_module)
  File "<frozen importlib._bootstrap_external>", line 879, in exec_module
  File "<frozen importlib._bootstrap_external>", line 1017, in get_code
  File "<frozen importlib._bootstrap_external>", line 947, in source_to_code
  File "<frozen importlib._bootstrap>", line 241, in _call_with_frames_removed
  File "/home/ubuntu/airflow/dags/etl.py", line 10
    'start_date': datetime(2023, 5. 12),
                                 ^^^^^
SyntaxError: invalid syntax. Perhaps you forgot a comma?
[2023-12-05T18:43:44.016+0000] {processor.py:841} WARNING - No viable dags retrieved from /home/ubuntu/airflow/dags/etl.py
[2023-12-05T18:43:44.046+0000] {processor.py:179} INFO - Processing /home/ubuntu/airflow/dags/etl.py took 0.042 seconds
[2023-12-05T18:44:14.148+0000] {processor.py:157} INFO - Started process (PID=19996) to work on /home/ubuntu/airflow/dags/etl.py
[2023-12-05T18:44:14.150+0000] {processor.py:829} INFO - Processing file /home/ubuntu/airflow/dags/etl.py for tasks to queue
[2023-12-05T18:44:14.153+0000] {logging_mixin.py:154} INFO - [2023-12-05T18:44:14.153+0000] {dagbag.py:536} INFO - Filling up the DagBag from /home/ubuntu/airflow/dags/etl.py
[2023-12-05T18:44:14.162+0000] {logging_mixin.py:154} INFO - [2023-12-05T18:44:14.158+0000] {dagbag.py:346} ERROR - Failed to import: /home/ubuntu/airflow/dags/etl.py
Traceback (most recent call last):
  File "/usr/local/lib/python3.10/dist-packages/airflow/models/dagbag.py", line 342, in parse
    loader.exec_module(new_module)
  File "<frozen importlib._bootstrap_external>", line 879, in exec_module
  File "<frozen importlib._bootstrap_external>", line 1017, in get_code
  File "<frozen importlib._bootstrap_external>", line 947, in source_to_code
  File "<frozen importlib._bootstrap>", line 241, in _call_with_frames_removed
  File "/home/ubuntu/airflow/dags/etl.py", line 10
    'start_date': datetime(2023, 5. 12),
                                 ^^^^^
SyntaxError: invalid syntax. Perhaps you forgot a comma?
[2023-12-05T18:44:14.165+0000] {processor.py:841} WARNING - No viable dags retrieved from /home/ubuntu/airflow/dags/etl.py
[2023-12-05T18:44:14.202+0000] {processor.py:179} INFO - Processing /home/ubuntu/airflow/dags/etl.py took 0.059 seconds
[2023-12-05T18:44:44.362+0000] {processor.py:157} INFO - Started process (PID=19999) to work on /home/ubuntu/airflow/dags/etl.py
[2023-12-05T18:44:44.363+0000] {processor.py:829} INFO - Processing file /home/ubuntu/airflow/dags/etl.py for tasks to queue
[2023-12-05T18:44:44.364+0000] {logging_mixin.py:154} INFO - [2023-12-05T18:44:44.364+0000] {dagbag.py:536} INFO - Filling up the DagBag from /home/ubuntu/airflow/dags/etl.py
[2023-12-05T18:44:44.369+0000] {logging_mixin.py:154} INFO - [2023-12-05T18:44:44.368+0000] {dagbag.py:346} ERROR - Failed to import: /home/ubuntu/airflow/dags/etl.py
Traceback (most recent call last):
  File "/usr/local/lib/python3.10/dist-packages/airflow/models/dagbag.py", line 342, in parse
    loader.exec_module(new_module)
  File "<frozen importlib._bootstrap_external>", line 879, in exec_module
  File "<frozen importlib._bootstrap_external>", line 1017, in get_code
  File "<frozen importlib._bootstrap_external>", line 947, in source_to_code
  File "<frozen importlib._bootstrap>", line 241, in _call_with_frames_removed
  File "/home/ubuntu/airflow/dags/etl.py", line 10
    'start_date': datetime(2023, 5. 12),
                                 ^^^^^
SyntaxError: invalid syntax. Perhaps you forgot a comma?
[2023-12-05T18:44:44.369+0000] {processor.py:841} WARNING - No viable dags retrieved from /home/ubuntu/airflow/dags/etl.py
[2023-12-05T18:44:44.398+0000] {processor.py:179} INFO - Processing /home/ubuntu/airflow/dags/etl.py took 0.039 seconds
[2023-12-05T18:45:14.548+0000] {processor.py:157} INFO - Started process (PID=20062) to work on /home/ubuntu/airflow/dags/etl.py
[2023-12-05T18:45:14.549+0000] {processor.py:829} INFO - Processing file /home/ubuntu/airflow/dags/etl.py for tasks to queue
[2023-12-05T18:45:14.550+0000] {logging_mixin.py:154} INFO - [2023-12-05T18:45:14.549+0000] {dagbag.py:536} INFO - Filling up the DagBag from /home/ubuntu/airflow/dags/etl.py
[2023-12-05T18:45:14.553+0000] {logging_mixin.py:154} INFO - [2023-12-05T18:45:14.552+0000] {dagbag.py:346} ERROR - Failed to import: /home/ubuntu/airflow/dags/etl.py
Traceback (most recent call last):
  File "/usr/local/lib/python3.10/dist-packages/airflow/models/dagbag.py", line 342, in parse
    loader.exec_module(new_module)
  File "<frozen importlib._bootstrap_external>", line 879, in exec_module
  File "<frozen importlib._bootstrap_external>", line 1017, in get_code
  File "<frozen importlib._bootstrap_external>", line 947, in source_to_code
  File "<frozen importlib._bootstrap>", line 241, in _call_with_frames_removed
  File "/home/ubuntu/airflow/dags/etl.py", line 10
    'start_date': datetime(2023, 5. 12),
                                 ^^^^^
SyntaxError: invalid syntax. Perhaps you forgot a comma?
[2023-12-05T18:45:14.553+0000] {processor.py:841} WARNING - No viable dags retrieved from /home/ubuntu/airflow/dags/etl.py
[2023-12-05T18:45:14.572+0000] {processor.py:179} INFO - Processing /home/ubuntu/airflow/dags/etl.py took 0.027 seconds
[2023-12-05T18:45:44.751+0000] {processor.py:157} INFO - Started process (PID=20069) to work on /home/ubuntu/airflow/dags/etl.py
[2023-12-05T18:45:44.752+0000] {processor.py:829} INFO - Processing file /home/ubuntu/airflow/dags/etl.py for tasks to queue
[2023-12-05T18:45:44.753+0000] {logging_mixin.py:154} INFO - [2023-12-05T18:45:44.752+0000] {dagbag.py:536} INFO - Filling up the DagBag from /home/ubuntu/airflow/dags/etl.py
[2023-12-05T18:45:44.756+0000] {logging_mixin.py:154} INFO - [2023-12-05T18:45:44.755+0000] {dagbag.py:346} ERROR - Failed to import: /home/ubuntu/airflow/dags/etl.py
Traceback (most recent call last):
  File "/usr/local/lib/python3.10/dist-packages/airflow/models/dagbag.py", line 342, in parse
    loader.exec_module(new_module)
  File "<frozen importlib._bootstrap_external>", line 879, in exec_module
  File "<frozen importlib._bootstrap_external>", line 1017, in get_code
  File "<frozen importlib._bootstrap_external>", line 947, in source_to_code
  File "<frozen importlib._bootstrap>", line 241, in _call_with_frames_removed
  File "/home/ubuntu/airflow/dags/etl.py", line 10
    'start_date': datetime(2023, 5. 12),
                                 ^^^^^
SyntaxError: invalid syntax. Perhaps you forgot a comma?
[2023-12-05T18:45:44.756+0000] {processor.py:841} WARNING - No viable dags retrieved from /home/ubuntu/airflow/dags/etl.py
[2023-12-05T18:45:44.792+0000] {processor.py:179} INFO - Processing /home/ubuntu/airflow/dags/etl.py took 0.044 seconds
[2023-12-05T18:46:14.957+0000] {processor.py:157} INFO - Started process (PID=20212) to work on /home/ubuntu/airflow/dags/etl.py
[2023-12-05T18:46:14.959+0000] {processor.py:829} INFO - Processing file /home/ubuntu/airflow/dags/etl.py for tasks to queue
[2023-12-05T18:46:14.961+0000] {logging_mixin.py:154} INFO - [2023-12-05T18:46:14.960+0000] {dagbag.py:536} INFO - Filling up the DagBag from /home/ubuntu/airflow/dags/etl.py
[2023-12-05T18:46:14.964+0000] {logging_mixin.py:154} INFO - [2023-12-05T18:46:14.963+0000] {dagbag.py:346} ERROR - Failed to import: /home/ubuntu/airflow/dags/etl.py
Traceback (most recent call last):
  File "/usr/local/lib/python3.10/dist-packages/airflow/models/dagbag.py", line 342, in parse
    loader.exec_module(new_module)
  File "<frozen importlib._bootstrap_external>", line 879, in exec_module
  File "<frozen importlib._bootstrap_external>", line 1017, in get_code
  File "<frozen importlib._bootstrap_external>", line 947, in source_to_code
  File "<frozen importlib._bootstrap>", line 241, in _call_with_frames_removed
  File "/home/ubuntu/airflow/dags/etl.py", line 10
    'start_date': datetime(2023, 5. 12),
                                 ^^^^^
SyntaxError: invalid syntax. Perhaps you forgot a comma?
[2023-12-05T18:46:14.965+0000] {processor.py:841} WARNING - No viable dags retrieved from /home/ubuntu/airflow/dags/etl.py
[2023-12-05T18:46:14.988+0000] {processor.py:179} INFO - Processing /home/ubuntu/airflow/dags/etl.py took 0.038 seconds
[2023-12-05T18:46:45.153+0000] {processor.py:157} INFO - Started process (PID=20245) to work on /home/ubuntu/airflow/dags/etl.py
[2023-12-05T18:46:45.154+0000] {processor.py:829} INFO - Processing file /home/ubuntu/airflow/dags/etl.py for tasks to queue
[2023-12-05T18:46:45.155+0000] {logging_mixin.py:154} INFO - [2023-12-05T18:46:45.155+0000] {dagbag.py:536} INFO - Filling up the DagBag from /home/ubuntu/airflow/dags/etl.py
[2023-12-05T18:46:45.159+0000] {logging_mixin.py:154} INFO - [2023-12-05T18:46:45.158+0000] {dagbag.py:346} ERROR - Failed to import: /home/ubuntu/airflow/dags/etl.py
Traceback (most recent call last):
  File "/usr/local/lib/python3.10/dist-packages/airflow/models/dagbag.py", line 342, in parse
    loader.exec_module(new_module)
  File "<frozen importlib._bootstrap_external>", line 879, in exec_module
  File "<frozen importlib._bootstrap_external>", line 1017, in get_code
  File "<frozen importlib._bootstrap_external>", line 947, in source_to_code
  File "<frozen importlib._bootstrap>", line 241, in _call_with_frames_removed
  File "/home/ubuntu/airflow/dags/etl.py", line 10
    'start_date': datetime(2023, 5. 12),
                                 ^^^^^
SyntaxError: invalid syntax. Perhaps you forgot a comma?
[2023-12-05T18:46:45.159+0000] {processor.py:841} WARNING - No viable dags retrieved from /home/ubuntu/airflow/dags/etl.py
[2023-12-05T18:46:45.181+0000] {processor.py:179} INFO - Processing /home/ubuntu/airflow/dags/etl.py took 0.032 seconds
[2023-12-05T18:47:15.361+0000] {processor.py:157} INFO - Started process (PID=20327) to work on /home/ubuntu/airflow/dags/etl.py
[2023-12-05T18:47:15.362+0000] {processor.py:829} INFO - Processing file /home/ubuntu/airflow/dags/etl.py for tasks to queue
[2023-12-05T18:47:15.363+0000] {logging_mixin.py:154} INFO - [2023-12-05T18:47:15.363+0000] {dagbag.py:536} INFO - Filling up the DagBag from /home/ubuntu/airflow/dags/etl.py
[2023-12-05T18:47:15.367+0000] {logging_mixin.py:154} INFO - [2023-12-05T18:47:15.365+0000] {dagbag.py:346} ERROR - Failed to import: /home/ubuntu/airflow/dags/etl.py
Traceback (most recent call last):
  File "/usr/local/lib/python3.10/dist-packages/airflow/models/dagbag.py", line 342, in parse
    loader.exec_module(new_module)
  File "<frozen importlib._bootstrap_external>", line 879, in exec_module
  File "<frozen importlib._bootstrap_external>", line 1017, in get_code
  File "<frozen importlib._bootstrap_external>", line 947, in source_to_code
  File "<frozen importlib._bootstrap>", line 241, in _call_with_frames_removed
  File "/home/ubuntu/airflow/dags/etl.py", line 10
    'start_date': datetime(2023, 5. 12),
                                 ^^^^^
SyntaxError: invalid syntax. Perhaps you forgot a comma?
[2023-12-05T18:47:15.367+0000] {processor.py:841} WARNING - No viable dags retrieved from /home/ubuntu/airflow/dags/etl.py
[2023-12-05T18:47:15.388+0000] {processor.py:179} INFO - Processing /home/ubuntu/airflow/dags/etl.py took 0.031 seconds
[2023-12-05T18:47:45.474+0000] {processor.py:157} INFO - Started process (PID=20334) to work on /home/ubuntu/airflow/dags/etl.py
[2023-12-05T18:47:45.475+0000] {processor.py:829} INFO - Processing file /home/ubuntu/airflow/dags/etl.py for tasks to queue
[2023-12-05T18:47:45.476+0000] {logging_mixin.py:154} INFO - [2023-12-05T18:47:45.476+0000] {dagbag.py:536} INFO - Filling up the DagBag from /home/ubuntu/airflow/dags/etl.py
[2023-12-05T18:47:45.480+0000] {logging_mixin.py:154} INFO - [2023-12-05T18:47:45.479+0000] {dagbag.py:346} ERROR - Failed to import: /home/ubuntu/airflow/dags/etl.py
Traceback (most recent call last):
  File "/usr/local/lib/python3.10/dist-packages/airflow/models/dagbag.py", line 342, in parse
    loader.exec_module(new_module)
  File "<frozen importlib._bootstrap_external>", line 879, in exec_module
  File "<frozen importlib._bootstrap_external>", line 1017, in get_code
  File "<frozen importlib._bootstrap_external>", line 947, in source_to_code
  File "<frozen importlib._bootstrap>", line 241, in _call_with_frames_removed
  File "/home/ubuntu/airflow/dags/etl.py", line 10
    'start_date': datetime(2023, 5. 12),
                                 ^^^^^
SyntaxError: invalid syntax. Perhaps you forgot a comma?
[2023-12-05T18:47:45.481+0000] {processor.py:841} WARNING - No viable dags retrieved from /home/ubuntu/airflow/dags/etl.py
[2023-12-05T18:47:45.513+0000] {processor.py:179} INFO - Processing /home/ubuntu/airflow/dags/etl.py took 0.043 seconds
[2023-12-05T18:48:15.687+0000] {processor.py:157} INFO - Started process (PID=20399) to work on /home/ubuntu/airflow/dags/etl.py
[2023-12-05T18:48:15.688+0000] {processor.py:829} INFO - Processing file /home/ubuntu/airflow/dags/etl.py for tasks to queue
[2023-12-05T18:48:15.689+0000] {logging_mixin.py:154} INFO - [2023-12-05T18:48:15.689+0000] {dagbag.py:536} INFO - Filling up the DagBag from /home/ubuntu/airflow/dags/etl.py
[2023-12-05T18:48:15.693+0000] {logging_mixin.py:154} INFO - [2023-12-05T18:48:15.692+0000] {dagbag.py:346} ERROR - Failed to import: /home/ubuntu/airflow/dags/etl.py
Traceback (most recent call last):
  File "/usr/local/lib/python3.10/dist-packages/airflow/models/dagbag.py", line 342, in parse
    loader.exec_module(new_module)
  File "<frozen importlib._bootstrap_external>", line 879, in exec_module
  File "<frozen importlib._bootstrap_external>", line 1017, in get_code
  File "<frozen importlib._bootstrap_external>", line 947, in source_to_code
  File "<frozen importlib._bootstrap>", line 241, in _call_with_frames_removed
  File "/home/ubuntu/airflow/dags/etl.py", line 10
    'start_date': datetime(2023, 5. 12),
                                 ^^^^^
SyntaxError: invalid syntax. Perhaps you forgot a comma?
[2023-12-05T18:48:15.694+0000] {processor.py:841} WARNING - No viable dags retrieved from /home/ubuntu/airflow/dags/etl.py
[2023-12-05T18:48:15.715+0000] {processor.py:179} INFO - Processing /home/ubuntu/airflow/dags/etl.py took 0.036 seconds
[2023-12-05T18:48:45.872+0000] {processor.py:157} INFO - Started process (PID=20402) to work on /home/ubuntu/airflow/dags/etl.py
[2023-12-05T18:48:45.874+0000] {processor.py:829} INFO - Processing file /home/ubuntu/airflow/dags/etl.py for tasks to queue
[2023-12-05T18:48:45.875+0000] {logging_mixin.py:154} INFO - [2023-12-05T18:48:45.875+0000] {dagbag.py:536} INFO - Filling up the DagBag from /home/ubuntu/airflow/dags/etl.py
[2023-12-05T18:48:45.878+0000] {logging_mixin.py:154} INFO - [2023-12-05T18:48:45.877+0000] {dagbag.py:346} ERROR - Failed to import: /home/ubuntu/airflow/dags/etl.py
Traceback (most recent call last):
  File "/usr/local/lib/python3.10/dist-packages/airflow/models/dagbag.py", line 342, in parse
    loader.exec_module(new_module)
  File "<frozen importlib._bootstrap_external>", line 879, in exec_module
  File "<frozen importlib._bootstrap_external>", line 1017, in get_code
  File "<frozen importlib._bootstrap_external>", line 947, in source_to_code
  File "<frozen importlib._bootstrap>", line 241, in _call_with_frames_removed
  File "/home/ubuntu/airflow/dags/etl.py", line 10
    'start_date': datetime(2023, 5. 12),
                                 ^^^^^
SyntaxError: invalid syntax. Perhaps you forgot a comma?
[2023-12-05T18:48:45.879+0000] {processor.py:841} WARNING - No viable dags retrieved from /home/ubuntu/airflow/dags/etl.py
[2023-12-05T18:48:45.900+0000] {processor.py:179} INFO - Processing /home/ubuntu/airflow/dags/etl.py took 0.031 seconds
[2023-12-05T18:49:16.093+0000] {processor.py:157} INFO - Started process (PID=20475) to work on /home/ubuntu/airflow/dags/etl.py
[2023-12-05T18:49:16.094+0000] {processor.py:829} INFO - Processing file /home/ubuntu/airflow/dags/etl.py for tasks to queue
[2023-12-05T18:49:16.099+0000] {logging_mixin.py:154} INFO - [2023-12-05T18:49:16.098+0000] {dagbag.py:536} INFO - Filling up the DagBag from /home/ubuntu/airflow/dags/etl.py
[2023-12-05T18:49:16.103+0000] {logging_mixin.py:154} INFO - [2023-12-05T18:49:16.102+0000] {dagbag.py:346} ERROR - Failed to import: /home/ubuntu/airflow/dags/etl.py
Traceback (most recent call last):
  File "/usr/local/lib/python3.10/dist-packages/airflow/models/dagbag.py", line 342, in parse
    loader.exec_module(new_module)
  File "<frozen importlib._bootstrap_external>", line 879, in exec_module
  File "<frozen importlib._bootstrap_external>", line 1017, in get_code
  File "<frozen importlib._bootstrap_external>", line 947, in source_to_code
  File "<frozen importlib._bootstrap>", line 241, in _call_with_frames_removed
  File "/home/ubuntu/airflow/dags/etl.py", line 10
    'start_date': datetime(2023, 5. 12),
                                 ^^^^^
SyntaxError: invalid syntax. Perhaps you forgot a comma?
[2023-12-05T18:49:16.103+0000] {processor.py:841} WARNING - No viable dags retrieved from /home/ubuntu/airflow/dags/etl.py
[2023-12-05T18:49:16.129+0000] {processor.py:179} INFO - Processing /home/ubuntu/airflow/dags/etl.py took 0.055 seconds
[2023-12-05T18:49:46.295+0000] {processor.py:157} INFO - Started process (PID=20722) to work on /home/ubuntu/airflow/dags/etl.py
[2023-12-05T18:49:46.297+0000] {processor.py:829} INFO - Processing file /home/ubuntu/airflow/dags/etl.py for tasks to queue
[2023-12-05T18:49:46.298+0000] {logging_mixin.py:154} INFO - [2023-12-05T18:49:46.297+0000] {dagbag.py:536} INFO - Filling up the DagBag from /home/ubuntu/airflow/dags/etl.py
[2023-12-05T18:49:46.303+0000] {logging_mixin.py:154} INFO - [2023-12-05T18:49:46.301+0000] {dagbag.py:346} ERROR - Failed to import: /home/ubuntu/airflow/dags/etl.py
Traceback (most recent call last):
  File "/usr/local/lib/python3.10/dist-packages/airflow/models/dagbag.py", line 342, in parse
    loader.exec_module(new_module)
  File "<frozen importlib._bootstrap_external>", line 879, in exec_module
  File "<frozen importlib._bootstrap_external>", line 1017, in get_code
  File "<frozen importlib._bootstrap_external>", line 947, in source_to_code
  File "<frozen importlib._bootstrap>", line 241, in _call_with_frames_removed
  File "/home/ubuntu/airflow/dags/etl.py", line 10
    'start_date': datetime(2023, 5. 12),
                                 ^^^^^
SyntaxError: invalid syntax. Perhaps you forgot a comma?
[2023-12-05T18:49:46.303+0000] {processor.py:841} WARNING - No viable dags retrieved from /home/ubuntu/airflow/dags/etl.py
[2023-12-05T18:49:46.326+0000] {processor.py:179} INFO - Processing /home/ubuntu/airflow/dags/etl.py took 0.034 seconds
[2023-12-05T18:50:16.522+0000] {processor.py:157} INFO - Started process (PID=20790) to work on /home/ubuntu/airflow/dags/etl.py
[2023-12-05T18:50:16.523+0000] {processor.py:829} INFO - Processing file /home/ubuntu/airflow/dags/etl.py for tasks to queue
[2023-12-05T18:50:16.524+0000] {logging_mixin.py:154} INFO - [2023-12-05T18:50:16.524+0000] {dagbag.py:536} INFO - Filling up the DagBag from /home/ubuntu/airflow/dags/etl.py
[2023-12-05T18:50:16.527+0000] {logging_mixin.py:154} INFO - [2023-12-05T18:50:16.526+0000] {dagbag.py:346} ERROR - Failed to import: /home/ubuntu/airflow/dags/etl.py
Traceback (most recent call last):
  File "/usr/local/lib/python3.10/dist-packages/airflow/models/dagbag.py", line 342, in parse
    loader.exec_module(new_module)
  File "<frozen importlib._bootstrap_external>", line 879, in exec_module
  File "<frozen importlib._bootstrap_external>", line 1017, in get_code
  File "<frozen importlib._bootstrap_external>", line 947, in source_to_code
  File "<frozen importlib._bootstrap>", line 241, in _call_with_frames_removed
  File "/home/ubuntu/airflow/dags/etl.py", line 10
    'start_date': datetime(2023, 5. 12),
                                 ^^^^^
SyntaxError: invalid syntax. Perhaps you forgot a comma?
[2023-12-05T18:50:16.528+0000] {processor.py:841} WARNING - No viable dags retrieved from /home/ubuntu/airflow/dags/etl.py
[2023-12-05T18:50:16.575+0000] {processor.py:179} INFO - Processing /home/ubuntu/airflow/dags/etl.py took 0.058 seconds
[2023-12-05T18:50:46.725+0000] {processor.py:157} INFO - Started process (PID=20793) to work on /home/ubuntu/airflow/dags/etl.py
[2023-12-05T18:50:46.727+0000] {processor.py:829} INFO - Processing file /home/ubuntu/airflow/dags/etl.py for tasks to queue
[2023-12-05T18:50:46.727+0000] {logging_mixin.py:154} INFO - [2023-12-05T18:50:46.727+0000] {dagbag.py:536} INFO - Filling up the DagBag from /home/ubuntu/airflow/dags/etl.py
[2023-12-05T18:50:46.732+0000] {logging_mixin.py:154} INFO - [2023-12-05T18:50:46.731+0000] {dagbag.py:346} ERROR - Failed to import: /home/ubuntu/airflow/dags/etl.py
Traceback (most recent call last):
  File "/usr/local/lib/python3.10/dist-packages/airflow/models/dagbag.py", line 342, in parse
    loader.exec_module(new_module)
  File "<frozen importlib._bootstrap_external>", line 879, in exec_module
  File "<frozen importlib._bootstrap_external>", line 1017, in get_code
  File "<frozen importlib._bootstrap_external>", line 947, in source_to_code
  File "<frozen importlib._bootstrap>", line 241, in _call_with_frames_removed
  File "/home/ubuntu/airflow/dags/etl.py", line 10
    'start_date': datetime(2023, 5. 12),
                                 ^^^^^
SyntaxError: invalid syntax. Perhaps you forgot a comma?
[2023-12-05T18:50:46.732+0000] {processor.py:841} WARNING - No viable dags retrieved from /home/ubuntu/airflow/dags/etl.py
[2023-12-05T18:50:46.761+0000] {processor.py:179} INFO - Processing /home/ubuntu/airflow/dags/etl.py took 0.043 seconds
[2023-12-05T18:51:16.906+0000] {processor.py:157} INFO - Started process (PID=20923) to work on /home/ubuntu/airflow/dags/etl.py
[2023-12-05T18:51:16.907+0000] {processor.py:829} INFO - Processing file /home/ubuntu/airflow/dags/etl.py for tasks to queue
[2023-12-05T18:51:16.908+0000] {logging_mixin.py:154} INFO - [2023-12-05T18:51:16.907+0000] {dagbag.py:536} INFO - Filling up the DagBag from /home/ubuntu/airflow/dags/etl.py
[2023-12-05T18:51:16.911+0000] {logging_mixin.py:154} INFO - [2023-12-05T18:51:16.910+0000] {dagbag.py:346} ERROR - Failed to import: /home/ubuntu/airflow/dags/etl.py
Traceback (most recent call last):
  File "/usr/local/lib/python3.10/dist-packages/airflow/models/dagbag.py", line 342, in parse
    loader.exec_module(new_module)
  File "<frozen importlib._bootstrap_external>", line 879, in exec_module
  File "<frozen importlib._bootstrap_external>", line 1017, in get_code
  File "<frozen importlib._bootstrap_external>", line 947, in source_to_code
  File "<frozen importlib._bootstrap>", line 241, in _call_with_frames_removed
  File "/home/ubuntu/airflow/dags/etl.py", line 10
    'start_date': datetime(2023, 5. 12),
                                 ^^^^^
SyntaxError: invalid syntax. Perhaps you forgot a comma?
[2023-12-05T18:51:16.912+0000] {processor.py:841} WARNING - No viable dags retrieved from /home/ubuntu/airflow/dags/etl.py
[2023-12-05T18:51:16.933+0000] {processor.py:179} INFO - Processing /home/ubuntu/airflow/dags/etl.py took 0.031 seconds
[2023-12-05T18:51:47.056+0000] {processor.py:157} INFO - Started process (PID=20943) to work on /home/ubuntu/airflow/dags/etl.py
[2023-12-05T18:51:47.058+0000] {processor.py:829} INFO - Processing file /home/ubuntu/airflow/dags/etl.py for tasks to queue
[2023-12-05T18:51:47.059+0000] {logging_mixin.py:154} INFO - [2023-12-05T18:51:47.058+0000] {dagbag.py:536} INFO - Filling up the DagBag from /home/ubuntu/airflow/dags/etl.py
[2023-12-05T18:51:47.063+0000] {logging_mixin.py:154} INFO - [2023-12-05T18:51:47.062+0000] {dagbag.py:346} ERROR - Failed to import: /home/ubuntu/airflow/dags/etl.py
Traceback (most recent call last):
  File "/usr/local/lib/python3.10/dist-packages/airflow/models/dagbag.py", line 342, in parse
    loader.exec_module(new_module)
  File "<frozen importlib._bootstrap_external>", line 879, in exec_module
  File "<frozen importlib._bootstrap_external>", line 1017, in get_code
  File "<frozen importlib._bootstrap_external>", line 947, in source_to_code
  File "<frozen importlib._bootstrap>", line 241, in _call_with_frames_removed
  File "/home/ubuntu/airflow/dags/etl.py", line 10
    'start_date': datetime(2023, 5. 12),
                                 ^^^^^
SyntaxError: invalid syntax. Perhaps you forgot a comma?
[2023-12-05T18:51:47.063+0000] {processor.py:841} WARNING - No viable dags retrieved from /home/ubuntu/airflow/dags/etl.py
[2023-12-05T18:51:47.088+0000] {processor.py:179} INFO - Processing /home/ubuntu/airflow/dags/etl.py took 0.038 seconds
[2023-12-05T18:52:12.534+0000] {processor.py:157} INFO - Started process (PID=21016) to work on /home/ubuntu/airflow/dags/etl.py
[2023-12-05T18:52:12.536+0000] {processor.py:829} INFO - Processing file /home/ubuntu/airflow/dags/etl.py for tasks to queue
[2023-12-05T18:52:12.538+0000] {logging_mixin.py:154} INFO - [2023-12-05T18:52:12.537+0000] {dagbag.py:536} INFO - Filling up the DagBag from /home/ubuntu/airflow/dags/etl.py
[2023-12-05T18:52:12.544+0000] {logging_mixin.py:154} INFO - [2023-12-05T18:52:12.543+0000] {dagbag.py:346} ERROR - Failed to import: /home/ubuntu/airflow/dags/etl.py
Traceback (most recent call last):
  File "/usr/local/lib/python3.10/dist-packages/airflow/models/dagbag.py", line 342, in parse
    loader.exec_module(new_module)
  File "<frozen importlib._bootstrap_external>", line 879, in exec_module
  File "<frozen importlib._bootstrap_external>", line 1017, in get_code
  File "<frozen importlib._bootstrap_external>", line 947, in source_to_code
  File "<frozen importlib._bootstrap>", line 241, in _call_with_frames_removed
  File "/home/ubuntu/airflow/dags/etl.py", line 10
    'start_date': datetime(2023, 5. 12),
                                 ^^^^^
SyntaxError: invalid syntax. Perhaps you forgot a comma?
[2023-12-05T18:52:12.545+0000] {processor.py:841} WARNING - No viable dags retrieved from /home/ubuntu/airflow/dags/etl.py
[2023-12-05T18:52:12.589+0000] {processor.py:179} INFO - Processing /home/ubuntu/airflow/dags/etl.py took 0.063 seconds
[2023-12-05T18:52:42.952+0000] {processor.py:157} INFO - Started process (PID=21031) to work on /home/ubuntu/airflow/dags/etl.py
[2023-12-05T18:52:42.954+0000] {processor.py:829} INFO - Processing file /home/ubuntu/airflow/dags/etl.py for tasks to queue
[2023-12-05T18:52:42.955+0000] {logging_mixin.py:154} INFO - [2023-12-05T18:52:42.954+0000] {dagbag.py:536} INFO - Filling up the DagBag from /home/ubuntu/airflow/dags/etl.py
[2023-12-05T18:52:42.958+0000] {logging_mixin.py:154} INFO - [2023-12-05T18:52:42.957+0000] {dagbag.py:346} ERROR - Failed to import: /home/ubuntu/airflow/dags/etl.py
Traceback (most recent call last):
  File "/usr/local/lib/python3.10/dist-packages/airflow/models/dagbag.py", line 342, in parse
    loader.exec_module(new_module)
  File "<frozen importlib._bootstrap_external>", line 879, in exec_module
  File "<frozen importlib._bootstrap_external>", line 1017, in get_code
  File "<frozen importlib._bootstrap_external>", line 947, in source_to_code
  File "<frozen importlib._bootstrap>", line 241, in _call_with_frames_removed
  File "/home/ubuntu/airflow/dags/etl.py", line 10
    'start_date': datetime(2023, 5. 12),
                                 ^^^^^
SyntaxError: invalid syntax. Perhaps you forgot a comma?
[2023-12-05T18:52:42.959+0000] {processor.py:841} WARNING - No viable dags retrieved from /home/ubuntu/airflow/dags/etl.py
[2023-12-05T18:52:42.988+0000] {processor.py:179} INFO - Processing /home/ubuntu/airflow/dags/etl.py took 0.040 seconds
[2023-12-05T18:53:13.366+0000] {processor.py:157} INFO - Started process (PID=21110) to work on /home/ubuntu/airflow/dags/etl.py
[2023-12-05T18:53:13.367+0000] {processor.py:829} INFO - Processing file /home/ubuntu/airflow/dags/etl.py for tasks to queue
[2023-12-05T18:53:13.369+0000] {logging_mixin.py:154} INFO - [2023-12-05T18:53:13.369+0000] {dagbag.py:536} INFO - Filling up the DagBag from /home/ubuntu/airflow/dags/etl.py
[2023-12-05T18:53:13.375+0000] {logging_mixin.py:154} INFO - [2023-12-05T18:53:13.373+0000] {dagbag.py:346} ERROR - Failed to import: /home/ubuntu/airflow/dags/etl.py
Traceback (most recent call last):
  File "/usr/local/lib/python3.10/dist-packages/airflow/models/dagbag.py", line 342, in parse
    loader.exec_module(new_module)
  File "<frozen importlib._bootstrap_external>", line 879, in exec_module
  File "<frozen importlib._bootstrap_external>", line 1017, in get_code
  File "<frozen importlib._bootstrap_external>", line 947, in source_to_code
  File "<frozen importlib._bootstrap>", line 241, in _call_with_frames_removed
  File "/home/ubuntu/airflow/dags/etl.py", line 10
    'start_date': datetime(2023, 5. 12),
                                 ^^^^^
SyntaxError: invalid syntax. Perhaps you forgot a comma?
[2023-12-05T18:53:13.376+0000] {processor.py:841} WARNING - No viable dags retrieved from /home/ubuntu/airflow/dags/etl.py
[2023-12-05T18:53:13.423+0000] {processor.py:179} INFO - Processing /home/ubuntu/airflow/dags/etl.py took 0.061 seconds
[2023-12-05T18:53:43.834+0000] {processor.py:157} INFO - Started process (PID=21120) to work on /home/ubuntu/airflow/dags/etl.py
[2023-12-05T18:53:43.835+0000] {processor.py:829} INFO - Processing file /home/ubuntu/airflow/dags/etl.py for tasks to queue
[2023-12-05T18:53:43.836+0000] {logging_mixin.py:154} INFO - [2023-12-05T18:53:43.836+0000] {dagbag.py:536} INFO - Filling up the DagBag from /home/ubuntu/airflow/dags/etl.py
[2023-12-05T18:53:43.840+0000] {logging_mixin.py:154} INFO - [2023-12-05T18:53:43.839+0000] {dagbag.py:346} ERROR - Failed to import: /home/ubuntu/airflow/dags/etl.py
Traceback (most recent call last):
  File "/usr/local/lib/python3.10/dist-packages/airflow/models/dagbag.py", line 342, in parse
    loader.exec_module(new_module)
  File "<frozen importlib._bootstrap_external>", line 879, in exec_module
  File "<frozen importlib._bootstrap_external>", line 1017, in get_code
  File "<frozen importlib._bootstrap_external>", line 947, in source_to_code
  File "<frozen importlib._bootstrap>", line 241, in _call_with_frames_removed
  File "/home/ubuntu/airflow/dags/etl.py", line 10
    'start_date': datetime(2023, 5. 12),
                                 ^^^^^
SyntaxError: invalid syntax. Perhaps you forgot a comma?
[2023-12-05T18:53:43.840+0000] {processor.py:841} WARNING - No viable dags retrieved from /home/ubuntu/airflow/dags/etl.py
[2023-12-05T18:53:43.864+0000] {processor.py:179} INFO - Processing /home/ubuntu/airflow/dags/etl.py took 0.034 seconds
[2023-12-05T18:54:14.296+0000] {processor.py:157} INFO - Started process (PID=21197) to work on /home/ubuntu/airflow/dags/etl.py
[2023-12-05T18:54:14.297+0000] {processor.py:829} INFO - Processing file /home/ubuntu/airflow/dags/etl.py for tasks to queue
[2023-12-05T18:54:14.301+0000] {logging_mixin.py:154} INFO - [2023-12-05T18:54:14.300+0000] {dagbag.py:536} INFO - Filling up the DagBag from /home/ubuntu/airflow/dags/etl.py
[2023-12-05T18:54:14.309+0000] {logging_mixin.py:154} INFO - [2023-12-05T18:54:14.307+0000] {dagbag.py:346} ERROR - Failed to import: /home/ubuntu/airflow/dags/etl.py
Traceback (most recent call last):
  File "/usr/local/lib/python3.10/dist-packages/airflow/models/dagbag.py", line 342, in parse
    loader.exec_module(new_module)
  File "<frozen importlib._bootstrap_external>", line 879, in exec_module
  File "<frozen importlib._bootstrap_external>", line 1017, in get_code
  File "<frozen importlib._bootstrap_external>", line 947, in source_to_code
  File "<frozen importlib._bootstrap>", line 241, in _call_with_frames_removed
  File "/home/ubuntu/airflow/dags/etl.py", line 10
    'start_date': datetime(2023, 5. 12),
                                 ^^^^^
SyntaxError: invalid syntax. Perhaps you forgot a comma?
[2023-12-05T18:54:14.309+0000] {processor.py:841} WARNING - No viable dags retrieved from /home/ubuntu/airflow/dags/etl.py
[2023-12-05T18:54:14.342+0000] {processor.py:179} INFO - Processing /home/ubuntu/airflow/dags/etl.py took 0.053 seconds
[2023-12-05T18:54:44.708+0000] {processor.py:157} INFO - Started process (PID=21222) to work on /home/ubuntu/airflow/dags/etl.py
[2023-12-05T18:54:44.710+0000] {processor.py:829} INFO - Processing file /home/ubuntu/airflow/dags/etl.py for tasks to queue
[2023-12-05T18:54:44.711+0000] {logging_mixin.py:154} INFO - [2023-12-05T18:54:44.711+0000] {dagbag.py:536} INFO - Filling up the DagBag from /home/ubuntu/airflow/dags/etl.py
[2023-12-05T18:54:44.718+0000] {logging_mixin.py:154} INFO - [2023-12-05T18:54:44.714+0000] {dagbag.py:346} ERROR - Failed to import: /home/ubuntu/airflow/dags/etl.py
Traceback (most recent call last):
  File "/usr/local/lib/python3.10/dist-packages/airflow/models/dagbag.py", line 342, in parse
    loader.exec_module(new_module)
  File "<frozen importlib._bootstrap_external>", line 879, in exec_module
  File "<frozen importlib._bootstrap_external>", line 1017, in get_code
  File "<frozen importlib._bootstrap_external>", line 947, in source_to_code
  File "<frozen importlib._bootstrap>", line 241, in _call_with_frames_removed
  File "/home/ubuntu/airflow/dags/etl.py", line 10
    'start_date': datetime(2023, 5. 12),
                                 ^^^^^
SyntaxError: invalid syntax. Perhaps you forgot a comma?
[2023-12-05T18:54:44.718+0000] {processor.py:841} WARNING - No viable dags retrieved from /home/ubuntu/airflow/dags/etl.py
[2023-12-05T18:54:44.756+0000] {processor.py:179} INFO - Processing /home/ubuntu/airflow/dags/etl.py took 0.055 seconds
[2023-12-05T18:54:45.857+0000] {processor.py:157} INFO - Started process (PID=21223) to work on /home/ubuntu/airflow/dags/etl.py
[2023-12-05T18:54:45.858+0000] {processor.py:829} INFO - Processing file /home/ubuntu/airflow/dags/etl.py for tasks to queue
[2023-12-05T18:54:45.859+0000] {logging_mixin.py:154} INFO - [2023-12-05T18:54:45.859+0000] {dagbag.py:536} INFO - Filling up the DagBag from /home/ubuntu/airflow/dags/etl.py
[2023-12-05T18:54:45.863+0000] {logging_mixin.py:154} INFO - [2023-12-05T18:54:45.862+0000] {dagbag.py:346} ERROR - Failed to import: /home/ubuntu/airflow/dags/etl.py
Traceback (most recent call last):
  File "/usr/local/lib/python3.10/dist-packages/airflow/models/dagbag.py", line 342, in parse
    loader.exec_module(new_module)
  File "<frozen importlib._bootstrap_external>", line 879, in exec_module
  File "<frozen importlib._bootstrap_external>", line 1017, in get_code
  File "<frozen importlib._bootstrap_external>", line 947, in source_to_code
  File "<frozen importlib._bootstrap>", line 241, in _call_with_frames_removed
  File "/home/ubuntu/airflow/dags/etl.py", line 10
    'start_date': datetime(2023, 5. 12),
                                 ^^^^^
SyntaxError: invalid syntax. Perhaps you forgot a comma?
[2023-12-05T18:54:45.863+0000] {processor.py:841} WARNING - No viable dags retrieved from /home/ubuntu/airflow/dags/etl.py
[2023-12-05T18:54:45.883+0000] {processor.py:179} INFO - Processing /home/ubuntu/airflow/dags/etl.py took 0.029 seconds
[2023-12-05T18:55:16.161+0000] {processor.py:157} INFO - Started process (PID=21421) to work on /home/ubuntu/airflow/dags/etl.py
[2023-12-05T18:55:16.162+0000] {processor.py:829} INFO - Processing file /home/ubuntu/airflow/dags/etl.py for tasks to queue
[2023-12-05T18:55:16.162+0000] {logging_mixin.py:154} INFO - [2023-12-05T18:55:16.162+0000] {dagbag.py:536} INFO - Filling up the DagBag from /home/ubuntu/airflow/dags/etl.py
[2023-12-05T18:55:16.166+0000] {logging_mixin.py:154} INFO - [2023-12-05T18:55:16.165+0000] {dagbag.py:346} ERROR - Failed to import: /home/ubuntu/airflow/dags/etl.py
Traceback (most recent call last):
  File "/usr/local/lib/python3.10/dist-packages/airflow/models/dagbag.py", line 342, in parse
    loader.exec_module(new_module)
  File "<frozen importlib._bootstrap_external>", line 879, in exec_module
  File "<frozen importlib._bootstrap_external>", line 1017, in get_code
  File "<frozen importlib._bootstrap_external>", line 947, in source_to_code
  File "<frozen importlib._bootstrap>", line 241, in _call_with_frames_removed
  File "/home/ubuntu/airflow/dags/etl.py", line 10
    'start_date': datetime(2023, 5. 12),
                                 ^^^^^
SyntaxError: invalid syntax. Perhaps you forgot a comma?
[2023-12-05T18:55:16.167+0000] {processor.py:841} WARNING - No viable dags retrieved from /home/ubuntu/airflow/dags/etl.py
[2023-12-05T18:55:16.221+0000] {processor.py:179} INFO - Processing /home/ubuntu/airflow/dags/etl.py took 0.065 seconds
[2023-12-05T18:55:46.588+0000] {processor.py:157} INFO - Started process (PID=21554) to work on /home/ubuntu/airflow/dags/etl.py
[2023-12-05T18:55:46.589+0000] {processor.py:829} INFO - Processing file /home/ubuntu/airflow/dags/etl.py for tasks to queue
[2023-12-05T18:55:46.591+0000] {logging_mixin.py:154} INFO - [2023-12-05T18:55:46.590+0000] {dagbag.py:536} INFO - Filling up the DagBag from /home/ubuntu/airflow/dags/etl.py
[2023-12-05T18:55:46.596+0000] {logging_mixin.py:154} INFO - [2023-12-05T18:55:46.595+0000] {dagbag.py:346} ERROR - Failed to import: /home/ubuntu/airflow/dags/etl.py
Traceback (most recent call last):
  File "/usr/local/lib/python3.10/dist-packages/airflow/models/dagbag.py", line 342, in parse
    loader.exec_module(new_module)
  File "<frozen importlib._bootstrap_external>", line 879, in exec_module
  File "<frozen importlib._bootstrap_external>", line 1017, in get_code
  File "<frozen importlib._bootstrap_external>", line 947, in source_to_code
  File "<frozen importlib._bootstrap>", line 241, in _call_with_frames_removed
  File "/home/ubuntu/airflow/dags/etl.py", line 10
    'start_date': datetime(2023, 5. 12),
                                 ^^^^^
SyntaxError: invalid syntax. Perhaps you forgot a comma?
[2023-12-05T18:55:46.597+0000] {processor.py:841} WARNING - No viable dags retrieved from /home/ubuntu/airflow/dags/etl.py
[2023-12-05T18:55:46.642+0000] {processor.py:179} INFO - Processing /home/ubuntu/airflow/dags/etl.py took 0.058 seconds
[2023-12-05T18:55:54.776+0000] {processor.py:157} INFO - Started process (PID=21634) to work on /home/ubuntu/airflow/dags/etl.py
[2023-12-05T18:55:54.777+0000] {processor.py:829} INFO - Processing file /home/ubuntu/airflow/dags/etl.py for tasks to queue
[2023-12-05T18:55:54.778+0000] {logging_mixin.py:154} INFO - [2023-12-05T18:55:54.778+0000] {dagbag.py:536} INFO - Filling up the DagBag from /home/ubuntu/airflow/dags/etl.py
[2023-12-05T18:55:54.795+0000] {logging_mixin.py:154} INFO - [2023-12-05T18:55:54.789+0000] {dagbag.py:346} ERROR - Failed to import: /home/ubuntu/airflow/dags/etl.py
Traceback (most recent call last):
  File "/usr/local/lib/python3.10/dist-packages/airflow/models/dagbag.py", line 342, in parse
    loader.exec_module(new_module)
  File "<frozen importlib._bootstrap_external>", line 883, in exec_module
  File "<frozen importlib._bootstrap>", line 241, in _call_with_frames_removed
  File "/home/ubuntu/airflow/dags/etl.py", line 25, in <module>
    is_api_available = HttpSensor(
NameError: name 'HttpSensor' is not defined
[2023-12-05T18:55:54.800+0000] {processor.py:841} WARNING - No viable dags retrieved from /home/ubuntu/airflow/dags/etl.py
[2023-12-05T18:55:54.820+0000] {processor.py:179} INFO - Processing /home/ubuntu/airflow/dags/etl.py took 0.049 seconds
[2023-12-05T18:56:25.089+0000] {processor.py:157} INFO - Started process (PID=21776) to work on /home/ubuntu/airflow/dags/etl.py
[2023-12-05T18:56:25.091+0000] {processor.py:829} INFO - Processing file /home/ubuntu/airflow/dags/etl.py for tasks to queue
[2023-12-05T18:56:25.092+0000] {logging_mixin.py:154} INFO - [2023-12-05T18:56:25.091+0000] {dagbag.py:536} INFO - Filling up the DagBag from /home/ubuntu/airflow/dags/etl.py
[2023-12-05T18:56:25.103+0000] {logging_mixin.py:154} INFO - [2023-12-05T18:56:25.099+0000] {dagbag.py:346} ERROR - Failed to import: /home/ubuntu/airflow/dags/etl.py
Traceback (most recent call last):
  File "/usr/local/lib/python3.10/dist-packages/airflow/models/dagbag.py", line 342, in parse
    loader.exec_module(new_module)
  File "<frozen importlib._bootstrap_external>", line 883, in exec_module
  File "<frozen importlib._bootstrap>", line 241, in _call_with_frames_removed
  File "/home/ubuntu/airflow/dags/etl.py", line 25, in <module>
    is_api_available = HttpSensor(
NameError: name 'HttpSensor' is not defined
[2023-12-05T18:56:25.107+0000] {processor.py:841} WARNING - No viable dags retrieved from /home/ubuntu/airflow/dags/etl.py
[2023-12-05T18:56:25.126+0000] {processor.py:179} INFO - Processing /home/ubuntu/airflow/dags/etl.py took 0.041 seconds
[2023-12-05T18:56:55.401+0000] {processor.py:157} INFO - Started process (PID=21803) to work on /home/ubuntu/airflow/dags/etl.py
[2023-12-05T18:56:55.402+0000] {processor.py:829} INFO - Processing file /home/ubuntu/airflow/dags/etl.py for tasks to queue
[2023-12-05T18:56:55.403+0000] {logging_mixin.py:154} INFO - [2023-12-05T18:56:55.402+0000] {dagbag.py:536} INFO - Filling up the DagBag from /home/ubuntu/airflow/dags/etl.py
[2023-12-05T18:56:55.427+0000] {logging_mixin.py:154} INFO - [2023-12-05T18:56:55.419+0000] {dagbag.py:346} ERROR - Failed to import: /home/ubuntu/airflow/dags/etl.py
Traceback (most recent call last):
  File "/usr/local/lib/python3.10/dist-packages/airflow/models/dagbag.py", line 342, in parse
    loader.exec_module(new_module)
  File "<frozen importlib._bootstrap_external>", line 883, in exec_module
  File "<frozen importlib._bootstrap>", line 241, in _call_with_frames_removed
  File "/home/ubuntu/airflow/dags/etl.py", line 25, in <module>
    is_api_available = HttpSensor(
NameError: name 'HttpSensor' is not defined
[2023-12-05T18:56:55.435+0000] {processor.py:841} WARNING - No viable dags retrieved from /home/ubuntu/airflow/dags/etl.py
[2023-12-05T18:56:55.468+0000] {processor.py:179} INFO - Processing /home/ubuntu/airflow/dags/etl.py took 0.071 seconds
[2023-12-05T18:57:25.708+0000] {processor.py:157} INFO - Started process (PID=21941) to work on /home/ubuntu/airflow/dags/etl.py
[2023-12-05T18:57:25.710+0000] {processor.py:829} INFO - Processing file /home/ubuntu/airflow/dags/etl.py for tasks to queue
[2023-12-05T18:57:25.712+0000] {logging_mixin.py:154} INFO - [2023-12-05T18:57:25.712+0000] {dagbag.py:536} INFO - Filling up the DagBag from /home/ubuntu/airflow/dags/etl.py
[2023-12-05T18:57:25.730+0000] {logging_mixin.py:154} INFO - [2023-12-05T18:57:25.722+0000] {dagbag.py:346} ERROR - Failed to import: /home/ubuntu/airflow/dags/etl.py
Traceback (most recent call last):
  File "/usr/local/lib/python3.10/dist-packages/airflow/models/dagbag.py", line 342, in parse
    loader.exec_module(new_module)
  File "<frozen importlib._bootstrap_external>", line 883, in exec_module
  File "<frozen importlib._bootstrap>", line 241, in _call_with_frames_removed
  File "/home/ubuntu/airflow/dags/etl.py", line 25, in <module>
    is_api_available = HttpSensor(
NameError: name 'HttpSensor' is not defined
[2023-12-05T18:57:25.736+0000] {processor.py:841} WARNING - No viable dags retrieved from /home/ubuntu/airflow/dags/etl.py
[2023-12-05T18:57:25.759+0000] {processor.py:179} INFO - Processing /home/ubuntu/airflow/dags/etl.py took 0.058 seconds
[2023-12-05T18:57:56.225+0000] {processor.py:157} INFO - Started process (PID=21964) to work on /home/ubuntu/airflow/dags/etl.py
[2023-12-05T18:57:56.227+0000] {processor.py:829} INFO - Processing file /home/ubuntu/airflow/dags/etl.py for tasks to queue
[2023-12-05T18:57:56.228+0000] {logging_mixin.py:154} INFO - [2023-12-05T18:57:56.228+0000] {dagbag.py:536} INFO - Filling up the DagBag from /home/ubuntu/airflow/dags/etl.py
[2023-12-05T18:57:56.241+0000] {logging_mixin.py:154} INFO - [2023-12-05T18:57:56.237+0000] {dagbag.py:346} ERROR - Failed to import: /home/ubuntu/airflow/dags/etl.py
Traceback (most recent call last):
  File "/usr/local/lib/python3.10/dist-packages/airflow/models/dagbag.py", line 342, in parse
    loader.exec_module(new_module)
  File "<frozen importlib._bootstrap_external>", line 883, in exec_module
  File "<frozen importlib._bootstrap>", line 241, in _call_with_frames_removed
  File "/home/ubuntu/airflow/dags/etl.py", line 25, in <module>
    is_api_available = HttpSensor(
NameError: name 'HttpSensor' is not defined
[2023-12-05T18:57:56.244+0000] {processor.py:841} WARNING - No viable dags retrieved from /home/ubuntu/airflow/dags/etl.py
[2023-12-05T18:57:56.263+0000] {processor.py:179} INFO - Processing /home/ubuntu/airflow/dags/etl.py took 0.041 seconds
[2023-12-05T18:58:26.619+0000] {processor.py:157} INFO - Started process (PID=22049) to work on /home/ubuntu/airflow/dags/etl.py
[2023-12-05T18:58:26.625+0000] {processor.py:829} INFO - Processing file /home/ubuntu/airflow/dags/etl.py for tasks to queue
[2023-12-05T18:58:26.626+0000] {logging_mixin.py:154} INFO - [2023-12-05T18:58:26.626+0000] {dagbag.py:536} INFO - Filling up the DagBag from /home/ubuntu/airflow/dags/etl.py
[2023-12-05T18:58:26.648+0000] {logging_mixin.py:154} INFO - [2023-12-05T18:58:26.640+0000] {dagbag.py:346} ERROR - Failed to import: /home/ubuntu/airflow/dags/etl.py
Traceback (most recent call last):
  File "/usr/local/lib/python3.10/dist-packages/airflow/models/dagbag.py", line 342, in parse
    loader.exec_module(new_module)
  File "<frozen importlib._bootstrap_external>", line 883, in exec_module
  File "<frozen importlib._bootstrap>", line 241, in _call_with_frames_removed
  File "/home/ubuntu/airflow/dags/etl.py", line 25, in <module>
    is_api_available = HttpSensor(
NameError: name 'HttpSensor' is not defined
[2023-12-05T18:58:26.656+0000] {processor.py:841} WARNING - No viable dags retrieved from /home/ubuntu/airflow/dags/etl.py
[2023-12-05T18:58:26.692+0000] {processor.py:179} INFO - Processing /home/ubuntu/airflow/dags/etl.py took 0.081 seconds
[2023-12-05T18:58:57.004+0000] {processor.py:157} INFO - Started process (PID=22071) to work on /home/ubuntu/airflow/dags/etl.py
[2023-12-05T18:58:57.006+0000] {processor.py:829} INFO - Processing file /home/ubuntu/airflow/dags/etl.py for tasks to queue
[2023-12-05T18:58:57.007+0000] {logging_mixin.py:154} INFO - [2023-12-05T18:58:57.006+0000] {dagbag.py:536} INFO - Filling up the DagBag from /home/ubuntu/airflow/dags/etl.py
[2023-12-05T18:58:57.020+0000] {logging_mixin.py:154} INFO - [2023-12-05T18:58:57.015+0000] {dagbag.py:346} ERROR - Failed to import: /home/ubuntu/airflow/dags/etl.py
Traceback (most recent call last):
  File "/usr/local/lib/python3.10/dist-packages/airflow/models/dagbag.py", line 342, in parse
    loader.exec_module(new_module)
  File "<frozen importlib._bootstrap_external>", line 883, in exec_module
  File "<frozen importlib._bootstrap>", line 241, in _call_with_frames_removed
  File "/home/ubuntu/airflow/dags/etl.py", line 25, in <module>
    is_api_available = HttpSensor(
NameError: name 'HttpSensor' is not defined
[2023-12-05T18:58:57.024+0000] {processor.py:841} WARNING - No viable dags retrieved from /home/ubuntu/airflow/dags/etl.py
[2023-12-05T18:58:57.049+0000] {processor.py:179} INFO - Processing /home/ubuntu/airflow/dags/etl.py took 0.050 seconds
[2023-12-05T18:59:27.404+0000] {processor.py:157} INFO - Started process (PID=22215) to work on /home/ubuntu/airflow/dags/etl.py
[2023-12-05T18:59:27.405+0000] {processor.py:829} INFO - Processing file /home/ubuntu/airflow/dags/etl.py for tasks to queue
[2023-12-05T18:59:27.405+0000] {logging_mixin.py:154} INFO - [2023-12-05T18:59:27.405+0000] {dagbag.py:536} INFO - Filling up the DagBag from /home/ubuntu/airflow/dags/etl.py
[2023-12-05T18:59:27.420+0000] {logging_mixin.py:154} INFO - [2023-12-05T18:59:27.413+0000] {dagbag.py:346} ERROR - Failed to import: /home/ubuntu/airflow/dags/etl.py
Traceback (most recent call last):
  File "/usr/local/lib/python3.10/dist-packages/airflow/models/dagbag.py", line 342, in parse
    loader.exec_module(new_module)
  File "<frozen importlib._bootstrap_external>", line 883, in exec_module
  File "<frozen importlib._bootstrap>", line 241, in _call_with_frames_removed
  File "/home/ubuntu/airflow/dags/etl.py", line 25, in <module>
    is_api_available = HttpSensor(
NameError: name 'HttpSensor' is not defined
[2023-12-05T18:59:27.424+0000] {processor.py:841} WARNING - No viable dags retrieved from /home/ubuntu/airflow/dags/etl.py
[2023-12-05T18:59:27.446+0000] {processor.py:179} INFO - Processing /home/ubuntu/airflow/dags/etl.py took 0.046 seconds
[2023-12-05T18:59:57.730+0000] {processor.py:157} INFO - Started process (PID=22238) to work on /home/ubuntu/airflow/dags/etl.py
[2023-12-05T18:59:57.732+0000] {processor.py:829} INFO - Processing file /home/ubuntu/airflow/dags/etl.py for tasks to queue
[2023-12-05T18:59:57.734+0000] {logging_mixin.py:154} INFO - [2023-12-05T18:59:57.733+0000] {dagbag.py:536} INFO - Filling up the DagBag from /home/ubuntu/airflow/dags/etl.py
[2023-12-05T18:59:57.746+0000] {logging_mixin.py:154} INFO - [2023-12-05T18:59:57.741+0000] {dagbag.py:346} ERROR - Failed to import: /home/ubuntu/airflow/dags/etl.py
Traceback (most recent call last):
  File "/usr/local/lib/python3.10/dist-packages/airflow/models/dagbag.py", line 342, in parse
    loader.exec_module(new_module)
  File "<frozen importlib._bootstrap_external>", line 883, in exec_module
  File "<frozen importlib._bootstrap>", line 241, in _call_with_frames_removed
  File "/home/ubuntu/airflow/dags/etl.py", line 25, in <module>
    is_api_available = HttpSensor(
NameError: name 'HttpSensor' is not defined
[2023-12-05T18:59:57.749+0000] {processor.py:841} WARNING - No viable dags retrieved from /home/ubuntu/airflow/dags/etl.py
[2023-12-05T18:59:57.770+0000] {processor.py:179} INFO - Processing /home/ubuntu/airflow/dags/etl.py took 0.043 seconds
[2023-12-05T19:00:28.068+0000] {processor.py:157} INFO - Started process (PID=22321) to work on /home/ubuntu/airflow/dags/etl.py
[2023-12-05T19:00:28.070+0000] {processor.py:829} INFO - Processing file /home/ubuntu/airflow/dags/etl.py for tasks to queue
[2023-12-05T19:00:28.077+0000] {logging_mixin.py:154} INFO - [2023-12-05T19:00:28.076+0000] {dagbag.py:536} INFO - Filling up the DagBag from /home/ubuntu/airflow/dags/etl.py
[2023-12-05T19:00:28.107+0000] {logging_mixin.py:154} INFO - [2023-12-05T19:00:28.095+0000] {dagbag.py:346} ERROR - Failed to import: /home/ubuntu/airflow/dags/etl.py
Traceback (most recent call last):
  File "/usr/local/lib/python3.10/dist-packages/airflow/models/dagbag.py", line 342, in parse
    loader.exec_module(new_module)
  File "<frozen importlib._bootstrap_external>", line 883, in exec_module
  File "<frozen importlib._bootstrap>", line 241, in _call_with_frames_removed
  File "/home/ubuntu/airflow/dags/etl.py", line 25, in <module>
    is_api_available = HttpSensor(
NameError: name 'HttpSensor' is not defined
[2023-12-05T19:00:28.113+0000] {processor.py:841} WARNING - No viable dags retrieved from /home/ubuntu/airflow/dags/etl.py
[2023-12-05T19:00:28.135+0000] {processor.py:179} INFO - Processing /home/ubuntu/airflow/dags/etl.py took 0.076 seconds
[2023-12-05T19:00:58.377+0000] {processor.py:157} INFO - Started process (PID=22340) to work on /home/ubuntu/airflow/dags/etl.py
[2023-12-05T19:00:58.381+0000] {processor.py:829} INFO - Processing file /home/ubuntu/airflow/dags/etl.py for tasks to queue
[2023-12-05T19:00:58.382+0000] {logging_mixin.py:154} INFO - [2023-12-05T19:00:58.381+0000] {dagbag.py:536} INFO - Filling up the DagBag from /home/ubuntu/airflow/dags/etl.py
[2023-12-05T19:00:58.398+0000] {logging_mixin.py:154} INFO - [2023-12-05T19:00:58.391+0000] {dagbag.py:346} ERROR - Failed to import: /home/ubuntu/airflow/dags/etl.py
Traceback (most recent call last):
  File "/usr/local/lib/python3.10/dist-packages/airflow/models/dagbag.py", line 342, in parse
    loader.exec_module(new_module)
  File "<frozen importlib._bootstrap_external>", line 883, in exec_module
  File "<frozen importlib._bootstrap>", line 241, in _call_with_frames_removed
  File "/home/ubuntu/airflow/dags/etl.py", line 25, in <module>
    is_api_available = HttpSensor(
NameError: name 'HttpSensor' is not defined
[2023-12-05T19:00:58.403+0000] {processor.py:841} WARNING - No viable dags retrieved from /home/ubuntu/airflow/dags/etl.py
[2023-12-05T19:00:58.432+0000] {processor.py:179} INFO - Processing /home/ubuntu/airflow/dags/etl.py took 0.059 seconds
[2023-12-05T19:01:28.691+0000] {processor.py:157} INFO - Started process (PID=22487) to work on /home/ubuntu/airflow/dags/etl.py
[2023-12-05T19:01:28.692+0000] {processor.py:829} INFO - Processing file /home/ubuntu/airflow/dags/etl.py for tasks to queue
[2023-12-05T19:01:28.693+0000] {logging_mixin.py:154} INFO - [2023-12-05T19:01:28.693+0000] {dagbag.py:536} INFO - Filling up the DagBag from /home/ubuntu/airflow/dags/etl.py
[2023-12-05T19:01:28.705+0000] {logging_mixin.py:154} INFO - [2023-12-05T19:01:28.701+0000] {dagbag.py:346} ERROR - Failed to import: /home/ubuntu/airflow/dags/etl.py
Traceback (most recent call last):
  File "/usr/local/lib/python3.10/dist-packages/airflow/models/dagbag.py", line 342, in parse
    loader.exec_module(new_module)
  File "<frozen importlib._bootstrap_external>", line 883, in exec_module
  File "<frozen importlib._bootstrap>", line 241, in _call_with_frames_removed
  File "/home/ubuntu/airflow/dags/etl.py", line 25, in <module>
    is_api_available = HttpSensor(
NameError: name 'HttpSensor' is not defined
[2023-12-05T19:01:28.710+0000] {processor.py:841} WARNING - No viable dags retrieved from /home/ubuntu/airflow/dags/etl.py
[2023-12-05T19:01:28.732+0000] {processor.py:179} INFO - Processing /home/ubuntu/airflow/dags/etl.py took 0.045 seconds
[2023-12-05T19:01:58.955+0000] {processor.py:157} INFO - Started process (PID=22506) to work on /home/ubuntu/airflow/dags/etl.py
[2023-12-05T19:01:58.956+0000] {processor.py:829} INFO - Processing file /home/ubuntu/airflow/dags/etl.py for tasks to queue
[2023-12-05T19:01:58.957+0000] {logging_mixin.py:154} INFO - [2023-12-05T19:01:58.957+0000] {dagbag.py:536} INFO - Filling up the DagBag from /home/ubuntu/airflow/dags/etl.py
[2023-12-05T19:01:58.969+0000] {logging_mixin.py:154} INFO - [2023-12-05T19:01:58.965+0000] {dagbag.py:346} ERROR - Failed to import: /home/ubuntu/airflow/dags/etl.py
Traceback (most recent call last):
  File "/usr/local/lib/python3.10/dist-packages/airflow/models/dagbag.py", line 342, in parse
    loader.exec_module(new_module)
  File "<frozen importlib._bootstrap_external>", line 883, in exec_module
  File "<frozen importlib._bootstrap>", line 241, in _call_with_frames_removed
  File "/home/ubuntu/airflow/dags/etl.py", line 25, in <module>
    is_api_available = HttpSensor(
NameError: name 'HttpSensor' is not defined
[2023-12-05T19:01:58.976+0000] {processor.py:841} WARNING - No viable dags retrieved from /home/ubuntu/airflow/dags/etl.py
[2023-12-05T19:01:58.995+0000] {processor.py:179} INFO - Processing /home/ubuntu/airflow/dags/etl.py took 0.044 seconds
[2023-12-05T19:02:29.277+0000] {processor.py:157} INFO - Started process (PID=22584) to work on /home/ubuntu/airflow/dags/etl.py
[2023-12-05T19:02:29.279+0000] {processor.py:829} INFO - Processing file /home/ubuntu/airflow/dags/etl.py for tasks to queue
[2023-12-05T19:02:29.280+0000] {logging_mixin.py:154} INFO - [2023-12-05T19:02:29.280+0000] {dagbag.py:536} INFO - Filling up the DagBag from /home/ubuntu/airflow/dags/etl.py
[2023-12-05T19:02:29.303+0000] {logging_mixin.py:154} INFO - [2023-12-05T19:02:29.297+0000] {dagbag.py:346} ERROR - Failed to import: /home/ubuntu/airflow/dags/etl.py
Traceback (most recent call last):
  File "/usr/local/lib/python3.10/dist-packages/airflow/models/dagbag.py", line 342, in parse
    loader.exec_module(new_module)
  File "<frozen importlib._bootstrap_external>", line 883, in exec_module
  File "<frozen importlib._bootstrap>", line 241, in _call_with_frames_removed
  File "/home/ubuntu/airflow/dags/etl.py", line 25, in <module>
    is_api_available = HttpSensor(
NameError: name 'HttpSensor' is not defined
[2023-12-05T19:02:29.307+0000] {processor.py:841} WARNING - No viable dags retrieved from /home/ubuntu/airflow/dags/etl.py
[2023-12-05T19:02:29.330+0000] {processor.py:179} INFO - Processing /home/ubuntu/airflow/dags/etl.py took 0.057 seconds
[2023-12-05T19:02:59.604+0000] {processor.py:157} INFO - Started process (PID=22609) to work on /home/ubuntu/airflow/dags/etl.py
[2023-12-05T19:02:59.605+0000] {processor.py:829} INFO - Processing file /home/ubuntu/airflow/dags/etl.py for tasks to queue
[2023-12-05T19:02:59.606+0000] {logging_mixin.py:154} INFO - [2023-12-05T19:02:59.606+0000] {dagbag.py:536} INFO - Filling up the DagBag from /home/ubuntu/airflow/dags/etl.py
[2023-12-05T19:02:59.619+0000] {logging_mixin.py:154} INFO - [2023-12-05T19:02:59.615+0000] {dagbag.py:346} ERROR - Failed to import: /home/ubuntu/airflow/dags/etl.py
Traceback (most recent call last):
  File "/usr/local/lib/python3.10/dist-packages/airflow/models/dagbag.py", line 342, in parse
    loader.exec_module(new_module)
  File "<frozen importlib._bootstrap_external>", line 883, in exec_module
  File "<frozen importlib._bootstrap>", line 241, in _call_with_frames_removed
  File "/home/ubuntu/airflow/dags/etl.py", line 25, in <module>
    is_api_available = HttpSensor(
NameError: name 'HttpSensor' is not defined
[2023-12-05T19:02:59.623+0000] {processor.py:841} WARNING - No viable dags retrieved from /home/ubuntu/airflow/dags/etl.py
[2023-12-05T19:02:59.644+0000] {processor.py:179} INFO - Processing /home/ubuntu/airflow/dags/etl.py took 0.044 seconds
[2023-12-05T19:03:29.930+0000] {processor.py:157} INFO - Started process (PID=22689) to work on /home/ubuntu/airflow/dags/etl.py
[2023-12-05T19:03:29.931+0000] {processor.py:829} INFO - Processing file /home/ubuntu/airflow/dags/etl.py for tasks to queue
[2023-12-05T19:03:29.932+0000] {logging_mixin.py:154} INFO - [2023-12-05T19:03:29.932+0000] {dagbag.py:536} INFO - Filling up the DagBag from /home/ubuntu/airflow/dags/etl.py
[2023-12-05T19:03:29.944+0000] {logging_mixin.py:154} INFO - [2023-12-05T19:03:29.940+0000] {dagbag.py:346} ERROR - Failed to import: /home/ubuntu/airflow/dags/etl.py
Traceback (most recent call last):
  File "/usr/local/lib/python3.10/dist-packages/airflow/models/dagbag.py", line 342, in parse
    loader.exec_module(new_module)
  File "<frozen importlib._bootstrap_external>", line 883, in exec_module
  File "<frozen importlib._bootstrap>", line 241, in _call_with_frames_removed
  File "/home/ubuntu/airflow/dags/etl.py", line 25, in <module>
    is_api_available = HttpSensor(
NameError: name 'HttpSensor' is not defined
[2023-12-05T19:03:29.948+0000] {processor.py:841} WARNING - No viable dags retrieved from /home/ubuntu/airflow/dags/etl.py
[2023-12-05T19:03:29.970+0000] {processor.py:179} INFO - Processing /home/ubuntu/airflow/dags/etl.py took 0.043 seconds
[2023-12-05T19:04:00.143+0000] {processor.py:157} INFO - Started process (PID=22713) to work on /home/ubuntu/airflow/dags/etl.py
[2023-12-05T19:04:00.145+0000] {processor.py:829} INFO - Processing file /home/ubuntu/airflow/dags/etl.py for tasks to queue
[2023-12-05T19:04:00.146+0000] {logging_mixin.py:154} INFO - [2023-12-05T19:04:00.145+0000] {dagbag.py:536} INFO - Filling up the DagBag from /home/ubuntu/airflow/dags/etl.py
[2023-12-05T19:04:00.166+0000] {logging_mixin.py:154} INFO - [2023-12-05T19:04:00.158+0000] {dagbag.py:346} ERROR - Failed to import: /home/ubuntu/airflow/dags/etl.py
Traceback (most recent call last):
  File "/usr/local/lib/python3.10/dist-packages/airflow/models/dagbag.py", line 342, in parse
    loader.exec_module(new_module)
  File "<frozen importlib._bootstrap_external>", line 883, in exec_module
  File "<frozen importlib._bootstrap>", line 241, in _call_with_frames_removed
  File "/home/ubuntu/airflow/dags/etl.py", line 25, in <module>
    is_api_available = HttpSensor(
NameError: name 'HttpSensor' is not defined
[2023-12-05T19:04:00.174+0000] {processor.py:841} WARNING - No viable dags retrieved from /home/ubuntu/airflow/dags/etl.py
[2023-12-05T19:04:00.216+0000] {processor.py:179} INFO - Processing /home/ubuntu/airflow/dags/etl.py took 0.078 seconds
[2023-12-05T19:04:30.440+0000] {processor.py:157} INFO - Started process (PID=22795) to work on /home/ubuntu/airflow/dags/etl.py
[2023-12-05T19:04:30.441+0000] {processor.py:829} INFO - Processing file /home/ubuntu/airflow/dags/etl.py for tasks to queue
[2023-12-05T19:04:30.442+0000] {logging_mixin.py:154} INFO - [2023-12-05T19:04:30.441+0000] {dagbag.py:536} INFO - Filling up the DagBag from /home/ubuntu/airflow/dags/etl.py
[2023-12-05T19:04:30.453+0000] {logging_mixin.py:154} INFO - [2023-12-05T19:04:30.449+0000] {dagbag.py:346} ERROR - Failed to import: /home/ubuntu/airflow/dags/etl.py
Traceback (most recent call last):
  File "/usr/local/lib/python3.10/dist-packages/airflow/models/dagbag.py", line 342, in parse
    loader.exec_module(new_module)
  File "<frozen importlib._bootstrap_external>", line 883, in exec_module
  File "<frozen importlib._bootstrap>", line 241, in _call_with_frames_removed
  File "/home/ubuntu/airflow/dags/etl.py", line 25, in <module>
    is_api_available = HttpSensor(
NameError: name 'HttpSensor' is not defined
[2023-12-05T19:04:30.457+0000] {processor.py:841} WARNING - No viable dags retrieved from /home/ubuntu/airflow/dags/etl.py
[2023-12-05T19:04:30.478+0000] {processor.py:179} INFO - Processing /home/ubuntu/airflow/dags/etl.py took 0.043 seconds
[2023-12-05T19:05:00.710+0000] {processor.py:157} INFO - Started process (PID=22816) to work on /home/ubuntu/airflow/dags/etl.py
[2023-12-05T19:05:00.713+0000] {processor.py:829} INFO - Processing file /home/ubuntu/airflow/dags/etl.py for tasks to queue
[2023-12-05T19:05:00.715+0000] {logging_mixin.py:154} INFO - [2023-12-05T19:05:00.714+0000] {dagbag.py:536} INFO - Filling up the DagBag from /home/ubuntu/airflow/dags/etl.py
[2023-12-05T19:05:00.729+0000] {logging_mixin.py:154} INFO - [2023-12-05T19:05:00.722+0000] {dagbag.py:346} ERROR - Failed to import: /home/ubuntu/airflow/dags/etl.py
Traceback (most recent call last):
  File "/usr/local/lib/python3.10/dist-packages/airflow/models/dagbag.py", line 342, in parse
    loader.exec_module(new_module)
  File "<frozen importlib._bootstrap_external>", line 883, in exec_module
  File "<frozen importlib._bootstrap>", line 241, in _call_with_frames_removed
  File "/home/ubuntu/airflow/dags/etl.py", line 25, in <module>
    is_api_available = HttpSensor(
NameError: name 'HttpSensor' is not defined
[2023-12-05T19:05:00.733+0000] {processor.py:841} WARNING - No viable dags retrieved from /home/ubuntu/airflow/dags/etl.py
[2023-12-05T19:05:00.757+0000] {processor.py:179} INFO - Processing /home/ubuntu/airflow/dags/etl.py took 0.052 seconds
[2023-12-05T19:05:30.963+0000] {processor.py:157} INFO - Started process (PID=22901) to work on /home/ubuntu/airflow/dags/etl.py
[2023-12-05T19:05:30.965+0000] {processor.py:829} INFO - Processing file /home/ubuntu/airflow/dags/etl.py for tasks to queue
[2023-12-05T19:05:30.966+0000] {logging_mixin.py:154} INFO - [2023-12-05T19:05:30.966+0000] {dagbag.py:536} INFO - Filling up the DagBag from /home/ubuntu/airflow/dags/etl.py
[2023-12-05T19:05:30.984+0000] {logging_mixin.py:154} INFO - [2023-12-05T19:05:30.977+0000] {dagbag.py:346} ERROR - Failed to import: /home/ubuntu/airflow/dags/etl.py
Traceback (most recent call last):
  File "/usr/local/lib/python3.10/dist-packages/airflow/models/dagbag.py", line 342, in parse
    loader.exec_module(new_module)
  File "<frozen importlib._bootstrap_external>", line 883, in exec_module
  File "<frozen importlib._bootstrap>", line 241, in _call_with_frames_removed
  File "/home/ubuntu/airflow/dags/etl.py", line 25, in <module>
    is_api_available = HttpSensor(
NameError: name 'HttpSensor' is not defined
[2023-12-05T19:05:30.988+0000] {processor.py:841} WARNING - No viable dags retrieved from /home/ubuntu/airflow/dags/etl.py
[2023-12-05T19:05:31.028+0000] {processor.py:179} INFO - Processing /home/ubuntu/airflow/dags/etl.py took 0.070 seconds
[2023-12-05T19:06:01.191+0000] {processor.py:157} INFO - Started process (PID=22919) to work on /home/ubuntu/airflow/dags/etl.py
[2023-12-05T19:06:01.193+0000] {processor.py:829} INFO - Processing file /home/ubuntu/airflow/dags/etl.py for tasks to queue
[2023-12-05T19:06:01.194+0000] {logging_mixin.py:154} INFO - [2023-12-05T19:06:01.193+0000] {dagbag.py:536} INFO - Filling up the DagBag from /home/ubuntu/airflow/dags/etl.py
[2023-12-05T19:06:01.204+0000] {logging_mixin.py:154} INFO - [2023-12-05T19:06:01.200+0000] {dagbag.py:346} ERROR - Failed to import: /home/ubuntu/airflow/dags/etl.py
Traceback (most recent call last):
  File "/usr/local/lib/python3.10/dist-packages/airflow/models/dagbag.py", line 342, in parse
    loader.exec_module(new_module)
  File "<frozen importlib._bootstrap_external>", line 883, in exec_module
  File "<frozen importlib._bootstrap>", line 241, in _call_with_frames_removed
  File "/home/ubuntu/airflow/dags/etl.py", line 25, in <module>
    is_api_available = HttpSensor(
NameError: name 'HttpSensor' is not defined
[2023-12-05T19:06:01.208+0000] {processor.py:841} WARNING - No viable dags retrieved from /home/ubuntu/airflow/dags/etl.py
[2023-12-05T19:06:01.227+0000] {processor.py:179} INFO - Processing /home/ubuntu/airflow/dags/etl.py took 0.039 seconds
[2023-12-05T19:06:31.428+0000] {processor.py:157} INFO - Started process (PID=23063) to work on /home/ubuntu/airflow/dags/etl.py
[2023-12-05T19:06:31.429+0000] {processor.py:829} INFO - Processing file /home/ubuntu/airflow/dags/etl.py for tasks to queue
[2023-12-05T19:06:31.430+0000] {logging_mixin.py:154} INFO - [2023-12-05T19:06:31.429+0000] {dagbag.py:536} INFO - Filling up the DagBag from /home/ubuntu/airflow/dags/etl.py
[2023-12-05T19:06:31.441+0000] {logging_mixin.py:154} INFO - [2023-12-05T19:06:31.436+0000] {dagbag.py:346} ERROR - Failed to import: /home/ubuntu/airflow/dags/etl.py
Traceback (most recent call last):
  File "/usr/local/lib/python3.10/dist-packages/airflow/models/dagbag.py", line 342, in parse
    loader.exec_module(new_module)
  File "<frozen importlib._bootstrap_external>", line 883, in exec_module
  File "<frozen importlib._bootstrap>", line 241, in _call_with_frames_removed
  File "/home/ubuntu/airflow/dags/etl.py", line 25, in <module>
    is_api_available = HttpSensor(
NameError: name 'HttpSensor' is not defined
[2023-12-05T19:06:31.446+0000] {processor.py:841} WARNING - No viable dags retrieved from /home/ubuntu/airflow/dags/etl.py
[2023-12-05T19:06:31.465+0000] {processor.py:179} INFO - Processing /home/ubuntu/airflow/dags/etl.py took 0.040 seconds
[2023-12-05T19:07:01.669+0000] {processor.py:157} INFO - Started process (PID=23084) to work on /home/ubuntu/airflow/dags/etl.py
[2023-12-05T19:07:01.671+0000] {processor.py:829} INFO - Processing file /home/ubuntu/airflow/dags/etl.py for tasks to queue
[2023-12-05T19:07:01.673+0000] {logging_mixin.py:154} INFO - [2023-12-05T19:07:01.672+0000] {dagbag.py:536} INFO - Filling up the DagBag from /home/ubuntu/airflow/dags/etl.py
[2023-12-05T19:07:01.692+0000] {logging_mixin.py:154} INFO - [2023-12-05T19:07:01.687+0000] {dagbag.py:346} ERROR - Failed to import: /home/ubuntu/airflow/dags/etl.py
Traceback (most recent call last):
  File "/usr/local/lib/python3.10/dist-packages/airflow/models/dagbag.py", line 342, in parse
    loader.exec_module(new_module)
  File "<frozen importlib._bootstrap_external>", line 883, in exec_module
  File "<frozen importlib._bootstrap>", line 241, in _call_with_frames_removed
  File "/home/ubuntu/airflow/dags/etl.py", line 25, in <module>
    is_api_available = HttpSensor(
NameError: name 'HttpSensor' is not defined
[2023-12-05T19:07:01.696+0000] {processor.py:841} WARNING - No viable dags retrieved from /home/ubuntu/airflow/dags/etl.py
[2023-12-05T19:07:01.719+0000] {processor.py:179} INFO - Processing /home/ubuntu/airflow/dags/etl.py took 0.061 seconds
[2023-12-05T19:07:31.872+0000] {processor.py:157} INFO - Started process (PID=23231) to work on /home/ubuntu/airflow/dags/etl.py
[2023-12-05T19:07:31.873+0000] {processor.py:829} INFO - Processing file /home/ubuntu/airflow/dags/etl.py for tasks to queue
[2023-12-05T19:07:31.874+0000] {logging_mixin.py:154} INFO - [2023-12-05T19:07:31.873+0000] {dagbag.py:536} INFO - Filling up the DagBag from /home/ubuntu/airflow/dags/etl.py
[2023-12-05T19:07:31.890+0000] {logging_mixin.py:154} INFO - [2023-12-05T19:07:31.885+0000] {dagbag.py:346} ERROR - Failed to import: /home/ubuntu/airflow/dags/etl.py
Traceback (most recent call last):
  File "/usr/local/lib/python3.10/dist-packages/airflow/models/dagbag.py", line 342, in parse
    loader.exec_module(new_module)
  File "<frozen importlib._bootstrap_external>", line 883, in exec_module
  File "<frozen importlib._bootstrap>", line 241, in _call_with_frames_removed
  File "/home/ubuntu/airflow/dags/etl.py", line 25, in <module>
    is_api_available = HttpSensor(
NameError: name 'HttpSensor' is not defined
[2023-12-05T19:07:31.893+0000] {processor.py:841} WARNING - No viable dags retrieved from /home/ubuntu/airflow/dags/etl.py
[2023-12-05T19:07:31.915+0000] {processor.py:179} INFO - Processing /home/ubuntu/airflow/dags/etl.py took 0.047 seconds
[2023-12-05T19:08:02.110+0000] {processor.py:157} INFO - Started process (PID=23253) to work on /home/ubuntu/airflow/dags/etl.py
[2023-12-05T19:08:02.113+0000] {processor.py:829} INFO - Processing file /home/ubuntu/airflow/dags/etl.py for tasks to queue
[2023-12-05T19:08:02.115+0000] {logging_mixin.py:154} INFO - [2023-12-05T19:08:02.114+0000] {dagbag.py:536} INFO - Filling up the DagBag from /home/ubuntu/airflow/dags/etl.py
[2023-12-05T19:08:02.142+0000] {logging_mixin.py:154} INFO - [2023-12-05T19:08:02.133+0000] {dagbag.py:346} ERROR - Failed to import: /home/ubuntu/airflow/dags/etl.py
Traceback (most recent call last):
  File "/usr/local/lib/python3.10/dist-packages/airflow/models/dagbag.py", line 342, in parse
    loader.exec_module(new_module)
  File "<frozen importlib._bootstrap_external>", line 883, in exec_module
  File "<frozen importlib._bootstrap>", line 241, in _call_with_frames_removed
  File "/home/ubuntu/airflow/dags/etl.py", line 25, in <module>
    is_api_available = HttpSensor(
NameError: name 'HttpSensor' is not defined
[2023-12-05T19:08:02.152+0000] {processor.py:841} WARNING - No viable dags retrieved from /home/ubuntu/airflow/dags/etl.py
[2023-12-05T19:08:02.200+0000] {processor.py:179} INFO - Processing /home/ubuntu/airflow/dags/etl.py took 0.095 seconds
[2023-12-05T19:08:32.432+0000] {processor.py:157} INFO - Started process (PID=23338) to work on /home/ubuntu/airflow/dags/etl.py
[2023-12-05T19:08:32.433+0000] {processor.py:829} INFO - Processing file /home/ubuntu/airflow/dags/etl.py for tasks to queue
[2023-12-05T19:08:32.434+0000] {logging_mixin.py:154} INFO - [2023-12-05T19:08:32.433+0000] {dagbag.py:536} INFO - Filling up the DagBag from /home/ubuntu/airflow/dags/etl.py
[2023-12-05T19:08:32.450+0000] {logging_mixin.py:154} INFO - [2023-12-05T19:08:32.442+0000] {dagbag.py:346} ERROR - Failed to import: /home/ubuntu/airflow/dags/etl.py
Traceback (most recent call last):
  File "/usr/local/lib/python3.10/dist-packages/airflow/models/dagbag.py", line 342, in parse
    loader.exec_module(new_module)
  File "<frozen importlib._bootstrap_external>", line 883, in exec_module
  File "<frozen importlib._bootstrap>", line 241, in _call_with_frames_removed
  File "/home/ubuntu/airflow/dags/etl.py", line 25, in <module>
    is_api_available = HttpSensor(
NameError: name 'HttpSensor' is not defined
[2023-12-05T19:08:32.454+0000] {processor.py:841} WARNING - No viable dags retrieved from /home/ubuntu/airflow/dags/etl.py
[2023-12-05T19:08:32.474+0000] {processor.py:179} INFO - Processing /home/ubuntu/airflow/dags/etl.py took 0.046 seconds
[2023-12-05T19:09:02.695+0000] {processor.py:157} INFO - Started process (PID=23356) to work on /home/ubuntu/airflow/dags/etl.py
[2023-12-05T19:09:02.697+0000] {processor.py:829} INFO - Processing file /home/ubuntu/airflow/dags/etl.py for tasks to queue
[2023-12-05T19:09:02.698+0000] {logging_mixin.py:154} INFO - [2023-12-05T19:09:02.698+0000] {dagbag.py:536} INFO - Filling up the DagBag from /home/ubuntu/airflow/dags/etl.py
[2023-12-05T19:09:02.729+0000] {logging_mixin.py:154} INFO - [2023-12-05T19:09:02.719+0000] {dagbag.py:346} ERROR - Failed to import: /home/ubuntu/airflow/dags/etl.py
Traceback (most recent call last):
  File "/usr/local/lib/python3.10/dist-packages/airflow/models/dagbag.py", line 342, in parse
    loader.exec_module(new_module)
  File "<frozen importlib._bootstrap_external>", line 883, in exec_module
  File "<frozen importlib._bootstrap>", line 241, in _call_with_frames_removed
  File "/home/ubuntu/airflow/dags/etl.py", line 25, in <module>
    is_api_available = HttpSensor(
NameError: name 'HttpSensor' is not defined
[2023-12-05T19:09:02.738+0000] {processor.py:841} WARNING - No viable dags retrieved from /home/ubuntu/airflow/dags/etl.py
[2023-12-05T19:09:02.778+0000] {processor.py:179} INFO - Processing /home/ubuntu/airflow/dags/etl.py took 0.087 seconds
[2023-12-05T19:09:32.942+0000] {processor.py:157} INFO - Started process (PID=23439) to work on /home/ubuntu/airflow/dags/etl.py
[2023-12-05T19:09:32.943+0000] {processor.py:829} INFO - Processing file /home/ubuntu/airflow/dags/etl.py for tasks to queue
[2023-12-05T19:09:32.944+0000] {logging_mixin.py:154} INFO - [2023-12-05T19:09:32.944+0000] {dagbag.py:536} INFO - Filling up the DagBag from /home/ubuntu/airflow/dags/etl.py
[2023-12-05T19:09:32.955+0000] {logging_mixin.py:154} INFO - [2023-12-05T19:09:32.951+0000] {dagbag.py:346} ERROR - Failed to import: /home/ubuntu/airflow/dags/etl.py
Traceback (most recent call last):
  File "/usr/local/lib/python3.10/dist-packages/airflow/models/dagbag.py", line 342, in parse
    loader.exec_module(new_module)
  File "<frozen importlib._bootstrap_external>", line 883, in exec_module
  File "<frozen importlib._bootstrap>", line 241, in _call_with_frames_removed
  File "/home/ubuntu/airflow/dags/etl.py", line 25, in <module>
    is_api_available = HttpSensor(
NameError: name 'HttpSensor' is not defined
[2023-12-05T19:09:32.960+0000] {processor.py:841} WARNING - No viable dags retrieved from /home/ubuntu/airflow/dags/etl.py
[2023-12-05T19:09:32.984+0000] {processor.py:179} INFO - Processing /home/ubuntu/airflow/dags/etl.py took 0.045 seconds
[2023-12-05T19:10:03.185+0000] {processor.py:157} INFO - Started process (PID=23464) to work on /home/ubuntu/airflow/dags/etl.py
[2023-12-05T19:10:03.187+0000] {processor.py:829} INFO - Processing file /home/ubuntu/airflow/dags/etl.py for tasks to queue
[2023-12-05T19:10:03.188+0000] {logging_mixin.py:154} INFO - [2023-12-05T19:10:03.187+0000] {dagbag.py:536} INFO - Filling up the DagBag from /home/ubuntu/airflow/dags/etl.py
[2023-12-05T19:10:03.201+0000] {logging_mixin.py:154} INFO - [2023-12-05T19:10:03.196+0000] {dagbag.py:346} ERROR - Failed to import: /home/ubuntu/airflow/dags/etl.py
Traceback (most recent call last):
  File "/usr/local/lib/python3.10/dist-packages/airflow/models/dagbag.py", line 342, in parse
    loader.exec_module(new_module)
  File "<frozen importlib._bootstrap_external>", line 883, in exec_module
  File "<frozen importlib._bootstrap>", line 241, in _call_with_frames_removed
  File "/home/ubuntu/airflow/dags/etl.py", line 25, in <module>
    is_api_available = HttpSensor(
NameError: name 'HttpSensor' is not defined
[2023-12-05T19:10:03.208+0000] {processor.py:841} WARNING - No viable dags retrieved from /home/ubuntu/airflow/dags/etl.py
[2023-12-05T19:10:03.233+0000] {processor.py:179} INFO - Processing /home/ubuntu/airflow/dags/etl.py took 0.052 seconds
[2023-12-05T19:10:33.408+0000] {processor.py:157} INFO - Started process (PID=23542) to work on /home/ubuntu/airflow/dags/etl.py
[2023-12-05T19:10:33.409+0000] {processor.py:829} INFO - Processing file /home/ubuntu/airflow/dags/etl.py for tasks to queue
[2023-12-05T19:10:33.410+0000] {logging_mixin.py:154} INFO - [2023-12-05T19:10:33.409+0000] {dagbag.py:536} INFO - Filling up the DagBag from /home/ubuntu/airflow/dags/etl.py
[2023-12-05T19:10:33.421+0000] {logging_mixin.py:154} INFO - [2023-12-05T19:10:33.416+0000] {dagbag.py:346} ERROR - Failed to import: /home/ubuntu/airflow/dags/etl.py
Traceback (most recent call last):
  File "/usr/local/lib/python3.10/dist-packages/airflow/models/dagbag.py", line 342, in parse
    loader.exec_module(new_module)
  File "<frozen importlib._bootstrap_external>", line 883, in exec_module
  File "<frozen importlib._bootstrap>", line 241, in _call_with_frames_removed
  File "/home/ubuntu/airflow/dags/etl.py", line 25, in <module>
    is_api_available = HttpSensor(
NameError: name 'HttpSensor' is not defined
[2023-12-05T19:10:33.429+0000] {processor.py:841} WARNING - No viable dags retrieved from /home/ubuntu/airflow/dags/etl.py
[2023-12-05T19:10:33.452+0000] {processor.py:179} INFO - Processing /home/ubuntu/airflow/dags/etl.py took 0.049 seconds
[2023-12-05T19:11:03.638+0000] {processor.py:157} INFO - Started process (PID=23571) to work on /home/ubuntu/airflow/dags/etl.py
[2023-12-05T19:11:03.640+0000] {processor.py:829} INFO - Processing file /home/ubuntu/airflow/dags/etl.py for tasks to queue
[2023-12-05T19:11:03.641+0000] {logging_mixin.py:154} INFO - [2023-12-05T19:11:03.640+0000] {dagbag.py:536} INFO - Filling up the DagBag from /home/ubuntu/airflow/dags/etl.py
[2023-12-05T19:11:03.654+0000] {logging_mixin.py:154} INFO - [2023-12-05T19:11:03.650+0000] {dagbag.py:346} ERROR - Failed to import: /home/ubuntu/airflow/dags/etl.py
Traceback (most recent call last):
  File "/usr/local/lib/python3.10/dist-packages/airflow/models/dagbag.py", line 342, in parse
    loader.exec_module(new_module)
  File "<frozen importlib._bootstrap_external>", line 883, in exec_module
  File "<frozen importlib._bootstrap>", line 241, in _call_with_frames_removed
  File "/home/ubuntu/airflow/dags/etl.py", line 25, in <module>
    is_api_available = HttpSensor(
NameError: name 'HttpSensor' is not defined
[2023-12-05T19:11:03.658+0000] {processor.py:841} WARNING - No viable dags retrieved from /home/ubuntu/airflow/dags/etl.py
[2023-12-05T19:11:03.679+0000] {processor.py:179} INFO - Processing /home/ubuntu/airflow/dags/etl.py took 0.044 seconds
[2023-12-05T19:11:33.896+0000] {processor.py:157} INFO - Started process (PID=23712) to work on /home/ubuntu/airflow/dags/etl.py
[2023-12-05T19:11:33.897+0000] {processor.py:829} INFO - Processing file /home/ubuntu/airflow/dags/etl.py for tasks to queue
[2023-12-05T19:11:33.898+0000] {logging_mixin.py:154} INFO - [2023-12-05T19:11:33.898+0000] {dagbag.py:536} INFO - Filling up the DagBag from /home/ubuntu/airflow/dags/etl.py
[2023-12-05T19:11:33.909+0000] {logging_mixin.py:154} INFO - [2023-12-05T19:11:33.905+0000] {dagbag.py:346} ERROR - Failed to import: /home/ubuntu/airflow/dags/etl.py
Traceback (most recent call last):
  File "/usr/local/lib/python3.10/dist-packages/airflow/models/dagbag.py", line 342, in parse
    loader.exec_module(new_module)
  File "<frozen importlib._bootstrap_external>", line 883, in exec_module
  File "<frozen importlib._bootstrap>", line 241, in _call_with_frames_removed
  File "/home/ubuntu/airflow/dags/etl.py", line 25, in <module>
    is_api_available = HttpSensor(
NameError: name 'HttpSensor' is not defined
[2023-12-05T19:11:33.913+0000] {processor.py:841} WARNING - No viable dags retrieved from /home/ubuntu/airflow/dags/etl.py
[2023-12-05T19:11:33.931+0000] {processor.py:179} INFO - Processing /home/ubuntu/airflow/dags/etl.py took 0.039 seconds
[2023-12-05T19:12:04.171+0000] {processor.py:157} INFO - Started process (PID=23734) to work on /home/ubuntu/airflow/dags/etl.py
[2023-12-05T19:12:04.172+0000] {processor.py:829} INFO - Processing file /home/ubuntu/airflow/dags/etl.py for tasks to queue
[2023-12-05T19:12:04.174+0000] {logging_mixin.py:154} INFO - [2023-12-05T19:12:04.173+0000] {dagbag.py:536} INFO - Filling up the DagBag from /home/ubuntu/airflow/dags/etl.py
[2023-12-05T19:12:04.192+0000] {logging_mixin.py:154} INFO - [2023-12-05T19:12:04.188+0000] {dagbag.py:346} ERROR - Failed to import: /home/ubuntu/airflow/dags/etl.py
Traceback (most recent call last):
  File "/usr/local/lib/python3.10/dist-packages/airflow/models/dagbag.py", line 342, in parse
    loader.exec_module(new_module)
  File "<frozen importlib._bootstrap_external>", line 883, in exec_module
  File "<frozen importlib._bootstrap>", line 241, in _call_with_frames_removed
  File "/home/ubuntu/airflow/dags/etl.py", line 25, in <module>
    is_api_available = HttpSensor(
NameError: name 'HttpSensor' is not defined
[2023-12-05T19:12:04.196+0000] {processor.py:841} WARNING - No viable dags retrieved from /home/ubuntu/airflow/dags/etl.py
[2023-12-05T19:12:04.218+0000] {processor.py:179} INFO - Processing /home/ubuntu/airflow/dags/etl.py took 0.061 seconds
[2023-12-05T19:12:34.429+0000] {processor.py:157} INFO - Started process (PID=23820) to work on /home/ubuntu/airflow/dags/etl.py
[2023-12-05T19:12:34.431+0000] {processor.py:829} INFO - Processing file /home/ubuntu/airflow/dags/etl.py for tasks to queue
[2023-12-05T19:12:34.432+0000] {logging_mixin.py:154} INFO - [2023-12-05T19:12:34.432+0000] {dagbag.py:536} INFO - Filling up the DagBag from /home/ubuntu/airflow/dags/etl.py
[2023-12-05T19:12:34.455+0000] {logging_mixin.py:154} INFO - [2023-12-05T19:12:34.447+0000] {dagbag.py:346} ERROR - Failed to import: /home/ubuntu/airflow/dags/etl.py
Traceback (most recent call last):
  File "/usr/local/lib/python3.10/dist-packages/airflow/models/dagbag.py", line 342, in parse
    loader.exec_module(new_module)
  File "<frozen importlib._bootstrap_external>", line 883, in exec_module
  File "<frozen importlib._bootstrap>", line 241, in _call_with_frames_removed
  File "/home/ubuntu/airflow/dags/etl.py", line 25, in <module>
    is_api_available = HttpSensor(
NameError: name 'HttpSensor' is not defined
[2023-12-05T19:12:34.463+0000] {processor.py:841} WARNING - No viable dags retrieved from /home/ubuntu/airflow/dags/etl.py
[2023-12-05T19:12:34.493+0000] {processor.py:179} INFO - Processing /home/ubuntu/airflow/dags/etl.py took 0.068 seconds
[2023-12-05T19:13:04.677+0000] {processor.py:157} INFO - Started process (PID=23838) to work on /home/ubuntu/airflow/dags/etl.py
[2023-12-05T19:13:04.678+0000] {processor.py:829} INFO - Processing file /home/ubuntu/airflow/dags/etl.py for tasks to queue
[2023-12-05T19:13:04.679+0000] {logging_mixin.py:154} INFO - [2023-12-05T19:13:04.678+0000] {dagbag.py:536} INFO - Filling up the DagBag from /home/ubuntu/airflow/dags/etl.py
[2023-12-05T19:13:04.695+0000] {logging_mixin.py:154} INFO - [2023-12-05T19:13:04.688+0000] {dagbag.py:346} ERROR - Failed to import: /home/ubuntu/airflow/dags/etl.py
Traceback (most recent call last):
  File "/usr/local/lib/python3.10/dist-packages/airflow/models/dagbag.py", line 342, in parse
    loader.exec_module(new_module)
  File "<frozen importlib._bootstrap_external>", line 883, in exec_module
  File "<frozen importlib._bootstrap>", line 241, in _call_with_frames_removed
  File "/home/ubuntu/airflow/dags/etl.py", line 25, in <module>
    is_api_available = HttpSensor(
NameError: name 'HttpSensor' is not defined
[2023-12-05T19:13:04.707+0000] {processor.py:841} WARNING - No viable dags retrieved from /home/ubuntu/airflow/dags/etl.py
[2023-12-05T19:13:04.729+0000] {processor.py:179} INFO - Processing /home/ubuntu/airflow/dags/etl.py took 0.057 seconds
[2023-12-05T19:13:34.909+0000] {processor.py:157} INFO - Started process (PID=23906) to work on /home/ubuntu/airflow/dags/etl.py
[2023-12-05T19:13:34.911+0000] {processor.py:829} INFO - Processing file /home/ubuntu/airflow/dags/etl.py for tasks to queue
[2023-12-05T19:13:34.912+0000] {logging_mixin.py:154} INFO - [2023-12-05T19:13:34.911+0000] {dagbag.py:536} INFO - Filling up the DagBag from /home/ubuntu/airflow/dags/etl.py
[2023-12-05T19:13:34.922+0000] {logging_mixin.py:154} INFO - [2023-12-05T19:13:34.918+0000] {dagbag.py:346} ERROR - Failed to import: /home/ubuntu/airflow/dags/etl.py
Traceback (most recent call last):
  File "/usr/local/lib/python3.10/dist-packages/airflow/models/dagbag.py", line 342, in parse
    loader.exec_module(new_module)
  File "<frozen importlib._bootstrap_external>", line 883, in exec_module
  File "<frozen importlib._bootstrap>", line 241, in _call_with_frames_removed
  File "/home/ubuntu/airflow/dags/etl.py", line 25, in <module>
    is_api_available = HttpSensor(
NameError: name 'HttpSensor' is not defined
[2023-12-05T19:13:34.926+0000] {processor.py:841} WARNING - No viable dags retrieved from /home/ubuntu/airflow/dags/etl.py
[2023-12-05T19:13:34.946+0000] {processor.py:179} INFO - Processing /home/ubuntu/airflow/dags/etl.py took 0.040 seconds
[2023-12-05T19:14:05.129+0000] {processor.py:157} INFO - Started process (PID=23914) to work on /home/ubuntu/airflow/dags/etl.py
[2023-12-05T19:14:05.130+0000] {processor.py:829} INFO - Processing file /home/ubuntu/airflow/dags/etl.py for tasks to queue
[2023-12-05T19:14:05.131+0000] {logging_mixin.py:154} INFO - [2023-12-05T19:14:05.131+0000] {dagbag.py:536} INFO - Filling up the DagBag from /home/ubuntu/airflow/dags/etl.py
[2023-12-05T19:14:05.142+0000] {logging_mixin.py:154} INFO - [2023-12-05T19:14:05.138+0000] {dagbag.py:346} ERROR - Failed to import: /home/ubuntu/airflow/dags/etl.py
Traceback (most recent call last):
  File "/usr/local/lib/python3.10/dist-packages/airflow/models/dagbag.py", line 342, in parse
    loader.exec_module(new_module)
  File "<frozen importlib._bootstrap_external>", line 883, in exec_module
  File "<frozen importlib._bootstrap>", line 241, in _call_with_frames_removed
  File "/home/ubuntu/airflow/dags/etl.py", line 25, in <module>
    is_api_available = HttpSensor(
NameError: name 'HttpSensor' is not defined
[2023-12-05T19:14:05.147+0000] {processor.py:841} WARNING - No viable dags retrieved from /home/ubuntu/airflow/dags/etl.py
[2023-12-05T19:14:05.167+0000] {processor.py:179} INFO - Processing /home/ubuntu/airflow/dags/etl.py took 0.042 seconds
[2023-12-05T19:14:35.306+0000] {processor.py:157} INFO - Started process (PID=24197) to work on /home/ubuntu/airflow/dags/etl.py
[2023-12-05T19:14:35.308+0000] {processor.py:829} INFO - Processing file /home/ubuntu/airflow/dags/etl.py for tasks to queue
[2023-12-05T19:14:35.308+0000] {logging_mixin.py:154} INFO - [2023-12-05T19:14:35.308+0000] {dagbag.py:536} INFO - Filling up the DagBag from /home/ubuntu/airflow/dags/etl.py
[2023-12-05T19:14:35.328+0000] {logging_mixin.py:154} INFO - [2023-12-05T19:14:35.320+0000] {dagbag.py:346} ERROR - Failed to import: /home/ubuntu/airflow/dags/etl.py
Traceback (most recent call last):
  File "/usr/local/lib/python3.10/dist-packages/airflow/models/dagbag.py", line 342, in parse
    loader.exec_module(new_module)
  File "<frozen importlib._bootstrap_external>", line 883, in exec_module
  File "<frozen importlib._bootstrap>", line 241, in _call_with_frames_removed
  File "/home/ubuntu/airflow/dags/etl.py", line 25, in <module>
    is_api_available = HttpSensor(
NameError: name 'HttpSensor' is not defined
[2023-12-05T19:14:35.335+0000] {processor.py:841} WARNING - No viable dags retrieved from /home/ubuntu/airflow/dags/etl.py
[2023-12-05T19:14:35.365+0000] {processor.py:179} INFO - Processing /home/ubuntu/airflow/dags/etl.py took 0.062 seconds
[2023-12-05T19:15:05.546+0000] {processor.py:157} INFO - Started process (PID=24296) to work on /home/ubuntu/airflow/dags/etl.py
[2023-12-05T19:15:05.548+0000] {processor.py:829} INFO - Processing file /home/ubuntu/airflow/dags/etl.py for tasks to queue
[2023-12-05T19:15:05.549+0000] {logging_mixin.py:154} INFO - [2023-12-05T19:15:05.549+0000] {dagbag.py:536} INFO - Filling up the DagBag from /home/ubuntu/airflow/dags/etl.py
[2023-12-05T19:15:05.562+0000] {logging_mixin.py:154} INFO - [2023-12-05T19:15:05.558+0000] {dagbag.py:346} ERROR - Failed to import: /home/ubuntu/airflow/dags/etl.py
Traceback (most recent call last):
  File "/usr/local/lib/python3.10/dist-packages/airflow/models/dagbag.py", line 342, in parse
    loader.exec_module(new_module)
  File "<frozen importlib._bootstrap_external>", line 883, in exec_module
  File "<frozen importlib._bootstrap>", line 241, in _call_with_frames_removed
  File "/home/ubuntu/airflow/dags/etl.py", line 25, in <module>
    is_api_available = HttpSensor(
NameError: name 'HttpSensor' is not defined
[2023-12-05T19:15:05.566+0000] {processor.py:841} WARNING - No viable dags retrieved from /home/ubuntu/airflow/dags/etl.py
[2023-12-05T19:15:05.587+0000] {processor.py:179} INFO - Processing /home/ubuntu/airflow/dags/etl.py took 0.044 seconds
[2023-12-05T19:15:35.758+0000] {processor.py:157} INFO - Started process (PID=24439) to work on /home/ubuntu/airflow/dags/etl.py
[2023-12-05T19:15:35.761+0000] {processor.py:829} INFO - Processing file /home/ubuntu/airflow/dags/etl.py for tasks to queue
[2023-12-05T19:15:35.762+0000] {logging_mixin.py:154} INFO - [2023-12-05T19:15:35.762+0000] {dagbag.py:536} INFO - Filling up the DagBag from /home/ubuntu/airflow/dags/etl.py
[2023-12-05T19:15:35.781+0000] {logging_mixin.py:154} INFO - [2023-12-05T19:15:35.776+0000] {dagbag.py:346} ERROR - Failed to import: /home/ubuntu/airflow/dags/etl.py
Traceback (most recent call last):
  File "/usr/local/lib/python3.10/dist-packages/airflow/models/dagbag.py", line 342, in parse
    loader.exec_module(new_module)
  File "<frozen importlib._bootstrap_external>", line 883, in exec_module
  File "<frozen importlib._bootstrap>", line 241, in _call_with_frames_removed
  File "/home/ubuntu/airflow/dags/etl.py", line 25, in <module>
    is_api_available = HttpSensor(
NameError: name 'HttpSensor' is not defined
[2023-12-05T19:15:35.787+0000] {processor.py:841} WARNING - No viable dags retrieved from /home/ubuntu/airflow/dags/etl.py
[2023-12-05T19:15:35.815+0000] {processor.py:179} INFO - Processing /home/ubuntu/airflow/dags/etl.py took 0.068 seconds
[2023-12-05T19:16:06.012+0000] {processor.py:157} INFO - Started process (PID=24449) to work on /home/ubuntu/airflow/dags/etl.py
[2023-12-05T19:16:06.014+0000] {processor.py:829} INFO - Processing file /home/ubuntu/airflow/dags/etl.py for tasks to queue
[2023-12-05T19:16:06.015+0000] {logging_mixin.py:154} INFO - [2023-12-05T19:16:06.014+0000] {dagbag.py:536} INFO - Filling up the DagBag from /home/ubuntu/airflow/dags/etl.py
[2023-12-05T19:16:06.026+0000] {logging_mixin.py:154} INFO - [2023-12-05T19:16:06.022+0000] {dagbag.py:346} ERROR - Failed to import: /home/ubuntu/airflow/dags/etl.py
Traceback (most recent call last):
  File "/usr/local/lib/python3.10/dist-packages/airflow/models/dagbag.py", line 342, in parse
    loader.exec_module(new_module)
  File "<frozen importlib._bootstrap_external>", line 883, in exec_module
  File "<frozen importlib._bootstrap>", line 241, in _call_with_frames_removed
  File "/home/ubuntu/airflow/dags/etl.py", line 25, in <module>
    is_api_available = HttpSensor(
NameError: name 'HttpSensor' is not defined
[2023-12-05T19:16:06.029+0000] {processor.py:841} WARNING - No viable dags retrieved from /home/ubuntu/airflow/dags/etl.py
[2023-12-05T19:16:06.048+0000] {processor.py:179} INFO - Processing /home/ubuntu/airflow/dags/etl.py took 0.039 seconds
[2023-12-05T19:16:36.254+0000] {processor.py:157} INFO - Started process (PID=24581) to work on /home/ubuntu/airflow/dags/etl.py
[2023-12-05T19:16:36.255+0000] {processor.py:829} INFO - Processing file /home/ubuntu/airflow/dags/etl.py for tasks to queue
[2023-12-05T19:16:36.259+0000] {logging_mixin.py:154} INFO - [2023-12-05T19:16:36.259+0000] {dagbag.py:536} INFO - Filling up the DagBag from /home/ubuntu/airflow/dags/etl.py
[2023-12-05T19:16:36.276+0000] {logging_mixin.py:154} INFO - [2023-12-05T19:16:36.269+0000] {dagbag.py:346} ERROR - Failed to import: /home/ubuntu/airflow/dags/etl.py
Traceback (most recent call last):
  File "/usr/local/lib/python3.10/dist-packages/airflow/models/dagbag.py", line 342, in parse
    loader.exec_module(new_module)
  File "<frozen importlib._bootstrap_external>", line 883, in exec_module
  File "<frozen importlib._bootstrap>", line 241, in _call_with_frames_removed
  File "/home/ubuntu/airflow/dags/etl.py", line 25, in <module>
    is_api_available = HttpSensor(
NameError: name 'HttpSensor' is not defined
[2023-12-05T19:16:36.284+0000] {processor.py:841} WARNING - No viable dags retrieved from /home/ubuntu/airflow/dags/etl.py
[2023-12-05T19:16:36.312+0000] {processor.py:179} INFO - Processing /home/ubuntu/airflow/dags/etl.py took 0.065 seconds
[2023-12-05T19:17:06.479+0000] {processor.py:157} INFO - Started process (PID=24592) to work on /home/ubuntu/airflow/dags/etl.py
[2023-12-05T19:17:06.482+0000] {processor.py:829} INFO - Processing file /home/ubuntu/airflow/dags/etl.py for tasks to queue
[2023-12-05T19:17:06.483+0000] {logging_mixin.py:154} INFO - [2023-12-05T19:17:06.482+0000] {dagbag.py:536} INFO - Filling up the DagBag from /home/ubuntu/airflow/dags/etl.py
[2023-12-05T19:17:06.500+0000] {logging_mixin.py:154} INFO - [2023-12-05T19:17:06.494+0000] {dagbag.py:346} ERROR - Failed to import: /home/ubuntu/airflow/dags/etl.py
Traceback (most recent call last):
  File "/usr/local/lib/python3.10/dist-packages/airflow/models/dagbag.py", line 342, in parse
    loader.exec_module(new_module)
  File "<frozen importlib._bootstrap_external>", line 883, in exec_module
  File "<frozen importlib._bootstrap>", line 241, in _call_with_frames_removed
  File "/home/ubuntu/airflow/dags/etl.py", line 25, in <module>
    is_api_available = HttpSensor(
NameError: name 'HttpSensor' is not defined
[2023-12-05T19:17:06.505+0000] {processor.py:841} WARNING - No viable dags retrieved from /home/ubuntu/airflow/dags/etl.py
[2023-12-05T19:17:06.528+0000] {processor.py:179} INFO - Processing /home/ubuntu/airflow/dags/etl.py took 0.054 seconds
[2023-12-05T19:17:36.721+0000] {processor.py:157} INFO - Started process (PID=24660) to work on /home/ubuntu/airflow/dags/etl.py
[2023-12-05T19:17:36.723+0000] {processor.py:829} INFO - Processing file /home/ubuntu/airflow/dags/etl.py for tasks to queue
[2023-12-05T19:17:36.725+0000] {logging_mixin.py:154} INFO - [2023-12-05T19:17:36.724+0000] {dagbag.py:536} INFO - Filling up the DagBag from /home/ubuntu/airflow/dags/etl.py
[2023-12-05T19:17:36.737+0000] {logging_mixin.py:154} INFO - [2023-12-05T19:17:36.733+0000] {dagbag.py:346} ERROR - Failed to import: /home/ubuntu/airflow/dags/etl.py
Traceback (most recent call last):
  File "/usr/local/lib/python3.10/dist-packages/airflow/models/dagbag.py", line 342, in parse
    loader.exec_module(new_module)
  File "<frozen importlib._bootstrap_external>", line 883, in exec_module
  File "<frozen importlib._bootstrap>", line 241, in _call_with_frames_removed
  File "/home/ubuntu/airflow/dags/etl.py", line 25, in <module>
    is_api_available = HttpSensor(
NameError: name 'HttpSensor' is not defined
[2023-12-05T19:17:36.741+0000] {processor.py:841} WARNING - No viable dags retrieved from /home/ubuntu/airflow/dags/etl.py
[2023-12-05T19:17:36.771+0000] {processor.py:179} INFO - Processing /home/ubuntu/airflow/dags/etl.py took 0.054 seconds
[2023-12-05T19:17:58.996+0000] {processor.py:157} INFO - Started process (PID=24675) to work on /home/ubuntu/airflow/dags/etl.py
[2023-12-05T19:17:58.997+0000] {processor.py:829} INFO - Processing file /home/ubuntu/airflow/dags/etl.py for tasks to queue
[2023-12-05T19:17:58.999+0000] {logging_mixin.py:154} INFO - [2023-12-05T19:17:58.998+0000] {dagbag.py:536} INFO - Filling up the DagBag from /home/ubuntu/airflow/dags/etl.py
[2023-12-05T19:17:59.003+0000] {logging_mixin.py:154} INFO - [2023-12-05T19:17:59.002+0000] {dagbag.py:346} ERROR - Failed to import: /home/ubuntu/airflow/dags/etl.py
Traceback (most recent call last):
  File "/usr/local/lib/python3.10/dist-packages/airflow/models/dagbag.py", line 342, in parse
    loader.exec_module(new_module)
  File "<frozen importlib._bootstrap_external>", line 879, in exec_module
  File "<frozen importlib._bootstrap_external>", line 1017, in get_code
  File "<frozen importlib._bootstrap_external>", line 947, in source_to_code
  File "<frozen importlib._bootstrap>", line 241, in _call_with_frames_removed
  File "/home/ubuntu/airflow/dags/etl.py", line 4
    from airflow.providers,http.sensors.http import HttpSensor
                          ^
SyntaxError: invalid syntax
[2023-12-05T19:17:59.004+0000] {processor.py:841} WARNING - No viable dags retrieved from /home/ubuntu/airflow/dags/etl.py
[2023-12-05T19:17:59.030+0000] {processor.py:179} INFO - Processing /home/ubuntu/airflow/dags/etl.py took 0.040 seconds
[2023-12-05T19:18:30.126+0000] {processor.py:157} INFO - Started process (PID=24802) to work on /home/ubuntu/airflow/dags/etl.py
[2023-12-05T19:18:30.128+0000] {processor.py:829} INFO - Processing file /home/ubuntu/airflow/dags/etl.py for tasks to queue
[2023-12-05T19:18:30.130+0000] {logging_mixin.py:154} INFO - [2023-12-05T19:18:30.129+0000] {dagbag.py:536} INFO - Filling up the DagBag from /home/ubuntu/airflow/dags/etl.py
[2023-12-05T19:18:30.133+0000] {logging_mixin.py:154} INFO - [2023-12-05T19:18:30.132+0000] {dagbag.py:346} ERROR - Failed to import: /home/ubuntu/airflow/dags/etl.py
Traceback (most recent call last):
  File "/usr/local/lib/python3.10/dist-packages/airflow/models/dagbag.py", line 342, in parse
    loader.exec_module(new_module)
  File "<frozen importlib._bootstrap_external>", line 879, in exec_module
  File "<frozen importlib._bootstrap_external>", line 1017, in get_code
  File "<frozen importlib._bootstrap_external>", line 947, in source_to_code
  File "<frozen importlib._bootstrap>", line 241, in _call_with_frames_removed
  File "/home/ubuntu/airflow/dags/etl.py", line 4
    from airflow.providers,http.sensors.http import HttpSensor
                          ^
SyntaxError: invalid syntax
[2023-12-05T19:18:30.134+0000] {processor.py:841} WARNING - No viable dags retrieved from /home/ubuntu/airflow/dags/etl.py
[2023-12-05T19:18:30.183+0000] {processor.py:179} INFO - Processing /home/ubuntu/airflow/dags/etl.py took 0.063 seconds
[2023-12-05T19:19:00.993+0000] {processor.py:157} INFO - Started process (PID=24807) to work on /home/ubuntu/airflow/dags/etl.py
[2023-12-05T19:19:00.994+0000] {processor.py:829} INFO - Processing file /home/ubuntu/airflow/dags/etl.py for tasks to queue
[2023-12-05T19:19:00.995+0000] {logging_mixin.py:154} INFO - [2023-12-05T19:19:00.995+0000] {dagbag.py:536} INFO - Filling up the DagBag from /home/ubuntu/airflow/dags/etl.py
[2023-12-05T19:19:00.998+0000] {logging_mixin.py:154} INFO - [2023-12-05T19:19:00.997+0000] {dagbag.py:346} ERROR - Failed to import: /home/ubuntu/airflow/dags/etl.py
Traceback (most recent call last):
  File "/usr/local/lib/python3.10/dist-packages/airflow/models/dagbag.py", line 342, in parse
    loader.exec_module(new_module)
  File "<frozen importlib._bootstrap_external>", line 879, in exec_module
  File "<frozen importlib._bootstrap_external>", line 1017, in get_code
  File "<frozen importlib._bootstrap_external>", line 947, in source_to_code
  File "<frozen importlib._bootstrap>", line 241, in _call_with_frames_removed
  File "/home/ubuntu/airflow/dags/etl.py", line 4
    from airflow.providers,http.sensors.http import HttpSensor
                          ^
SyntaxError: invalid syntax
[2023-12-05T19:19:00.999+0000] {processor.py:841} WARNING - No viable dags retrieved from /home/ubuntu/airflow/dags/etl.py
[2023-12-05T19:19:01.024+0000] {processor.py:179} INFO - Processing /home/ubuntu/airflow/dags/etl.py took 0.037 seconds
[2023-12-05T19:19:31.399+0000] {processor.py:157} INFO - Started process (PID=24871) to work on /home/ubuntu/airflow/dags/etl.py
[2023-12-05T19:19:31.400+0000] {processor.py:829} INFO - Processing file /home/ubuntu/airflow/dags/etl.py for tasks to queue
[2023-12-05T19:19:31.401+0000] {logging_mixin.py:154} INFO - [2023-12-05T19:19:31.401+0000] {dagbag.py:536} INFO - Filling up the DagBag from /home/ubuntu/airflow/dags/etl.py
[2023-12-05T19:19:31.407+0000] {logging_mixin.py:154} INFO - [2023-12-05T19:19:31.406+0000] {dagbag.py:346} ERROR - Failed to import: /home/ubuntu/airflow/dags/etl.py
Traceback (most recent call last):
  File "/usr/local/lib/python3.10/dist-packages/airflow/models/dagbag.py", line 342, in parse
    loader.exec_module(new_module)
  File "<frozen importlib._bootstrap_external>", line 879, in exec_module
  File "<frozen importlib._bootstrap_external>", line 1017, in get_code
  File "<frozen importlib._bootstrap_external>", line 947, in source_to_code
  File "<frozen importlib._bootstrap>", line 241, in _call_with_frames_removed
  File "/home/ubuntu/airflow/dags/etl.py", line 4
    from airflow.providers,http.sensors.http import HttpSensor
                          ^
SyntaxError: invalid syntax
[2023-12-05T19:19:31.407+0000] {processor.py:841} WARNING - No viable dags retrieved from /home/ubuntu/airflow/dags/etl.py
[2023-12-05T19:19:31.429+0000] {processor.py:179} INFO - Processing /home/ubuntu/airflow/dags/etl.py took 0.034 seconds
[2023-12-05T19:20:01.830+0000] {processor.py:157} INFO - Started process (PID=24881) to work on /home/ubuntu/airflow/dags/etl.py
[2023-12-05T19:20:01.837+0000] {processor.py:829} INFO - Processing file /home/ubuntu/airflow/dags/etl.py for tasks to queue
[2023-12-05T19:20:01.838+0000] {logging_mixin.py:154} INFO - [2023-12-05T19:20:01.838+0000] {dagbag.py:536} INFO - Filling up the DagBag from /home/ubuntu/airflow/dags/etl.py
[2023-12-05T19:20:01.843+0000] {logging_mixin.py:154} INFO - [2023-12-05T19:20:01.841+0000] {dagbag.py:346} ERROR - Failed to import: /home/ubuntu/airflow/dags/etl.py
Traceback (most recent call last):
  File "/usr/local/lib/python3.10/dist-packages/airflow/models/dagbag.py", line 342, in parse
    loader.exec_module(new_module)
  File "<frozen importlib._bootstrap_external>", line 879, in exec_module
  File "<frozen importlib._bootstrap_external>", line 1017, in get_code
  File "<frozen importlib._bootstrap_external>", line 947, in source_to_code
  File "<frozen importlib._bootstrap>", line 241, in _call_with_frames_removed
  File "/home/ubuntu/airflow/dags/etl.py", line 4
    from airflow.providers,http.sensors.http import HttpSensor
                          ^
SyntaxError: invalid syntax
[2023-12-05T19:20:01.843+0000] {processor.py:841} WARNING - No viable dags retrieved from /home/ubuntu/airflow/dags/etl.py
[2023-12-05T19:20:01.878+0000] {processor.py:179} INFO - Processing /home/ubuntu/airflow/dags/etl.py took 0.054 seconds
