[2023-12-08T20:58:04.362+0000] {taskinstance.py:1159} INFO - Dependencies all met for dep_context=non-requeueable deps ti=<TaskInstance: weather_dag.extract_data_task scheduled__2023-12-07T00:00:00+00:00 [queued]>
[2023-12-08T20:58:04.369+0000] {taskinstance.py:1159} INFO - Dependencies all met for dep_context=requeueable deps ti=<TaskInstance: weather_dag.extract_data_task scheduled__2023-12-07T00:00:00+00:00 [queued]>
[2023-12-08T20:58:04.369+0000] {taskinstance.py:1361} INFO - Starting attempt 2 of 3
[2023-12-08T20:58:04.387+0000] {taskinstance.py:1382} INFO - Executing <Task(PythonOperator): extract_data_task> on 2023-12-07 00:00:00+00:00
[2023-12-08T20:58:04.391+0000] {standard_task_runner.py:57} INFO - Started process 5339 to run task
[2023-12-08T20:58:04.397+0000] {standard_task_runner.py:84} INFO - Running: ['airflow', 'tasks', 'run', 'weather_dag', 'extract_data_task', 'scheduled__2023-12-07T00:00:00+00:00', '--job-id', '17', '--raw', '--subdir', 'DAGS_FOLDER/etl.py', '--cfg-path', '/tmp/tmpnnye5s9p']
[2023-12-08T20:58:04.399+0000] {standard_task_runner.py:85} INFO - Job 17: Subtask extract_data_task
[2023-12-08T20:58:04.436+0000] {task_command.py:416} INFO - Running <TaskInstance: weather_dag.extract_data_task scheduled__2023-12-07T00:00:00+00:00 [running]> on host ip-172-31-29-175.eu-north-1.compute.internal
[2023-12-08T20:58:04.615+0000] {taskinstance.py:1662} INFO - Exporting env vars: AIRFLOW_CTX_DAG_EMAIL='anamsken60@gmail.com' AIRFLOW_CTX_DAG_OWNER='airflow' AIRFLOW_CTX_DAG_ID='weather_dag' AIRFLOW_CTX_TASK_ID='extract_data_task' AIRFLOW_CTX_EXECUTION_DATE='2023-12-07T00:00:00+00:00' AIRFLOW_CTX_TRY_NUMBER='2' AIRFLOW_CTX_DAG_RUN_ID='scheduled__2023-12-07T00:00:00+00:00'
[2023-12-08T20:58:04.617+0000] {taskinstance.py:1937} ERROR - Task failed with exception
Traceback (most recent call last):
  File "/usr/local/lib/python3.10/dist-packages/airflow/operators/python.py", line 192, in execute
    return_value = self.execute_callable()
  File "/usr/local/lib/python3.10/dist-packages/airflow/operators/python.py", line 209, in execute_callable
    return self.python_callable(*self.op_args, **self.op_kwargs)
  File "/home/ubuntu/airflow/dags/etl.py", line 28, in extract_data
    response = requests.get(url, headers=headers, params=querystring)
NameError: name 'requests' is not defined
[2023-12-08T20:58:04.627+0000] {taskinstance.py:1400} INFO - Marking task as UP_FOR_RETRY. dag_id=weather_dag, task_id=extract_data_task, execution_date=20231207T000000, start_date=20231208T205804, end_date=20231208T205804
[2023-12-08T20:58:04.646+0000] {standard_task_runner.py:104} ERROR - Failed to execute job 17 for task extract_data_task (name 'requests' is not defined; 5339)
[2023-12-08T20:58:04.690+0000] {local_task_job_runner.py:228} INFO - Task exited with return code 1
[2023-12-08T20:58:04.703+0000] {taskinstance.py:2778} INFO - 0 downstream tasks scheduled from follow-on schedule check
